{
 "cells": [
  {
   "cell_type": "code",
   "execution_count": 1,
   "metadata": {},
   "outputs": [
    {
     "name": "stderr",
     "output_type": "stream",
     "text": [
      "C:\\Users\\nuno_\\Anaconda3\\lib\\site-packages\\h5py\\__init__.py:36: FutureWarning: Conversion of the second argument of issubdtype from `float` to `np.floating` is deprecated. In future, it will be treated as `np.float64 == np.dtype(float).type`.\n",
      "  from ._conv import register_converters as _register_converters\n",
      "Using Theano backend.\n",
      "WARNING (theano.configdefaults): g++ not available, if using conda: `conda install m2w64-toolchain`\n",
      "C:\\Users\\nuno_\\Anaconda3\\lib\\site-packages\\theano\\configdefaults.py:560: UserWarning: DeprecationWarning: there is no c++ compiler.This is deprecated and with Theano 0.11 a c++ compiler will be mandatory\n",
      "  warnings.warn(\"DeprecationWarning: there is no c++ compiler.\"\n",
      "WARNING (theano.configdefaults): g++ not detected ! Theano will be unable to execute optimized C-implementations (for both CPU and GPU) and will default to Python implementations. Performance will be severely degraded. To remove this warning, set Theano flags cxx to an empty string.\n",
      "WARNING (theano.tensor.blas): Using NumPy C-API based implementation for BLAS functions.\n"
     ]
    }
   ],
   "source": [
    "# import the necessary packages\n",
    "from sklearn.preprocessing import LabelBinarizer\n",
    "from sklearn.metrics import classification_report\n",
    "from keras.models import Sequential\n",
    "from keras.layers.core import Dense\n",
    "from keras.optimizers import SGD\n",
    "from keras.datasets import cifar10\n",
    "import matplotlib.pyplot as plt\n",
    "import numpy as np"
   ]
  },
  {
   "cell_type": "code",
   "execution_count": 2,
   "metadata": {},
   "outputs": [
    {
     "name": "stdout",
     "output_type": "stream",
     "text": [
      "[INFO] loading CIFAR-10 data...\n"
     ]
    }
   ],
   "source": [
    "# load the training and testing data, scale it into the range [0, 1],\n",
    "# then reshape the design matrix\n",
    "print(\"[INFO] loading CIFAR-10 data...\")\n",
    "((trainX, trainY), (testX, testY)) = cifar10.load_data()\n",
    "\n",
    "# reshaping data...each image is 32x32x3 (RGB)\n",
    "trainX = trainX.astype(\"float\") / 255.0\n",
    "testX = testX.astype(\"float\") / 255.0\n",
    "trainX = trainX.reshape((trainX.shape[0], 3072))\n",
    "testX = testX.reshape((testX.shape[0], 3072))"
   ]
  },
  {
   "cell_type": "code",
   "execution_count": 3,
   "metadata": {},
   "outputs": [],
   "source": [
    "# convert the labels from integers to vectors\n",
    "lb = LabelBinarizer()\n",
    "trainY = lb.fit_transform(trainY)\n",
    "testY = lb.transform(testY)"
   ]
  },
  {
   "cell_type": "code",
   "execution_count": 4,
   "metadata": {},
   "outputs": [],
   "source": [
    "# initialize the label names for the CIFAR-10 dataset\n",
    "labelNames = [\"airplane\", \"automobile\", \"bird\", \"cat\", \"deer\", \"dog\", \"frog\", \"horse\", \"ship\", \"truck\"]"
   ]
  },
  {
   "cell_type": "code",
   "execution_count": 5,
   "metadata": {},
   "outputs": [
    {
     "ename": "SystemError",
     "evalue": "<class 'range'> returned a result with an error set\nApply node that caused the error: Elemwise{Composite{(i0 + (i1 * i2))}}[(0, 2)](TensorConstant{(1, 1) of ..0.03827328}, TensorConstant{(1, 1) of 0.07654656}, mrg_uniform{TensorType(float32, matrix),inplace}.1)\nToposort index: 1\nInputs types: [TensorType(float32, (True, True)), TensorType(float32, (True, True)), TensorType(float32, matrix)]\nInputs shapes: [(1, 1), (1, 1), (3072, 1024)]\nInputs strides: [(4, 4), (4, 4), (4096, 4)]\nInputs values: [array([[-0.03827328]], dtype=float32), array([[0.07654656]], dtype=float32), 'not shown']\nOutputs clients: [['output']]\n\nHINT: Re-running with most Theano optimization disabled could give you a back-trace of when this node was created. This can be done with by setting the Theano flag 'optimizer=fast_compile'. If that does not work, Theano optimizations can be disabled with 'optimizer=None'.\nHINT: Use the Theano flag 'exception_verbosity=high' for a debugprint and storage map footprint of this apply node.",
     "output_type": "error",
     "traceback": [
      "\u001b[1;31m---------------------------------------------------------------------------\u001b[0m",
      "\u001b[1;31mKeyboardInterrupt\u001b[0m                         Traceback (most recent call last)",
      "\u001b[1;32m~\\Anaconda3\\lib\\site-packages\\theano\\scalar\\basic.py\u001b[0m in \u001b[0;36mimpl\u001b[1;34m(self, *inputs)\u001b[0m\n\u001b[0;32m   4023\u001b[0m         \u001b[0moutput_storage\u001b[0m \u001b[1;33m=\u001b[0m \u001b[1;33m[\u001b[0m\u001b[1;33m[\u001b[0m\u001b[1;32mNone\u001b[0m\u001b[1;33m]\u001b[0m \u001b[1;32mfor\u001b[0m \u001b[0mi\u001b[0m \u001b[1;32min\u001b[0m \u001b[0mxrange\u001b[0m\u001b[1;33m(\u001b[0m\u001b[0mself\u001b[0m\u001b[1;33m.\u001b[0m\u001b[0mnout\u001b[0m\u001b[1;33m)\u001b[0m\u001b[1;33m]\u001b[0m\u001b[1;33m\u001b[0m\u001b[0m\n\u001b[1;32m-> 4024\u001b[1;33m         \u001b[0mself\u001b[0m\u001b[1;33m.\u001b[0m\u001b[0mperform\u001b[0m\u001b[1;33m(\u001b[0m\u001b[1;32mNone\u001b[0m\u001b[1;33m,\u001b[0m \u001b[0minputs\u001b[0m\u001b[1;33m,\u001b[0m \u001b[0moutput_storage\u001b[0m\u001b[1;33m)\u001b[0m\u001b[1;33m\u001b[0m\u001b[0m\n\u001b[0m\u001b[0;32m   4025\u001b[0m         ret = utils.to_return_values([storage[0] for storage in\n",
      "\u001b[1;32m~\\Anaconda3\\lib\\site-packages\\theano\\scalar\\basic.py\u001b[0m in \u001b[0;36mperform\u001b[1;34m(self, node, inputs, output_storage)\u001b[0m\n\u001b[0;32m   4019\u001b[0m         \u001b[1;32mfor\u001b[0m \u001b[0mstorage\u001b[0m\u001b[1;33m,\u001b[0m \u001b[0mimpl\u001b[0m \u001b[1;32min\u001b[0m \u001b[0mzip\u001b[0m\u001b[1;33m(\u001b[0m\u001b[0moutput_storage\u001b[0m\u001b[1;33m,\u001b[0m \u001b[0mself\u001b[0m\u001b[1;33m.\u001b[0m\u001b[0m_impls\u001b[0m\u001b[1;33m)\u001b[0m\u001b[1;33m:\u001b[0m\u001b[1;33m\u001b[0m\u001b[0m\n\u001b[1;32m-> 4020\u001b[1;33m             \u001b[0mstorage\u001b[0m\u001b[1;33m[\u001b[0m\u001b[1;36m0\u001b[0m\u001b[1;33m]\u001b[0m \u001b[1;33m=\u001b[0m \u001b[0mimpl\u001b[0m\u001b[1;33m(\u001b[0m\u001b[0minputs\u001b[0m\u001b[1;33m)\u001b[0m\u001b[1;33m\u001b[0m\u001b[0m\n\u001b[0m\u001b[0;32m   4021\u001b[0m \u001b[1;33m\u001b[0m\u001b[0m\n",
      "\u001b[1;32m~\\Anaconda3\\lib\\site-packages\\theano\\scalar\\basic.py\u001b[0m in \u001b[0;36mf\u001b[1;34m(inputs)\u001b[0m\n\u001b[0;32m   3891\u001b[0m             \u001b[1;32mdef\u001b[0m \u001b[0mf\u001b[0m\u001b[1;33m(\u001b[0m\u001b[0minputs\u001b[0m\u001b[1;33m)\u001b[0m\u001b[1;33m:\u001b[0m\u001b[1;33m\u001b[0m\u001b[0m\n\u001b[1;32m-> 3892\u001b[1;33m                 \u001b[1;32mreturn\u001b[0m \u001b[0mnode\u001b[0m\u001b[1;33m.\u001b[0m\u001b[0mop\u001b[0m\u001b[1;33m.\u001b[0m\u001b[0mimpl\u001b[0m\u001b[1;33m(\u001b[0m\u001b[1;33m*\u001b[0m\u001b[1;33m[\u001b[0m\u001b[0mp\u001b[0m\u001b[1;33m(\u001b[0m\u001b[0minputs\u001b[0m\u001b[1;33m)\u001b[0m \u001b[1;32mfor\u001b[0m \u001b[0mp\u001b[0m \u001b[1;32min\u001b[0m \u001b[0mproducers\u001b[0m\u001b[1;33m]\u001b[0m\u001b[1;33m)\u001b[0m\u001b[1;33m\u001b[0m\u001b[0m\n\u001b[0m\u001b[0;32m   3893\u001b[0m             \u001b[0mmemo\u001b[0m\u001b[1;33m[\u001b[0m\u001b[0mr\u001b[0m\u001b[1;33m]\u001b[0m \u001b[1;33m=\u001b[0m \u001b[0mf\u001b[0m\u001b[1;33m\u001b[0m\u001b[0m\n",
      "\u001b[1;32m~\\Anaconda3\\lib\\site-packages\\theano\\scalar\\basic.py\u001b[0m in \u001b[0;36m<listcomp>\u001b[1;34m(.0)\u001b[0m\n\u001b[0;32m   3891\u001b[0m             \u001b[1;32mdef\u001b[0m \u001b[0mf\u001b[0m\u001b[1;33m(\u001b[0m\u001b[0minputs\u001b[0m\u001b[1;33m)\u001b[0m\u001b[1;33m:\u001b[0m\u001b[1;33m\u001b[0m\u001b[0m\n\u001b[1;32m-> 3892\u001b[1;33m                 \u001b[1;32mreturn\u001b[0m \u001b[0mnode\u001b[0m\u001b[1;33m.\u001b[0m\u001b[0mop\u001b[0m\u001b[1;33m.\u001b[0m\u001b[0mimpl\u001b[0m\u001b[1;33m(\u001b[0m\u001b[1;33m*\u001b[0m\u001b[1;33m[\u001b[0m\u001b[0mp\u001b[0m\u001b[1;33m(\u001b[0m\u001b[0minputs\u001b[0m\u001b[1;33m)\u001b[0m \u001b[1;32mfor\u001b[0m \u001b[0mp\u001b[0m \u001b[1;32min\u001b[0m \u001b[0mproducers\u001b[0m\u001b[1;33m]\u001b[0m\u001b[1;33m)\u001b[0m\u001b[1;33m\u001b[0m\u001b[0m\n\u001b[0m\u001b[0;32m   3893\u001b[0m             \u001b[0mmemo\u001b[0m\u001b[1;33m[\u001b[0m\u001b[0mr\u001b[0m\u001b[1;33m]\u001b[0m \u001b[1;33m=\u001b[0m \u001b[0mf\u001b[0m\u001b[1;33m\u001b[0m\u001b[0m\n",
      "\u001b[1;32m~\\Anaconda3\\lib\\site-packages\\theano\\scalar\\basic.py\u001b[0m in \u001b[0;36mf\u001b[1;34m(inputs)\u001b[0m\n\u001b[0;32m   3891\u001b[0m             \u001b[1;32mdef\u001b[0m \u001b[0mf\u001b[0m\u001b[1;33m(\u001b[0m\u001b[0minputs\u001b[0m\u001b[1;33m)\u001b[0m\u001b[1;33m:\u001b[0m\u001b[1;33m\u001b[0m\u001b[0m\n\u001b[1;32m-> 3892\u001b[1;33m                 \u001b[1;32mreturn\u001b[0m \u001b[0mnode\u001b[0m\u001b[1;33m.\u001b[0m\u001b[0mop\u001b[0m\u001b[1;33m.\u001b[0m\u001b[0mimpl\u001b[0m\u001b[1;33m(\u001b[0m\u001b[1;33m*\u001b[0m\u001b[1;33m[\u001b[0m\u001b[0mp\u001b[0m\u001b[1;33m(\u001b[0m\u001b[0minputs\u001b[0m\u001b[1;33m)\u001b[0m \u001b[1;32mfor\u001b[0m \u001b[0mp\u001b[0m \u001b[1;32min\u001b[0m \u001b[0mproducers\u001b[0m\u001b[1;33m]\u001b[0m\u001b[1;33m)\u001b[0m\u001b[1;33m\u001b[0m\u001b[0m\n\u001b[0m\u001b[0;32m   3893\u001b[0m             \u001b[0mmemo\u001b[0m\u001b[1;33m[\u001b[0m\u001b[0mr\u001b[0m\u001b[1;33m]\u001b[0m \u001b[1;33m=\u001b[0m \u001b[0mf\u001b[0m\u001b[1;33m\u001b[0m\u001b[0m\n",
      "\u001b[1;32m~\\Anaconda3\\lib\\site-packages\\theano\\scalar\\basic.py\u001b[0m in \u001b[0;36mimpl\u001b[1;34m(self, *inputs)\u001b[0m\n\u001b[0;32m   1748\u001b[0m     \u001b[1;32mdef\u001b[0m \u001b[0mimpl\u001b[0m\u001b[1;33m(\u001b[0m\u001b[0mself\u001b[0m\u001b[1;33m,\u001b[0m \u001b[1;33m*\u001b[0m\u001b[0minputs\u001b[0m\u001b[1;33m)\u001b[0m\u001b[1;33m:\u001b[0m\u001b[1;33m\u001b[0m\u001b[0m\n\u001b[1;32m-> 1749\u001b[1;33m         \u001b[1;32mreturn\u001b[0m \u001b[0mnp\u001b[0m\u001b[1;33m.\u001b[0m\u001b[0mproduct\u001b[0m\u001b[1;33m(\u001b[0m\u001b[0minputs\u001b[0m\u001b[1;33m)\u001b[0m\u001b[1;33m\u001b[0m\u001b[0m\n\u001b[0m\u001b[0;32m   1750\u001b[0m \u001b[1;33m\u001b[0m\u001b[0m\n",
      "\u001b[1;31mKeyboardInterrupt\u001b[0m: ",
      "\nThe above exception was the direct cause of the following exception:\n",
      "\u001b[1;31mSystemError\u001b[0m                               Traceback (most recent call last)",
      "\u001b[1;32m~\\Anaconda3\\lib\\site-packages\\theano\\scalar\\basic.py\u001b[0m in \u001b[0;36mimpl\u001b[1;34m(self, *inputs)\u001b[0m\n\u001b[0;32m   4022\u001b[0m     \u001b[1;32mdef\u001b[0m \u001b[0mimpl\u001b[0m\u001b[1;33m(\u001b[0m\u001b[0mself\u001b[0m\u001b[1;33m,\u001b[0m \u001b[1;33m*\u001b[0m\u001b[0minputs\u001b[0m\u001b[1;33m)\u001b[0m\u001b[1;33m:\u001b[0m\u001b[1;33m\u001b[0m\u001b[0m\n\u001b[1;32m-> 4023\u001b[1;33m         \u001b[0moutput_storage\u001b[0m \u001b[1;33m=\u001b[0m \u001b[1;33m[\u001b[0m\u001b[1;33m[\u001b[0m\u001b[1;32mNone\u001b[0m\u001b[1;33m]\u001b[0m \u001b[1;32mfor\u001b[0m \u001b[0mi\u001b[0m \u001b[1;32min\u001b[0m \u001b[0mxrange\u001b[0m\u001b[1;33m(\u001b[0m\u001b[0mself\u001b[0m\u001b[1;33m.\u001b[0m\u001b[0mnout\u001b[0m\u001b[1;33m)\u001b[0m\u001b[1;33m]\u001b[0m\u001b[1;33m\u001b[0m\u001b[0m\n\u001b[0m\u001b[0;32m   4024\u001b[0m         \u001b[0mself\u001b[0m\u001b[1;33m.\u001b[0m\u001b[0mperform\u001b[0m\u001b[1;33m(\u001b[0m\u001b[1;32mNone\u001b[0m\u001b[1;33m,\u001b[0m \u001b[0minputs\u001b[0m\u001b[1;33m,\u001b[0m \u001b[0moutput_storage\u001b[0m\u001b[1;33m)\u001b[0m\u001b[1;33m\u001b[0m\u001b[0m\n",
      "\u001b[1;31mSystemError\u001b[0m: <class 'range'> returned a result with an error set",
      "\nThe above exception was the direct cause of the following exception:\n",
      "\u001b[1;31mSystemError\u001b[0m                               Traceback (most recent call last)",
      "\u001b[1;32m~\\Anaconda3\\lib\\site-packages\\theano\\scalar\\basic.py\u001b[0m in \u001b[0;36mimpl\u001b[1;34m(self, *inputs)\u001b[0m\n\u001b[0;32m   4022\u001b[0m     \u001b[1;32mdef\u001b[0m \u001b[0mimpl\u001b[0m\u001b[1;33m(\u001b[0m\u001b[0mself\u001b[0m\u001b[1;33m,\u001b[0m \u001b[1;33m*\u001b[0m\u001b[0minputs\u001b[0m\u001b[1;33m)\u001b[0m\u001b[1;33m:\u001b[0m\u001b[1;33m\u001b[0m\u001b[0m\n\u001b[1;32m-> 4023\u001b[1;33m         \u001b[0moutput_storage\u001b[0m \u001b[1;33m=\u001b[0m \u001b[1;33m[\u001b[0m\u001b[1;33m[\u001b[0m\u001b[1;32mNone\u001b[0m\u001b[1;33m]\u001b[0m \u001b[1;32mfor\u001b[0m \u001b[0mi\u001b[0m \u001b[1;32min\u001b[0m \u001b[0mxrange\u001b[0m\u001b[1;33m(\u001b[0m\u001b[0mself\u001b[0m\u001b[1;33m.\u001b[0m\u001b[0mnout\u001b[0m\u001b[1;33m)\u001b[0m\u001b[1;33m]\u001b[0m\u001b[1;33m\u001b[0m\u001b[0m\n\u001b[0m\u001b[0;32m   4024\u001b[0m         \u001b[0mself\u001b[0m\u001b[1;33m.\u001b[0m\u001b[0mperform\u001b[0m\u001b[1;33m(\u001b[0m\u001b[1;32mNone\u001b[0m\u001b[1;33m,\u001b[0m \u001b[0minputs\u001b[0m\u001b[1;33m,\u001b[0m \u001b[0moutput_storage\u001b[0m\u001b[1;33m)\u001b[0m\u001b[1;33m\u001b[0m\u001b[0m\n",
      "\u001b[1;31mSystemError\u001b[0m: <class 'range'> returned a result with an error set",
      "\nThe above exception was the direct cause of the following exception:\n",
      "\u001b[1;31mSystemError\u001b[0m                               Traceback (most recent call last)",
      "\u001b[1;32m~\\Anaconda3\\lib\\site-packages\\theano\\scalar\\basic.py\u001b[0m in \u001b[0;36mimpl\u001b[1;34m(self, *inputs)\u001b[0m\n\u001b[0;32m   4022\u001b[0m     \u001b[1;32mdef\u001b[0m \u001b[0mimpl\u001b[0m\u001b[1;33m(\u001b[0m\u001b[0mself\u001b[0m\u001b[1;33m,\u001b[0m \u001b[1;33m*\u001b[0m\u001b[0minputs\u001b[0m\u001b[1;33m)\u001b[0m\u001b[1;33m:\u001b[0m\u001b[1;33m\u001b[0m\u001b[0m\n\u001b[1;32m-> 4023\u001b[1;33m         \u001b[0moutput_storage\u001b[0m \u001b[1;33m=\u001b[0m \u001b[1;33m[\u001b[0m\u001b[1;33m[\u001b[0m\u001b[1;32mNone\u001b[0m\u001b[1;33m]\u001b[0m \u001b[1;32mfor\u001b[0m \u001b[0mi\u001b[0m \u001b[1;32min\u001b[0m \u001b[0mxrange\u001b[0m\u001b[1;33m(\u001b[0m\u001b[0mself\u001b[0m\u001b[1;33m.\u001b[0m\u001b[0mnout\u001b[0m\u001b[1;33m)\u001b[0m\u001b[1;33m]\u001b[0m\u001b[1;33m\u001b[0m\u001b[0m\n\u001b[0m\u001b[0;32m   4024\u001b[0m         \u001b[0mself\u001b[0m\u001b[1;33m.\u001b[0m\u001b[0mperform\u001b[0m\u001b[1;33m(\u001b[0m\u001b[1;32mNone\u001b[0m\u001b[1;33m,\u001b[0m \u001b[0minputs\u001b[0m\u001b[1;33m,\u001b[0m \u001b[0moutput_storage\u001b[0m\u001b[1;33m)\u001b[0m\u001b[1;33m\u001b[0m\u001b[0m\n",
      "\u001b[1;31mSystemError\u001b[0m: <class 'range'> returned a result with an error set",
      "\nThe above exception was the direct cause of the following exception:\n",
      "\u001b[1;31mSystemError\u001b[0m                               Traceback (most recent call last)",
      "\u001b[1;32m~\\Anaconda3\\lib\\site-packages\\theano\\scalar\\basic.py\u001b[0m in \u001b[0;36mimpl\u001b[1;34m(self, *inputs)\u001b[0m\n\u001b[0;32m   4022\u001b[0m     \u001b[1;32mdef\u001b[0m \u001b[0mimpl\u001b[0m\u001b[1;33m(\u001b[0m\u001b[0mself\u001b[0m\u001b[1;33m,\u001b[0m \u001b[1;33m*\u001b[0m\u001b[0minputs\u001b[0m\u001b[1;33m)\u001b[0m\u001b[1;33m:\u001b[0m\u001b[1;33m\u001b[0m\u001b[0m\n\u001b[1;32m-> 4023\u001b[1;33m         \u001b[0moutput_storage\u001b[0m \u001b[1;33m=\u001b[0m \u001b[1;33m[\u001b[0m\u001b[1;33m[\u001b[0m\u001b[1;32mNone\u001b[0m\u001b[1;33m]\u001b[0m \u001b[1;32mfor\u001b[0m \u001b[0mi\u001b[0m \u001b[1;32min\u001b[0m \u001b[0mxrange\u001b[0m\u001b[1;33m(\u001b[0m\u001b[0mself\u001b[0m\u001b[1;33m.\u001b[0m\u001b[0mnout\u001b[0m\u001b[1;33m)\u001b[0m\u001b[1;33m]\u001b[0m\u001b[1;33m\u001b[0m\u001b[0m\n\u001b[0m\u001b[0;32m   4024\u001b[0m         \u001b[0mself\u001b[0m\u001b[1;33m.\u001b[0m\u001b[0mperform\u001b[0m\u001b[1;33m(\u001b[0m\u001b[1;32mNone\u001b[0m\u001b[1;33m,\u001b[0m \u001b[0minputs\u001b[0m\u001b[1;33m,\u001b[0m \u001b[0moutput_storage\u001b[0m\u001b[1;33m)\u001b[0m\u001b[1;33m\u001b[0m\u001b[0m\n",
      "\u001b[1;31mSystemError\u001b[0m: <class 'range'> returned a result with an error set",
      "\nThe above exception was the direct cause of the following exception:\n",
      "\u001b[1;31mSystemError\u001b[0m                               Traceback (most recent call last)",
      "\u001b[1;32m~\\Anaconda3\\lib\\site-packages\\theano\\scalar\\basic.py\u001b[0m in \u001b[0;36mimpl\u001b[1;34m(self, *inputs)\u001b[0m\n\u001b[0;32m   4022\u001b[0m     \u001b[1;32mdef\u001b[0m \u001b[0mimpl\u001b[0m\u001b[1;33m(\u001b[0m\u001b[0mself\u001b[0m\u001b[1;33m,\u001b[0m \u001b[1;33m*\u001b[0m\u001b[0minputs\u001b[0m\u001b[1;33m)\u001b[0m\u001b[1;33m:\u001b[0m\u001b[1;33m\u001b[0m\u001b[0m\n\u001b[1;32m-> 4023\u001b[1;33m         \u001b[0moutput_storage\u001b[0m \u001b[1;33m=\u001b[0m \u001b[1;33m[\u001b[0m\u001b[1;33m[\u001b[0m\u001b[1;32mNone\u001b[0m\u001b[1;33m]\u001b[0m \u001b[1;32mfor\u001b[0m \u001b[0mi\u001b[0m \u001b[1;32min\u001b[0m \u001b[0mxrange\u001b[0m\u001b[1;33m(\u001b[0m\u001b[0mself\u001b[0m\u001b[1;33m.\u001b[0m\u001b[0mnout\u001b[0m\u001b[1;33m)\u001b[0m\u001b[1;33m]\u001b[0m\u001b[1;33m\u001b[0m\u001b[0m\n\u001b[0m\u001b[0;32m   4024\u001b[0m         \u001b[0mself\u001b[0m\u001b[1;33m.\u001b[0m\u001b[0mperform\u001b[0m\u001b[1;33m(\u001b[0m\u001b[1;32mNone\u001b[0m\u001b[1;33m,\u001b[0m \u001b[0minputs\u001b[0m\u001b[1;33m,\u001b[0m \u001b[0moutput_storage\u001b[0m\u001b[1;33m)\u001b[0m\u001b[1;33m\u001b[0m\u001b[0m\n",
      "\u001b[1;31mSystemError\u001b[0m: <class 'range'> returned a result with an error set",
      "\nThe above exception was the direct cause of the following exception:\n",
      "\u001b[1;31mSystemError\u001b[0m                               Traceback (most recent call last)",
      "\u001b[1;32m~\\Anaconda3\\lib\\site-packages\\theano\\scalar\\basic.py\u001b[0m in \u001b[0;36mimpl\u001b[1;34m(self, *inputs)\u001b[0m\n\u001b[0;32m   4022\u001b[0m     \u001b[1;32mdef\u001b[0m \u001b[0mimpl\u001b[0m\u001b[1;33m(\u001b[0m\u001b[0mself\u001b[0m\u001b[1;33m,\u001b[0m \u001b[1;33m*\u001b[0m\u001b[0minputs\u001b[0m\u001b[1;33m)\u001b[0m\u001b[1;33m:\u001b[0m\u001b[1;33m\u001b[0m\u001b[0m\n\u001b[1;32m-> 4023\u001b[1;33m         \u001b[0moutput_storage\u001b[0m \u001b[1;33m=\u001b[0m \u001b[1;33m[\u001b[0m\u001b[1;33m[\u001b[0m\u001b[1;32mNone\u001b[0m\u001b[1;33m]\u001b[0m \u001b[1;32mfor\u001b[0m \u001b[0mi\u001b[0m \u001b[1;32min\u001b[0m \u001b[0mxrange\u001b[0m\u001b[1;33m(\u001b[0m\u001b[0mself\u001b[0m\u001b[1;33m.\u001b[0m\u001b[0mnout\u001b[0m\u001b[1;33m)\u001b[0m\u001b[1;33m]\u001b[0m\u001b[1;33m\u001b[0m\u001b[0m\n\u001b[0m\u001b[0;32m   4024\u001b[0m         \u001b[0mself\u001b[0m\u001b[1;33m.\u001b[0m\u001b[0mperform\u001b[0m\u001b[1;33m(\u001b[0m\u001b[1;32mNone\u001b[0m\u001b[1;33m,\u001b[0m \u001b[0minputs\u001b[0m\u001b[1;33m,\u001b[0m \u001b[0moutput_storage\u001b[0m\u001b[1;33m)\u001b[0m\u001b[1;33m\u001b[0m\u001b[0m\n",
      "\u001b[1;31mSystemError\u001b[0m: <class 'range'> returned a result with an error set",
      "\nThe above exception was the direct cause of the following exception:\n",
      "\u001b[1;31mSystemError\u001b[0m                               Traceback (most recent call last)",
      "\u001b[1;32m~\\Anaconda3\\lib\\site-packages\\theano\\scalar\\basic.py\u001b[0m in \u001b[0;36mimpl\u001b[1;34m(self, *inputs)\u001b[0m\n\u001b[0;32m   4022\u001b[0m     \u001b[1;32mdef\u001b[0m \u001b[0mimpl\u001b[0m\u001b[1;33m(\u001b[0m\u001b[0mself\u001b[0m\u001b[1;33m,\u001b[0m \u001b[1;33m*\u001b[0m\u001b[0minputs\u001b[0m\u001b[1;33m)\u001b[0m\u001b[1;33m:\u001b[0m\u001b[1;33m\u001b[0m\u001b[0m\n\u001b[1;32m-> 4023\u001b[1;33m         \u001b[0moutput_storage\u001b[0m \u001b[1;33m=\u001b[0m \u001b[1;33m[\u001b[0m\u001b[1;33m[\u001b[0m\u001b[1;32mNone\u001b[0m\u001b[1;33m]\u001b[0m \u001b[1;32mfor\u001b[0m \u001b[0mi\u001b[0m \u001b[1;32min\u001b[0m \u001b[0mxrange\u001b[0m\u001b[1;33m(\u001b[0m\u001b[0mself\u001b[0m\u001b[1;33m.\u001b[0m\u001b[0mnout\u001b[0m\u001b[1;33m)\u001b[0m\u001b[1;33m]\u001b[0m\u001b[1;33m\u001b[0m\u001b[0m\n\u001b[0m\u001b[0;32m   4024\u001b[0m         \u001b[0mself\u001b[0m\u001b[1;33m.\u001b[0m\u001b[0mperform\u001b[0m\u001b[1;33m(\u001b[0m\u001b[1;32mNone\u001b[0m\u001b[1;33m,\u001b[0m \u001b[0minputs\u001b[0m\u001b[1;33m,\u001b[0m \u001b[0moutput_storage\u001b[0m\u001b[1;33m)\u001b[0m\u001b[1;33m\u001b[0m\u001b[0m\n",
      "\u001b[1;31mSystemError\u001b[0m: <class 'range'> returned a result with an error set",
      "\nThe above exception was the direct cause of the following exception:\n",
      "\u001b[1;31mSystemError\u001b[0m                               Traceback (most recent call last)",
      "\u001b[1;32m~\\Anaconda3\\lib\\site-packages\\theano\\scalar\\basic.py\u001b[0m in \u001b[0;36mimpl\u001b[1;34m(self, *inputs)\u001b[0m\n\u001b[0;32m   4022\u001b[0m     \u001b[1;32mdef\u001b[0m \u001b[0mimpl\u001b[0m\u001b[1;33m(\u001b[0m\u001b[0mself\u001b[0m\u001b[1;33m,\u001b[0m \u001b[1;33m*\u001b[0m\u001b[0minputs\u001b[0m\u001b[1;33m)\u001b[0m\u001b[1;33m:\u001b[0m\u001b[1;33m\u001b[0m\u001b[0m\n\u001b[1;32m-> 4023\u001b[1;33m         \u001b[0moutput_storage\u001b[0m \u001b[1;33m=\u001b[0m \u001b[1;33m[\u001b[0m\u001b[1;33m[\u001b[0m\u001b[1;32mNone\u001b[0m\u001b[1;33m]\u001b[0m \u001b[1;32mfor\u001b[0m \u001b[0mi\u001b[0m \u001b[1;32min\u001b[0m \u001b[0mxrange\u001b[0m\u001b[1;33m(\u001b[0m\u001b[0mself\u001b[0m\u001b[1;33m.\u001b[0m\u001b[0mnout\u001b[0m\u001b[1;33m)\u001b[0m\u001b[1;33m]\u001b[0m\u001b[1;33m\u001b[0m\u001b[0m\n\u001b[0m\u001b[0;32m   4024\u001b[0m         \u001b[0mself\u001b[0m\u001b[1;33m.\u001b[0m\u001b[0mperform\u001b[0m\u001b[1;33m(\u001b[0m\u001b[1;32mNone\u001b[0m\u001b[1;33m,\u001b[0m \u001b[0minputs\u001b[0m\u001b[1;33m,\u001b[0m \u001b[0moutput_storage\u001b[0m\u001b[1;33m)\u001b[0m\u001b[1;33m\u001b[0m\u001b[0m\n",
      "\u001b[1;31mSystemError\u001b[0m: <class 'range'> returned a result with an error set",
      "\nThe above exception was the direct cause of the following exception:\n",
      "\u001b[1;31mSystemError\u001b[0m                               Traceback (most recent call last)",
      "\u001b[1;32m~\\Anaconda3\\lib\\site-packages\\theano\\scalar\\basic.py\u001b[0m in \u001b[0;36mimpl\u001b[1;34m(self, *inputs)\u001b[0m\n\u001b[0;32m   4022\u001b[0m     \u001b[1;32mdef\u001b[0m \u001b[0mimpl\u001b[0m\u001b[1;33m(\u001b[0m\u001b[0mself\u001b[0m\u001b[1;33m,\u001b[0m \u001b[1;33m*\u001b[0m\u001b[0minputs\u001b[0m\u001b[1;33m)\u001b[0m\u001b[1;33m:\u001b[0m\u001b[1;33m\u001b[0m\u001b[0m\n\u001b[1;32m-> 4023\u001b[1;33m         \u001b[0moutput_storage\u001b[0m \u001b[1;33m=\u001b[0m \u001b[1;33m[\u001b[0m\u001b[1;33m[\u001b[0m\u001b[1;32mNone\u001b[0m\u001b[1;33m]\u001b[0m \u001b[1;32mfor\u001b[0m \u001b[0mi\u001b[0m \u001b[1;32min\u001b[0m \u001b[0mxrange\u001b[0m\u001b[1;33m(\u001b[0m\u001b[0mself\u001b[0m\u001b[1;33m.\u001b[0m\u001b[0mnout\u001b[0m\u001b[1;33m)\u001b[0m\u001b[1;33m]\u001b[0m\u001b[1;33m\u001b[0m\u001b[0m\n\u001b[0m\u001b[0;32m   4024\u001b[0m         \u001b[0mself\u001b[0m\u001b[1;33m.\u001b[0m\u001b[0mperform\u001b[0m\u001b[1;33m(\u001b[0m\u001b[1;32mNone\u001b[0m\u001b[1;33m,\u001b[0m \u001b[0minputs\u001b[0m\u001b[1;33m,\u001b[0m \u001b[0moutput_storage\u001b[0m\u001b[1;33m)\u001b[0m\u001b[1;33m\u001b[0m\u001b[0m\n",
      "\u001b[1;31mSystemError\u001b[0m: <class 'range'> returned a result with an error set",
      "\nThe above exception was the direct cause of the following exception:\n",
      "\u001b[1;31mSystemError\u001b[0m                               Traceback (most recent call last)",
      "\u001b[1;32m~\\Anaconda3\\lib\\site-packages\\theano\\scalar\\basic.py\u001b[0m in \u001b[0;36mimpl\u001b[1;34m(self, *inputs)\u001b[0m\n\u001b[0;32m   4022\u001b[0m     \u001b[1;32mdef\u001b[0m \u001b[0mimpl\u001b[0m\u001b[1;33m(\u001b[0m\u001b[0mself\u001b[0m\u001b[1;33m,\u001b[0m \u001b[1;33m*\u001b[0m\u001b[0minputs\u001b[0m\u001b[1;33m)\u001b[0m\u001b[1;33m:\u001b[0m\u001b[1;33m\u001b[0m\u001b[0m\n\u001b[1;32m-> 4023\u001b[1;33m         \u001b[0moutput_storage\u001b[0m \u001b[1;33m=\u001b[0m \u001b[1;33m[\u001b[0m\u001b[1;33m[\u001b[0m\u001b[1;32mNone\u001b[0m\u001b[1;33m]\u001b[0m \u001b[1;32mfor\u001b[0m \u001b[0mi\u001b[0m \u001b[1;32min\u001b[0m \u001b[0mxrange\u001b[0m\u001b[1;33m(\u001b[0m\u001b[0mself\u001b[0m\u001b[1;33m.\u001b[0m\u001b[0mnout\u001b[0m\u001b[1;33m)\u001b[0m\u001b[1;33m]\u001b[0m\u001b[1;33m\u001b[0m\u001b[0m\n\u001b[0m\u001b[0;32m   4024\u001b[0m         \u001b[0mself\u001b[0m\u001b[1;33m.\u001b[0m\u001b[0mperform\u001b[0m\u001b[1;33m(\u001b[0m\u001b[1;32mNone\u001b[0m\u001b[1;33m,\u001b[0m \u001b[0minputs\u001b[0m\u001b[1;33m,\u001b[0m \u001b[0moutput_storage\u001b[0m\u001b[1;33m)\u001b[0m\u001b[1;33m\u001b[0m\u001b[0m\n",
      "\u001b[1;31mSystemError\u001b[0m: <class 'range'> returned a result with an error set",
      "\nThe above exception was the direct cause of the following exception:\n",
      "\u001b[1;31mSystemError\u001b[0m                               Traceback (most recent call last)",
      "\u001b[1;32m~\\Anaconda3\\lib\\site-packages\\theano\\scalar\\basic.py\u001b[0m in \u001b[0;36mimpl\u001b[1;34m(self, *inputs)\u001b[0m\n\u001b[0;32m   4022\u001b[0m     \u001b[1;32mdef\u001b[0m \u001b[0mimpl\u001b[0m\u001b[1;33m(\u001b[0m\u001b[0mself\u001b[0m\u001b[1;33m,\u001b[0m \u001b[1;33m*\u001b[0m\u001b[0minputs\u001b[0m\u001b[1;33m)\u001b[0m\u001b[1;33m:\u001b[0m\u001b[1;33m\u001b[0m\u001b[0m\n\u001b[1;32m-> 4023\u001b[1;33m         \u001b[0moutput_storage\u001b[0m \u001b[1;33m=\u001b[0m \u001b[1;33m[\u001b[0m\u001b[1;33m[\u001b[0m\u001b[1;32mNone\u001b[0m\u001b[1;33m]\u001b[0m \u001b[1;32mfor\u001b[0m \u001b[0mi\u001b[0m \u001b[1;32min\u001b[0m \u001b[0mxrange\u001b[0m\u001b[1;33m(\u001b[0m\u001b[0mself\u001b[0m\u001b[1;33m.\u001b[0m\u001b[0mnout\u001b[0m\u001b[1;33m)\u001b[0m\u001b[1;33m]\u001b[0m\u001b[1;33m\u001b[0m\u001b[0m\n\u001b[0m\u001b[0;32m   4024\u001b[0m         \u001b[0mself\u001b[0m\u001b[1;33m.\u001b[0m\u001b[0mperform\u001b[0m\u001b[1;33m(\u001b[0m\u001b[1;32mNone\u001b[0m\u001b[1;33m,\u001b[0m \u001b[0minputs\u001b[0m\u001b[1;33m,\u001b[0m \u001b[0moutput_storage\u001b[0m\u001b[1;33m)\u001b[0m\u001b[1;33m\u001b[0m\u001b[0m\n",
      "\u001b[1;31mSystemError\u001b[0m: <class 'range'> returned a result with an error set",
      "\nThe above exception was the direct cause of the following exception:\n",
      "\u001b[1;31mSystemError\u001b[0m                               Traceback (most recent call last)",
      "\u001b[1;32m~\\Anaconda3\\lib\\site-packages\\theano\\scalar\\basic.py\u001b[0m in \u001b[0;36mimpl\u001b[1;34m(self, *inputs)\u001b[0m\n\u001b[0;32m   4022\u001b[0m     \u001b[1;32mdef\u001b[0m \u001b[0mimpl\u001b[0m\u001b[1;33m(\u001b[0m\u001b[0mself\u001b[0m\u001b[1;33m,\u001b[0m \u001b[1;33m*\u001b[0m\u001b[0minputs\u001b[0m\u001b[1;33m)\u001b[0m\u001b[1;33m:\u001b[0m\u001b[1;33m\u001b[0m\u001b[0m\n\u001b[1;32m-> 4023\u001b[1;33m         \u001b[0moutput_storage\u001b[0m \u001b[1;33m=\u001b[0m \u001b[1;33m[\u001b[0m\u001b[1;33m[\u001b[0m\u001b[1;32mNone\u001b[0m\u001b[1;33m]\u001b[0m \u001b[1;32mfor\u001b[0m \u001b[0mi\u001b[0m \u001b[1;32min\u001b[0m \u001b[0mxrange\u001b[0m\u001b[1;33m(\u001b[0m\u001b[0mself\u001b[0m\u001b[1;33m.\u001b[0m\u001b[0mnout\u001b[0m\u001b[1;33m)\u001b[0m\u001b[1;33m]\u001b[0m\u001b[1;33m\u001b[0m\u001b[0m\n\u001b[0m\u001b[0;32m   4024\u001b[0m         \u001b[0mself\u001b[0m\u001b[1;33m.\u001b[0m\u001b[0mperform\u001b[0m\u001b[1;33m(\u001b[0m\u001b[1;32mNone\u001b[0m\u001b[1;33m,\u001b[0m \u001b[0minputs\u001b[0m\u001b[1;33m,\u001b[0m \u001b[0moutput_storage\u001b[0m\u001b[1;33m)\u001b[0m\u001b[1;33m\u001b[0m\u001b[0m\n",
      "\u001b[1;31mSystemError\u001b[0m: <class 'range'> returned a result with an error set",
      "\nThe above exception was the direct cause of the following exception:\n",
      "\u001b[1;31mSystemError\u001b[0m                               Traceback (most recent call last)",
      "\u001b[1;32m~\\Anaconda3\\lib\\site-packages\\theano\\scalar\\basic.py\u001b[0m in \u001b[0;36mimpl\u001b[1;34m(self, *inputs)\u001b[0m\n\u001b[0;32m   4022\u001b[0m     \u001b[1;32mdef\u001b[0m \u001b[0mimpl\u001b[0m\u001b[1;33m(\u001b[0m\u001b[0mself\u001b[0m\u001b[1;33m,\u001b[0m \u001b[1;33m*\u001b[0m\u001b[0minputs\u001b[0m\u001b[1;33m)\u001b[0m\u001b[1;33m:\u001b[0m\u001b[1;33m\u001b[0m\u001b[0m\n\u001b[1;32m-> 4023\u001b[1;33m         \u001b[0moutput_storage\u001b[0m \u001b[1;33m=\u001b[0m \u001b[1;33m[\u001b[0m\u001b[1;33m[\u001b[0m\u001b[1;32mNone\u001b[0m\u001b[1;33m]\u001b[0m \u001b[1;32mfor\u001b[0m \u001b[0mi\u001b[0m \u001b[1;32min\u001b[0m \u001b[0mxrange\u001b[0m\u001b[1;33m(\u001b[0m\u001b[0mself\u001b[0m\u001b[1;33m.\u001b[0m\u001b[0mnout\u001b[0m\u001b[1;33m)\u001b[0m\u001b[1;33m]\u001b[0m\u001b[1;33m\u001b[0m\u001b[0m\n\u001b[0m\u001b[0;32m   4024\u001b[0m         \u001b[0mself\u001b[0m\u001b[1;33m.\u001b[0m\u001b[0mperform\u001b[0m\u001b[1;33m(\u001b[0m\u001b[1;32mNone\u001b[0m\u001b[1;33m,\u001b[0m \u001b[0minputs\u001b[0m\u001b[1;33m,\u001b[0m \u001b[0moutput_storage\u001b[0m\u001b[1;33m)\u001b[0m\u001b[1;33m\u001b[0m\u001b[0m\n",
      "\u001b[1;31mSystemError\u001b[0m: <class 'range'> returned a result with an error set",
      "\nThe above exception was the direct cause of the following exception:\n",
      "\u001b[1;31mSystemError\u001b[0m                               Traceback (most recent call last)",
      "\u001b[1;32m~\\Anaconda3\\lib\\site-packages\\theano\\scalar\\basic.py\u001b[0m in \u001b[0;36mimpl\u001b[1;34m(self, *inputs)\u001b[0m\n\u001b[0;32m   4022\u001b[0m     \u001b[1;32mdef\u001b[0m \u001b[0mimpl\u001b[0m\u001b[1;33m(\u001b[0m\u001b[0mself\u001b[0m\u001b[1;33m,\u001b[0m \u001b[1;33m*\u001b[0m\u001b[0minputs\u001b[0m\u001b[1;33m)\u001b[0m\u001b[1;33m:\u001b[0m\u001b[1;33m\u001b[0m\u001b[0m\n\u001b[1;32m-> 4023\u001b[1;33m         \u001b[0moutput_storage\u001b[0m \u001b[1;33m=\u001b[0m \u001b[1;33m[\u001b[0m\u001b[1;33m[\u001b[0m\u001b[1;32mNone\u001b[0m\u001b[1;33m]\u001b[0m \u001b[1;32mfor\u001b[0m \u001b[0mi\u001b[0m \u001b[1;32min\u001b[0m \u001b[0mxrange\u001b[0m\u001b[1;33m(\u001b[0m\u001b[0mself\u001b[0m\u001b[1;33m.\u001b[0m\u001b[0mnout\u001b[0m\u001b[1;33m)\u001b[0m\u001b[1;33m]\u001b[0m\u001b[1;33m\u001b[0m\u001b[0m\n\u001b[0m\u001b[0;32m   4024\u001b[0m         \u001b[0mself\u001b[0m\u001b[1;33m.\u001b[0m\u001b[0mperform\u001b[0m\u001b[1;33m(\u001b[0m\u001b[1;32mNone\u001b[0m\u001b[1;33m,\u001b[0m \u001b[0minputs\u001b[0m\u001b[1;33m,\u001b[0m \u001b[0moutput_storage\u001b[0m\u001b[1;33m)\u001b[0m\u001b[1;33m\u001b[0m\u001b[0m\n",
      "\u001b[1;31mSystemError\u001b[0m: <class 'range'> returned a result with an error set",
      "\nThe above exception was the direct cause of the following exception:\n",
      "\u001b[1;31mSystemError\u001b[0m                               Traceback (most recent call last)",
      "\u001b[1;32m~\\Anaconda3\\lib\\site-packages\\theano\\scalar\\basic.py\u001b[0m in \u001b[0;36mimpl\u001b[1;34m(self, *inputs)\u001b[0m\n\u001b[0;32m   4022\u001b[0m     \u001b[1;32mdef\u001b[0m \u001b[0mimpl\u001b[0m\u001b[1;33m(\u001b[0m\u001b[0mself\u001b[0m\u001b[1;33m,\u001b[0m \u001b[1;33m*\u001b[0m\u001b[0minputs\u001b[0m\u001b[1;33m)\u001b[0m\u001b[1;33m:\u001b[0m\u001b[1;33m\u001b[0m\u001b[0m\n\u001b[1;32m-> 4023\u001b[1;33m         \u001b[0moutput_storage\u001b[0m \u001b[1;33m=\u001b[0m \u001b[1;33m[\u001b[0m\u001b[1;33m[\u001b[0m\u001b[1;32mNone\u001b[0m\u001b[1;33m]\u001b[0m \u001b[1;32mfor\u001b[0m \u001b[0mi\u001b[0m \u001b[1;32min\u001b[0m \u001b[0mxrange\u001b[0m\u001b[1;33m(\u001b[0m\u001b[0mself\u001b[0m\u001b[1;33m.\u001b[0m\u001b[0mnout\u001b[0m\u001b[1;33m)\u001b[0m\u001b[1;33m]\u001b[0m\u001b[1;33m\u001b[0m\u001b[0m\n\u001b[0m\u001b[0;32m   4024\u001b[0m         \u001b[0mself\u001b[0m\u001b[1;33m.\u001b[0m\u001b[0mperform\u001b[0m\u001b[1;33m(\u001b[0m\u001b[1;32mNone\u001b[0m\u001b[1;33m,\u001b[0m \u001b[0minputs\u001b[0m\u001b[1;33m,\u001b[0m \u001b[0moutput_storage\u001b[0m\u001b[1;33m)\u001b[0m\u001b[1;33m\u001b[0m\u001b[0m\n",
      "\u001b[1;31mSystemError\u001b[0m: <class 'range'> returned a result with an error set",
      "\nThe above exception was the direct cause of the following exception:\n",
      "\u001b[1;31mSystemError\u001b[0m                               Traceback (most recent call last)",
      "\u001b[1;32m~\\Anaconda3\\lib\\site-packages\\theano\\scalar\\basic.py\u001b[0m in \u001b[0;36mimpl\u001b[1;34m(self, *inputs)\u001b[0m\n\u001b[0;32m   4022\u001b[0m     \u001b[1;32mdef\u001b[0m \u001b[0mimpl\u001b[0m\u001b[1;33m(\u001b[0m\u001b[0mself\u001b[0m\u001b[1;33m,\u001b[0m \u001b[1;33m*\u001b[0m\u001b[0minputs\u001b[0m\u001b[1;33m)\u001b[0m\u001b[1;33m:\u001b[0m\u001b[1;33m\u001b[0m\u001b[0m\n\u001b[1;32m-> 4023\u001b[1;33m         \u001b[0moutput_storage\u001b[0m \u001b[1;33m=\u001b[0m \u001b[1;33m[\u001b[0m\u001b[1;33m[\u001b[0m\u001b[1;32mNone\u001b[0m\u001b[1;33m]\u001b[0m \u001b[1;32mfor\u001b[0m \u001b[0mi\u001b[0m \u001b[1;32min\u001b[0m \u001b[0mxrange\u001b[0m\u001b[1;33m(\u001b[0m\u001b[0mself\u001b[0m\u001b[1;33m.\u001b[0m\u001b[0mnout\u001b[0m\u001b[1;33m)\u001b[0m\u001b[1;33m]\u001b[0m\u001b[1;33m\u001b[0m\u001b[0m\n\u001b[0m\u001b[0;32m   4024\u001b[0m         \u001b[0mself\u001b[0m\u001b[1;33m.\u001b[0m\u001b[0mperform\u001b[0m\u001b[1;33m(\u001b[0m\u001b[1;32mNone\u001b[0m\u001b[1;33m,\u001b[0m \u001b[0minputs\u001b[0m\u001b[1;33m,\u001b[0m \u001b[0moutput_storage\u001b[0m\u001b[1;33m)\u001b[0m\u001b[1;33m\u001b[0m\u001b[0m\n",
      "\u001b[1;31mSystemError\u001b[0m: <class 'range'> returned a result with an error set",
      "\nThe above exception was the direct cause of the following exception:\n",
      "\u001b[1;31mSystemError\u001b[0m                               Traceback (most recent call last)",
      "\u001b[1;32m~\\Anaconda3\\lib\\site-packages\\theano\\scalar\\basic.py\u001b[0m in \u001b[0;36mimpl\u001b[1;34m(self, *inputs)\u001b[0m\n\u001b[0;32m   4022\u001b[0m     \u001b[1;32mdef\u001b[0m \u001b[0mimpl\u001b[0m\u001b[1;33m(\u001b[0m\u001b[0mself\u001b[0m\u001b[1;33m,\u001b[0m \u001b[1;33m*\u001b[0m\u001b[0minputs\u001b[0m\u001b[1;33m)\u001b[0m\u001b[1;33m:\u001b[0m\u001b[1;33m\u001b[0m\u001b[0m\n\u001b[1;32m-> 4023\u001b[1;33m         \u001b[0moutput_storage\u001b[0m \u001b[1;33m=\u001b[0m \u001b[1;33m[\u001b[0m\u001b[1;33m[\u001b[0m\u001b[1;32mNone\u001b[0m\u001b[1;33m]\u001b[0m \u001b[1;32mfor\u001b[0m \u001b[0mi\u001b[0m \u001b[1;32min\u001b[0m \u001b[0mxrange\u001b[0m\u001b[1;33m(\u001b[0m\u001b[0mself\u001b[0m\u001b[1;33m.\u001b[0m\u001b[0mnout\u001b[0m\u001b[1;33m)\u001b[0m\u001b[1;33m]\u001b[0m\u001b[1;33m\u001b[0m\u001b[0m\n\u001b[0m\u001b[0;32m   4024\u001b[0m         \u001b[0mself\u001b[0m\u001b[1;33m.\u001b[0m\u001b[0mperform\u001b[0m\u001b[1;33m(\u001b[0m\u001b[1;32mNone\u001b[0m\u001b[1;33m,\u001b[0m \u001b[0minputs\u001b[0m\u001b[1;33m,\u001b[0m \u001b[0moutput_storage\u001b[0m\u001b[1;33m)\u001b[0m\u001b[1;33m\u001b[0m\u001b[0m\n",
      "\u001b[1;31mSystemError\u001b[0m: <class 'range'> returned a result with an error set",
      "\nThe above exception was the direct cause of the following exception:\n",
      "\u001b[1;31mSystemError\u001b[0m                               Traceback (most recent call last)",
      "\u001b[1;32m~\\Anaconda3\\lib\\site-packages\\theano\\scalar\\basic.py\u001b[0m in \u001b[0;36mimpl\u001b[1;34m(self, *inputs)\u001b[0m\n\u001b[0;32m   4022\u001b[0m     \u001b[1;32mdef\u001b[0m \u001b[0mimpl\u001b[0m\u001b[1;33m(\u001b[0m\u001b[0mself\u001b[0m\u001b[1;33m,\u001b[0m \u001b[1;33m*\u001b[0m\u001b[0minputs\u001b[0m\u001b[1;33m)\u001b[0m\u001b[1;33m:\u001b[0m\u001b[1;33m\u001b[0m\u001b[0m\n\u001b[1;32m-> 4023\u001b[1;33m         \u001b[0moutput_storage\u001b[0m \u001b[1;33m=\u001b[0m \u001b[1;33m[\u001b[0m\u001b[1;33m[\u001b[0m\u001b[1;32mNone\u001b[0m\u001b[1;33m]\u001b[0m \u001b[1;32mfor\u001b[0m \u001b[0mi\u001b[0m \u001b[1;32min\u001b[0m \u001b[0mxrange\u001b[0m\u001b[1;33m(\u001b[0m\u001b[0mself\u001b[0m\u001b[1;33m.\u001b[0m\u001b[0mnout\u001b[0m\u001b[1;33m)\u001b[0m\u001b[1;33m]\u001b[0m\u001b[1;33m\u001b[0m\u001b[0m\n\u001b[0m\u001b[0;32m   4024\u001b[0m         \u001b[0mself\u001b[0m\u001b[1;33m.\u001b[0m\u001b[0mperform\u001b[0m\u001b[1;33m(\u001b[0m\u001b[1;32mNone\u001b[0m\u001b[1;33m,\u001b[0m \u001b[0minputs\u001b[0m\u001b[1;33m,\u001b[0m \u001b[0moutput_storage\u001b[0m\u001b[1;33m)\u001b[0m\u001b[1;33m\u001b[0m\u001b[0m\n",
      "\u001b[1;31mSystemError\u001b[0m: <class 'range'> returned a result with an error set",
      "\nThe above exception was the direct cause of the following exception:\n",
      "\u001b[1;31mSystemError\u001b[0m                               Traceback (most recent call last)",
      "\u001b[1;32m~\\Anaconda3\\lib\\site-packages\\theano\\scalar\\basic.py\u001b[0m in \u001b[0;36mimpl\u001b[1;34m(self, *inputs)\u001b[0m\n\u001b[0;32m   4022\u001b[0m     \u001b[1;32mdef\u001b[0m \u001b[0mimpl\u001b[0m\u001b[1;33m(\u001b[0m\u001b[0mself\u001b[0m\u001b[1;33m,\u001b[0m \u001b[1;33m*\u001b[0m\u001b[0minputs\u001b[0m\u001b[1;33m)\u001b[0m\u001b[1;33m:\u001b[0m\u001b[1;33m\u001b[0m\u001b[0m\n\u001b[1;32m-> 4023\u001b[1;33m         \u001b[0moutput_storage\u001b[0m \u001b[1;33m=\u001b[0m \u001b[1;33m[\u001b[0m\u001b[1;33m[\u001b[0m\u001b[1;32mNone\u001b[0m\u001b[1;33m]\u001b[0m \u001b[1;32mfor\u001b[0m \u001b[0mi\u001b[0m \u001b[1;32min\u001b[0m \u001b[0mxrange\u001b[0m\u001b[1;33m(\u001b[0m\u001b[0mself\u001b[0m\u001b[1;33m.\u001b[0m\u001b[0mnout\u001b[0m\u001b[1;33m)\u001b[0m\u001b[1;33m]\u001b[0m\u001b[1;33m\u001b[0m\u001b[0m\n\u001b[0m\u001b[0;32m   4024\u001b[0m         \u001b[0mself\u001b[0m\u001b[1;33m.\u001b[0m\u001b[0mperform\u001b[0m\u001b[1;33m(\u001b[0m\u001b[1;32mNone\u001b[0m\u001b[1;33m,\u001b[0m \u001b[0minputs\u001b[0m\u001b[1;33m,\u001b[0m \u001b[0moutput_storage\u001b[0m\u001b[1;33m)\u001b[0m\u001b[1;33m\u001b[0m\u001b[0m\n",
      "\u001b[1;31mSystemError\u001b[0m: <class 'range'> returned a result with an error set",
      "\nThe above exception was the direct cause of the following exception:\n",
      "\u001b[1;31mSystemError\u001b[0m                               Traceback (most recent call last)",
      "\u001b[1;32m~\\Anaconda3\\lib\\site-packages\\theano\\scalar\\basic.py\u001b[0m in \u001b[0;36mimpl\u001b[1;34m(self, *inputs)\u001b[0m\n\u001b[0;32m   4022\u001b[0m     \u001b[1;32mdef\u001b[0m \u001b[0mimpl\u001b[0m\u001b[1;33m(\u001b[0m\u001b[0mself\u001b[0m\u001b[1;33m,\u001b[0m \u001b[1;33m*\u001b[0m\u001b[0minputs\u001b[0m\u001b[1;33m)\u001b[0m\u001b[1;33m:\u001b[0m\u001b[1;33m\u001b[0m\u001b[0m\n\u001b[1;32m-> 4023\u001b[1;33m         \u001b[0moutput_storage\u001b[0m \u001b[1;33m=\u001b[0m \u001b[1;33m[\u001b[0m\u001b[1;33m[\u001b[0m\u001b[1;32mNone\u001b[0m\u001b[1;33m]\u001b[0m \u001b[1;32mfor\u001b[0m \u001b[0mi\u001b[0m \u001b[1;32min\u001b[0m \u001b[0mxrange\u001b[0m\u001b[1;33m(\u001b[0m\u001b[0mself\u001b[0m\u001b[1;33m.\u001b[0m\u001b[0mnout\u001b[0m\u001b[1;33m)\u001b[0m\u001b[1;33m]\u001b[0m\u001b[1;33m\u001b[0m\u001b[0m\n\u001b[0m\u001b[0;32m   4024\u001b[0m         \u001b[0mself\u001b[0m\u001b[1;33m.\u001b[0m\u001b[0mperform\u001b[0m\u001b[1;33m(\u001b[0m\u001b[1;32mNone\u001b[0m\u001b[1;33m,\u001b[0m \u001b[0minputs\u001b[0m\u001b[1;33m,\u001b[0m \u001b[0moutput_storage\u001b[0m\u001b[1;33m)\u001b[0m\u001b[1;33m\u001b[0m\u001b[0m\n",
      "\u001b[1;31mSystemError\u001b[0m: <class 'range'> returned a result with an error set",
      "\nThe above exception was the direct cause of the following exception:\n",
      "\u001b[1;31mSystemError\u001b[0m                               Traceback (most recent call last)",
      "\u001b[1;32m~\\Anaconda3\\lib\\site-packages\\theano\\scalar\\basic.py\u001b[0m in \u001b[0;36mimpl\u001b[1;34m(self, *inputs)\u001b[0m\n\u001b[0;32m   4022\u001b[0m     \u001b[1;32mdef\u001b[0m \u001b[0mimpl\u001b[0m\u001b[1;33m(\u001b[0m\u001b[0mself\u001b[0m\u001b[1;33m,\u001b[0m \u001b[1;33m*\u001b[0m\u001b[0minputs\u001b[0m\u001b[1;33m)\u001b[0m\u001b[1;33m:\u001b[0m\u001b[1;33m\u001b[0m\u001b[0m\n\u001b[1;32m-> 4023\u001b[1;33m         \u001b[0moutput_storage\u001b[0m \u001b[1;33m=\u001b[0m \u001b[1;33m[\u001b[0m\u001b[1;33m[\u001b[0m\u001b[1;32mNone\u001b[0m\u001b[1;33m]\u001b[0m \u001b[1;32mfor\u001b[0m \u001b[0mi\u001b[0m \u001b[1;32min\u001b[0m \u001b[0mxrange\u001b[0m\u001b[1;33m(\u001b[0m\u001b[0mself\u001b[0m\u001b[1;33m.\u001b[0m\u001b[0mnout\u001b[0m\u001b[1;33m)\u001b[0m\u001b[1;33m]\u001b[0m\u001b[1;33m\u001b[0m\u001b[0m\n\u001b[0m\u001b[0;32m   4024\u001b[0m         \u001b[0mself\u001b[0m\u001b[1;33m.\u001b[0m\u001b[0mperform\u001b[0m\u001b[1;33m(\u001b[0m\u001b[1;32mNone\u001b[0m\u001b[1;33m,\u001b[0m \u001b[0minputs\u001b[0m\u001b[1;33m,\u001b[0m \u001b[0moutput_storage\u001b[0m\u001b[1;33m)\u001b[0m\u001b[1;33m\u001b[0m\u001b[0m\n",
      "\u001b[1;31mSystemError\u001b[0m: <class 'range'> returned a result with an error set",
      "\nThe above exception was the direct cause of the following exception:\n",
      "\u001b[1;31mSystemError\u001b[0m                               Traceback (most recent call last)",
      "\u001b[1;32m~\\Anaconda3\\lib\\site-packages\\theano\\scalar\\basic.py\u001b[0m in \u001b[0;36mimpl\u001b[1;34m(self, *inputs)\u001b[0m\n\u001b[0;32m   4022\u001b[0m     \u001b[1;32mdef\u001b[0m \u001b[0mimpl\u001b[0m\u001b[1;33m(\u001b[0m\u001b[0mself\u001b[0m\u001b[1;33m,\u001b[0m \u001b[1;33m*\u001b[0m\u001b[0minputs\u001b[0m\u001b[1;33m)\u001b[0m\u001b[1;33m:\u001b[0m\u001b[1;33m\u001b[0m\u001b[0m\n\u001b[1;32m-> 4023\u001b[1;33m         \u001b[0moutput_storage\u001b[0m \u001b[1;33m=\u001b[0m \u001b[1;33m[\u001b[0m\u001b[1;33m[\u001b[0m\u001b[1;32mNone\u001b[0m\u001b[1;33m]\u001b[0m \u001b[1;32mfor\u001b[0m \u001b[0mi\u001b[0m \u001b[1;32min\u001b[0m \u001b[0mxrange\u001b[0m\u001b[1;33m(\u001b[0m\u001b[0mself\u001b[0m\u001b[1;33m.\u001b[0m\u001b[0mnout\u001b[0m\u001b[1;33m)\u001b[0m\u001b[1;33m]\u001b[0m\u001b[1;33m\u001b[0m\u001b[0m\n\u001b[0m\u001b[0;32m   4024\u001b[0m         \u001b[0mself\u001b[0m\u001b[1;33m.\u001b[0m\u001b[0mperform\u001b[0m\u001b[1;33m(\u001b[0m\u001b[1;32mNone\u001b[0m\u001b[1;33m,\u001b[0m \u001b[0minputs\u001b[0m\u001b[1;33m,\u001b[0m \u001b[0moutput_storage\u001b[0m\u001b[1;33m)\u001b[0m\u001b[1;33m\u001b[0m\u001b[0m\n",
      "\u001b[1;31mSystemError\u001b[0m: <class 'range'> returned a result with an error set",
      "\nThe above exception was the direct cause of the following exception:\n",
      "\u001b[1;31mSystemError\u001b[0m                               Traceback (most recent call last)",
      "\u001b[1;32m~\\Anaconda3\\lib\\site-packages\\theano\\scalar\\basic.py\u001b[0m in \u001b[0;36mimpl\u001b[1;34m(self, *inputs)\u001b[0m\n\u001b[0;32m   4022\u001b[0m     \u001b[1;32mdef\u001b[0m \u001b[0mimpl\u001b[0m\u001b[1;33m(\u001b[0m\u001b[0mself\u001b[0m\u001b[1;33m,\u001b[0m \u001b[1;33m*\u001b[0m\u001b[0minputs\u001b[0m\u001b[1;33m)\u001b[0m\u001b[1;33m:\u001b[0m\u001b[1;33m\u001b[0m\u001b[0m\n\u001b[1;32m-> 4023\u001b[1;33m         \u001b[0moutput_storage\u001b[0m \u001b[1;33m=\u001b[0m \u001b[1;33m[\u001b[0m\u001b[1;33m[\u001b[0m\u001b[1;32mNone\u001b[0m\u001b[1;33m]\u001b[0m \u001b[1;32mfor\u001b[0m \u001b[0mi\u001b[0m \u001b[1;32min\u001b[0m \u001b[0mxrange\u001b[0m\u001b[1;33m(\u001b[0m\u001b[0mself\u001b[0m\u001b[1;33m.\u001b[0m\u001b[0mnout\u001b[0m\u001b[1;33m)\u001b[0m\u001b[1;33m]\u001b[0m\u001b[1;33m\u001b[0m\u001b[0m\n\u001b[0m\u001b[0;32m   4024\u001b[0m         \u001b[0mself\u001b[0m\u001b[1;33m.\u001b[0m\u001b[0mperform\u001b[0m\u001b[1;33m(\u001b[0m\u001b[1;32mNone\u001b[0m\u001b[1;33m,\u001b[0m \u001b[0minputs\u001b[0m\u001b[1;33m,\u001b[0m \u001b[0moutput_storage\u001b[0m\u001b[1;33m)\u001b[0m\u001b[1;33m\u001b[0m\u001b[0m\n",
      "\u001b[1;31mSystemError\u001b[0m: <class 'range'> returned a result with an error set",
      "\nThe above exception was the direct cause of the following exception:\n",
      "\u001b[1;31mSystemError\u001b[0m                               Traceback (most recent call last)",
      "\u001b[1;32m~\\Anaconda3\\lib\\site-packages\\theano\\scalar\\basic.py\u001b[0m in \u001b[0;36mimpl\u001b[1;34m(self, *inputs)\u001b[0m\n\u001b[0;32m   4022\u001b[0m     \u001b[1;32mdef\u001b[0m \u001b[0mimpl\u001b[0m\u001b[1;33m(\u001b[0m\u001b[0mself\u001b[0m\u001b[1;33m,\u001b[0m \u001b[1;33m*\u001b[0m\u001b[0minputs\u001b[0m\u001b[1;33m)\u001b[0m\u001b[1;33m:\u001b[0m\u001b[1;33m\u001b[0m\u001b[0m\n\u001b[1;32m-> 4023\u001b[1;33m         \u001b[0moutput_storage\u001b[0m \u001b[1;33m=\u001b[0m \u001b[1;33m[\u001b[0m\u001b[1;33m[\u001b[0m\u001b[1;32mNone\u001b[0m\u001b[1;33m]\u001b[0m \u001b[1;32mfor\u001b[0m \u001b[0mi\u001b[0m \u001b[1;32min\u001b[0m \u001b[0mxrange\u001b[0m\u001b[1;33m(\u001b[0m\u001b[0mself\u001b[0m\u001b[1;33m.\u001b[0m\u001b[0mnout\u001b[0m\u001b[1;33m)\u001b[0m\u001b[1;33m]\u001b[0m\u001b[1;33m\u001b[0m\u001b[0m\n\u001b[0m\u001b[0;32m   4024\u001b[0m         \u001b[0mself\u001b[0m\u001b[1;33m.\u001b[0m\u001b[0mperform\u001b[0m\u001b[1;33m(\u001b[0m\u001b[1;32mNone\u001b[0m\u001b[1;33m,\u001b[0m \u001b[0minputs\u001b[0m\u001b[1;33m,\u001b[0m \u001b[0moutput_storage\u001b[0m\u001b[1;33m)\u001b[0m\u001b[1;33m\u001b[0m\u001b[0m\n",
      "\u001b[1;31mSystemError\u001b[0m: <class 'range'> returned a result with an error set",
      "\nThe above exception was the direct cause of the following exception:\n",
      "\u001b[1;31mSystemError\u001b[0m                               Traceback (most recent call last)",
      "\u001b[1;32m~\\Anaconda3\\lib\\site-packages\\theano\\scalar\\basic.py\u001b[0m in \u001b[0;36mimpl\u001b[1;34m(self, *inputs)\u001b[0m\n\u001b[0;32m   4022\u001b[0m     \u001b[1;32mdef\u001b[0m \u001b[0mimpl\u001b[0m\u001b[1;33m(\u001b[0m\u001b[0mself\u001b[0m\u001b[1;33m,\u001b[0m \u001b[1;33m*\u001b[0m\u001b[0minputs\u001b[0m\u001b[1;33m)\u001b[0m\u001b[1;33m:\u001b[0m\u001b[1;33m\u001b[0m\u001b[0m\n\u001b[1;32m-> 4023\u001b[1;33m         \u001b[0moutput_storage\u001b[0m \u001b[1;33m=\u001b[0m \u001b[1;33m[\u001b[0m\u001b[1;33m[\u001b[0m\u001b[1;32mNone\u001b[0m\u001b[1;33m]\u001b[0m \u001b[1;32mfor\u001b[0m \u001b[0mi\u001b[0m \u001b[1;32min\u001b[0m \u001b[0mxrange\u001b[0m\u001b[1;33m(\u001b[0m\u001b[0mself\u001b[0m\u001b[1;33m.\u001b[0m\u001b[0mnout\u001b[0m\u001b[1;33m)\u001b[0m\u001b[1;33m]\u001b[0m\u001b[1;33m\u001b[0m\u001b[0m\n\u001b[0m\u001b[0;32m   4024\u001b[0m         \u001b[0mself\u001b[0m\u001b[1;33m.\u001b[0m\u001b[0mperform\u001b[0m\u001b[1;33m(\u001b[0m\u001b[1;32mNone\u001b[0m\u001b[1;33m,\u001b[0m \u001b[0minputs\u001b[0m\u001b[1;33m,\u001b[0m \u001b[0moutput_storage\u001b[0m\u001b[1;33m)\u001b[0m\u001b[1;33m\u001b[0m\u001b[0m\n",
      "\u001b[1;31mSystemError\u001b[0m: <class 'range'> returned a result with an error set",
      "\nThe above exception was the direct cause of the following exception:\n",
      "\u001b[1;31mSystemError\u001b[0m                               Traceback (most recent call last)",
      "\u001b[1;32m~\\Anaconda3\\lib\\site-packages\\theano\\scalar\\basic.py\u001b[0m in \u001b[0;36mimpl\u001b[1;34m(self, *inputs)\u001b[0m\n\u001b[0;32m   4022\u001b[0m     \u001b[1;32mdef\u001b[0m \u001b[0mimpl\u001b[0m\u001b[1;33m(\u001b[0m\u001b[0mself\u001b[0m\u001b[1;33m,\u001b[0m \u001b[1;33m*\u001b[0m\u001b[0minputs\u001b[0m\u001b[1;33m)\u001b[0m\u001b[1;33m:\u001b[0m\u001b[1;33m\u001b[0m\u001b[0m\n\u001b[1;32m-> 4023\u001b[1;33m         \u001b[0moutput_storage\u001b[0m \u001b[1;33m=\u001b[0m \u001b[1;33m[\u001b[0m\u001b[1;33m[\u001b[0m\u001b[1;32mNone\u001b[0m\u001b[1;33m]\u001b[0m \u001b[1;32mfor\u001b[0m \u001b[0mi\u001b[0m \u001b[1;32min\u001b[0m \u001b[0mxrange\u001b[0m\u001b[1;33m(\u001b[0m\u001b[0mself\u001b[0m\u001b[1;33m.\u001b[0m\u001b[0mnout\u001b[0m\u001b[1;33m)\u001b[0m\u001b[1;33m]\u001b[0m\u001b[1;33m\u001b[0m\u001b[0m\n\u001b[0m\u001b[0;32m   4024\u001b[0m         \u001b[0mself\u001b[0m\u001b[1;33m.\u001b[0m\u001b[0mperform\u001b[0m\u001b[1;33m(\u001b[0m\u001b[1;32mNone\u001b[0m\u001b[1;33m,\u001b[0m \u001b[0minputs\u001b[0m\u001b[1;33m,\u001b[0m \u001b[0moutput_storage\u001b[0m\u001b[1;33m)\u001b[0m\u001b[1;33m\u001b[0m\u001b[0m\n",
      "\u001b[1;31mSystemError\u001b[0m: <class 'range'> returned a result with an error set",
      "\nThe above exception was the direct cause of the following exception:\n",
      "\u001b[1;31mSystemError\u001b[0m                               Traceback (most recent call last)",
      "\u001b[1;32m~\\Anaconda3\\lib\\site-packages\\theano\\scalar\\basic.py\u001b[0m in \u001b[0;36mimpl\u001b[1;34m(self, *inputs)\u001b[0m\n\u001b[0;32m   4022\u001b[0m     \u001b[1;32mdef\u001b[0m \u001b[0mimpl\u001b[0m\u001b[1;33m(\u001b[0m\u001b[0mself\u001b[0m\u001b[1;33m,\u001b[0m \u001b[1;33m*\u001b[0m\u001b[0minputs\u001b[0m\u001b[1;33m)\u001b[0m\u001b[1;33m:\u001b[0m\u001b[1;33m\u001b[0m\u001b[0m\n\u001b[1;32m-> 4023\u001b[1;33m         \u001b[0moutput_storage\u001b[0m \u001b[1;33m=\u001b[0m \u001b[1;33m[\u001b[0m\u001b[1;33m[\u001b[0m\u001b[1;32mNone\u001b[0m\u001b[1;33m]\u001b[0m \u001b[1;32mfor\u001b[0m \u001b[0mi\u001b[0m \u001b[1;32min\u001b[0m \u001b[0mxrange\u001b[0m\u001b[1;33m(\u001b[0m\u001b[0mself\u001b[0m\u001b[1;33m.\u001b[0m\u001b[0mnout\u001b[0m\u001b[1;33m)\u001b[0m\u001b[1;33m]\u001b[0m\u001b[1;33m\u001b[0m\u001b[0m\n\u001b[0m\u001b[0;32m   4024\u001b[0m         \u001b[0mself\u001b[0m\u001b[1;33m.\u001b[0m\u001b[0mperform\u001b[0m\u001b[1;33m(\u001b[0m\u001b[1;32mNone\u001b[0m\u001b[1;33m,\u001b[0m \u001b[0minputs\u001b[0m\u001b[1;33m,\u001b[0m \u001b[0moutput_storage\u001b[0m\u001b[1;33m)\u001b[0m\u001b[1;33m\u001b[0m\u001b[0m\n",
      "\u001b[1;31mSystemError\u001b[0m: <class 'range'> returned a result with an error set",
      "\nThe above exception was the direct cause of the following exception:\n",
      "\u001b[1;31mSystemError\u001b[0m                               Traceback (most recent call last)",
      "\u001b[1;32m~\\Anaconda3\\lib\\site-packages\\theano\\scalar\\basic.py\u001b[0m in \u001b[0;36mimpl\u001b[1;34m(self, *inputs)\u001b[0m\n\u001b[0;32m   4022\u001b[0m     \u001b[1;32mdef\u001b[0m \u001b[0mimpl\u001b[0m\u001b[1;33m(\u001b[0m\u001b[0mself\u001b[0m\u001b[1;33m,\u001b[0m \u001b[1;33m*\u001b[0m\u001b[0minputs\u001b[0m\u001b[1;33m)\u001b[0m\u001b[1;33m:\u001b[0m\u001b[1;33m\u001b[0m\u001b[0m\n\u001b[1;32m-> 4023\u001b[1;33m         \u001b[0moutput_storage\u001b[0m \u001b[1;33m=\u001b[0m \u001b[1;33m[\u001b[0m\u001b[1;33m[\u001b[0m\u001b[1;32mNone\u001b[0m\u001b[1;33m]\u001b[0m \u001b[1;32mfor\u001b[0m \u001b[0mi\u001b[0m \u001b[1;32min\u001b[0m \u001b[0mxrange\u001b[0m\u001b[1;33m(\u001b[0m\u001b[0mself\u001b[0m\u001b[1;33m.\u001b[0m\u001b[0mnout\u001b[0m\u001b[1;33m)\u001b[0m\u001b[1;33m]\u001b[0m\u001b[1;33m\u001b[0m\u001b[0m\n\u001b[0m\u001b[0;32m   4024\u001b[0m         \u001b[0mself\u001b[0m\u001b[1;33m.\u001b[0m\u001b[0mperform\u001b[0m\u001b[1;33m(\u001b[0m\u001b[1;32mNone\u001b[0m\u001b[1;33m,\u001b[0m \u001b[0minputs\u001b[0m\u001b[1;33m,\u001b[0m \u001b[0moutput_storage\u001b[0m\u001b[1;33m)\u001b[0m\u001b[1;33m\u001b[0m\u001b[0m\n",
      "\u001b[1;31mSystemError\u001b[0m: <class 'range'> returned a result with an error set",
      "\nThe above exception was the direct cause of the following exception:\n",
      "\u001b[1;31mSystemError\u001b[0m                               Traceback (most recent call last)",
      "\u001b[1;32m~\\Anaconda3\\lib\\site-packages\\theano\\scalar\\basic.py\u001b[0m in \u001b[0;36mimpl\u001b[1;34m(self, *inputs)\u001b[0m\n\u001b[0;32m   4022\u001b[0m     \u001b[1;32mdef\u001b[0m \u001b[0mimpl\u001b[0m\u001b[1;33m(\u001b[0m\u001b[0mself\u001b[0m\u001b[1;33m,\u001b[0m \u001b[1;33m*\u001b[0m\u001b[0minputs\u001b[0m\u001b[1;33m)\u001b[0m\u001b[1;33m:\u001b[0m\u001b[1;33m\u001b[0m\u001b[0m\n\u001b[1;32m-> 4023\u001b[1;33m         \u001b[0moutput_storage\u001b[0m \u001b[1;33m=\u001b[0m \u001b[1;33m[\u001b[0m\u001b[1;33m[\u001b[0m\u001b[1;32mNone\u001b[0m\u001b[1;33m]\u001b[0m \u001b[1;32mfor\u001b[0m \u001b[0mi\u001b[0m \u001b[1;32min\u001b[0m \u001b[0mxrange\u001b[0m\u001b[1;33m(\u001b[0m\u001b[0mself\u001b[0m\u001b[1;33m.\u001b[0m\u001b[0mnout\u001b[0m\u001b[1;33m)\u001b[0m\u001b[1;33m]\u001b[0m\u001b[1;33m\u001b[0m\u001b[0m\n\u001b[0m\u001b[0;32m   4024\u001b[0m         \u001b[0mself\u001b[0m\u001b[1;33m.\u001b[0m\u001b[0mperform\u001b[0m\u001b[1;33m(\u001b[0m\u001b[1;32mNone\u001b[0m\u001b[1;33m,\u001b[0m \u001b[0minputs\u001b[0m\u001b[1;33m,\u001b[0m \u001b[0moutput_storage\u001b[0m\u001b[1;33m)\u001b[0m\u001b[1;33m\u001b[0m\u001b[0m\n",
      "\u001b[1;31mSystemError\u001b[0m: <class 'range'> returned a result with an error set",
      "\nThe above exception was the direct cause of the following exception:\n",
      "\u001b[1;31mSystemError\u001b[0m                               Traceback (most recent call last)",
      "\u001b[1;32m~\\Anaconda3\\lib\\site-packages\\theano\\scalar\\basic.py\u001b[0m in \u001b[0;36mimpl\u001b[1;34m(self, *inputs)\u001b[0m\n\u001b[0;32m   4022\u001b[0m     \u001b[1;32mdef\u001b[0m \u001b[0mimpl\u001b[0m\u001b[1;33m(\u001b[0m\u001b[0mself\u001b[0m\u001b[1;33m,\u001b[0m \u001b[1;33m*\u001b[0m\u001b[0minputs\u001b[0m\u001b[1;33m)\u001b[0m\u001b[1;33m:\u001b[0m\u001b[1;33m\u001b[0m\u001b[0m\n\u001b[1;32m-> 4023\u001b[1;33m         \u001b[0moutput_storage\u001b[0m \u001b[1;33m=\u001b[0m \u001b[1;33m[\u001b[0m\u001b[1;33m[\u001b[0m\u001b[1;32mNone\u001b[0m\u001b[1;33m]\u001b[0m \u001b[1;32mfor\u001b[0m \u001b[0mi\u001b[0m \u001b[1;32min\u001b[0m \u001b[0mxrange\u001b[0m\u001b[1;33m(\u001b[0m\u001b[0mself\u001b[0m\u001b[1;33m.\u001b[0m\u001b[0mnout\u001b[0m\u001b[1;33m)\u001b[0m\u001b[1;33m]\u001b[0m\u001b[1;33m\u001b[0m\u001b[0m\n\u001b[0m\u001b[0;32m   4024\u001b[0m         \u001b[0mself\u001b[0m\u001b[1;33m.\u001b[0m\u001b[0mperform\u001b[0m\u001b[1;33m(\u001b[0m\u001b[1;32mNone\u001b[0m\u001b[1;33m,\u001b[0m \u001b[0minputs\u001b[0m\u001b[1;33m,\u001b[0m \u001b[0moutput_storage\u001b[0m\u001b[1;33m)\u001b[0m\u001b[1;33m\u001b[0m\u001b[0m\n",
      "\u001b[1;31mSystemError\u001b[0m: <class 'range'> returned a result with an error set",
      "\nThe above exception was the direct cause of the following exception:\n",
      "\u001b[1;31mSystemError\u001b[0m                               Traceback (most recent call last)",
      "\u001b[1;32m~\\Anaconda3\\lib\\site-packages\\theano\\scalar\\basic.py\u001b[0m in \u001b[0;36mimpl\u001b[1;34m(self, *inputs)\u001b[0m\n\u001b[0;32m   4022\u001b[0m     \u001b[1;32mdef\u001b[0m \u001b[0mimpl\u001b[0m\u001b[1;33m(\u001b[0m\u001b[0mself\u001b[0m\u001b[1;33m,\u001b[0m \u001b[1;33m*\u001b[0m\u001b[0minputs\u001b[0m\u001b[1;33m)\u001b[0m\u001b[1;33m:\u001b[0m\u001b[1;33m\u001b[0m\u001b[0m\n\u001b[1;32m-> 4023\u001b[1;33m         \u001b[0moutput_storage\u001b[0m \u001b[1;33m=\u001b[0m \u001b[1;33m[\u001b[0m\u001b[1;33m[\u001b[0m\u001b[1;32mNone\u001b[0m\u001b[1;33m]\u001b[0m \u001b[1;32mfor\u001b[0m \u001b[0mi\u001b[0m \u001b[1;32min\u001b[0m \u001b[0mxrange\u001b[0m\u001b[1;33m(\u001b[0m\u001b[0mself\u001b[0m\u001b[1;33m.\u001b[0m\u001b[0mnout\u001b[0m\u001b[1;33m)\u001b[0m\u001b[1;33m]\u001b[0m\u001b[1;33m\u001b[0m\u001b[0m\n\u001b[0m\u001b[0;32m   4024\u001b[0m         \u001b[0mself\u001b[0m\u001b[1;33m.\u001b[0m\u001b[0mperform\u001b[0m\u001b[1;33m(\u001b[0m\u001b[1;32mNone\u001b[0m\u001b[1;33m,\u001b[0m \u001b[0minputs\u001b[0m\u001b[1;33m,\u001b[0m \u001b[0moutput_storage\u001b[0m\u001b[1;33m)\u001b[0m\u001b[1;33m\u001b[0m\u001b[0m\n",
      "\u001b[1;31mSystemError\u001b[0m: <class 'range'> returned a result with an error set",
      "\nThe above exception was the direct cause of the following exception:\n",
      "\u001b[1;31mSystemError\u001b[0m                               Traceback (most recent call last)",
      "\u001b[1;32m~\\Anaconda3\\lib\\site-packages\\theano\\scalar\\basic.py\u001b[0m in \u001b[0;36mimpl\u001b[1;34m(self, *inputs)\u001b[0m\n\u001b[0;32m   4022\u001b[0m     \u001b[1;32mdef\u001b[0m \u001b[0mimpl\u001b[0m\u001b[1;33m(\u001b[0m\u001b[0mself\u001b[0m\u001b[1;33m,\u001b[0m \u001b[1;33m*\u001b[0m\u001b[0minputs\u001b[0m\u001b[1;33m)\u001b[0m\u001b[1;33m:\u001b[0m\u001b[1;33m\u001b[0m\u001b[0m\n\u001b[1;32m-> 4023\u001b[1;33m         \u001b[0moutput_storage\u001b[0m \u001b[1;33m=\u001b[0m \u001b[1;33m[\u001b[0m\u001b[1;33m[\u001b[0m\u001b[1;32mNone\u001b[0m\u001b[1;33m]\u001b[0m \u001b[1;32mfor\u001b[0m \u001b[0mi\u001b[0m \u001b[1;32min\u001b[0m \u001b[0mxrange\u001b[0m\u001b[1;33m(\u001b[0m\u001b[0mself\u001b[0m\u001b[1;33m.\u001b[0m\u001b[0mnout\u001b[0m\u001b[1;33m)\u001b[0m\u001b[1;33m]\u001b[0m\u001b[1;33m\u001b[0m\u001b[0m\n\u001b[0m\u001b[0;32m   4024\u001b[0m         \u001b[0mself\u001b[0m\u001b[1;33m.\u001b[0m\u001b[0mperform\u001b[0m\u001b[1;33m(\u001b[0m\u001b[1;32mNone\u001b[0m\u001b[1;33m,\u001b[0m \u001b[0minputs\u001b[0m\u001b[1;33m,\u001b[0m \u001b[0moutput_storage\u001b[0m\u001b[1;33m)\u001b[0m\u001b[1;33m\u001b[0m\u001b[0m\n",
      "\u001b[1;31mSystemError\u001b[0m: <class 'range'> returned a result with an error set",
      "\nThe above exception was the direct cause of the following exception:\n",
      "\u001b[1;31mSystemError\u001b[0m                               Traceback (most recent call last)",
      "\u001b[1;32m~\\Anaconda3\\lib\\site-packages\\theano\\scalar\\basic.py\u001b[0m in \u001b[0;36mimpl\u001b[1;34m(self, *inputs)\u001b[0m\n\u001b[0;32m   4022\u001b[0m     \u001b[1;32mdef\u001b[0m \u001b[0mimpl\u001b[0m\u001b[1;33m(\u001b[0m\u001b[0mself\u001b[0m\u001b[1;33m,\u001b[0m \u001b[1;33m*\u001b[0m\u001b[0minputs\u001b[0m\u001b[1;33m)\u001b[0m\u001b[1;33m:\u001b[0m\u001b[1;33m\u001b[0m\u001b[0m\n\u001b[1;32m-> 4023\u001b[1;33m         \u001b[0moutput_storage\u001b[0m \u001b[1;33m=\u001b[0m \u001b[1;33m[\u001b[0m\u001b[1;33m[\u001b[0m\u001b[1;32mNone\u001b[0m\u001b[1;33m]\u001b[0m \u001b[1;32mfor\u001b[0m \u001b[0mi\u001b[0m \u001b[1;32min\u001b[0m \u001b[0mxrange\u001b[0m\u001b[1;33m(\u001b[0m\u001b[0mself\u001b[0m\u001b[1;33m.\u001b[0m\u001b[0mnout\u001b[0m\u001b[1;33m)\u001b[0m\u001b[1;33m]\u001b[0m\u001b[1;33m\u001b[0m\u001b[0m\n\u001b[0m\u001b[0;32m   4024\u001b[0m         \u001b[0mself\u001b[0m\u001b[1;33m.\u001b[0m\u001b[0mperform\u001b[0m\u001b[1;33m(\u001b[0m\u001b[1;32mNone\u001b[0m\u001b[1;33m,\u001b[0m \u001b[0minputs\u001b[0m\u001b[1;33m,\u001b[0m \u001b[0moutput_storage\u001b[0m\u001b[1;33m)\u001b[0m\u001b[1;33m\u001b[0m\u001b[0m\n",
      "\u001b[1;31mSystemError\u001b[0m: <class 'range'> returned a result with an error set",
      "\nThe above exception was the direct cause of the following exception:\n",
      "\u001b[1;31mSystemError\u001b[0m                               Traceback (most recent call last)",
      "\u001b[1;32m~\\Anaconda3\\lib\\site-packages\\theano\\scalar\\basic.py\u001b[0m in \u001b[0;36mimpl\u001b[1;34m(self, *inputs)\u001b[0m\n\u001b[0;32m   4022\u001b[0m     \u001b[1;32mdef\u001b[0m \u001b[0mimpl\u001b[0m\u001b[1;33m(\u001b[0m\u001b[0mself\u001b[0m\u001b[1;33m,\u001b[0m \u001b[1;33m*\u001b[0m\u001b[0minputs\u001b[0m\u001b[1;33m)\u001b[0m\u001b[1;33m:\u001b[0m\u001b[1;33m\u001b[0m\u001b[0m\n\u001b[1;32m-> 4023\u001b[1;33m         \u001b[0moutput_storage\u001b[0m \u001b[1;33m=\u001b[0m \u001b[1;33m[\u001b[0m\u001b[1;33m[\u001b[0m\u001b[1;32mNone\u001b[0m\u001b[1;33m]\u001b[0m \u001b[1;32mfor\u001b[0m \u001b[0mi\u001b[0m \u001b[1;32min\u001b[0m \u001b[0mxrange\u001b[0m\u001b[1;33m(\u001b[0m\u001b[0mself\u001b[0m\u001b[1;33m.\u001b[0m\u001b[0mnout\u001b[0m\u001b[1;33m)\u001b[0m\u001b[1;33m]\u001b[0m\u001b[1;33m\u001b[0m\u001b[0m\n\u001b[0m\u001b[0;32m   4024\u001b[0m         \u001b[0mself\u001b[0m\u001b[1;33m.\u001b[0m\u001b[0mperform\u001b[0m\u001b[1;33m(\u001b[0m\u001b[1;32mNone\u001b[0m\u001b[1;33m,\u001b[0m \u001b[0minputs\u001b[0m\u001b[1;33m,\u001b[0m \u001b[0moutput_storage\u001b[0m\u001b[1;33m)\u001b[0m\u001b[1;33m\u001b[0m\u001b[0m\n",
      "\u001b[1;31mSystemError\u001b[0m: <class 'range'> returned a result with an error set",
      "\nThe above exception was the direct cause of the following exception:\n",
      "\u001b[1;31mSystemError\u001b[0m                               Traceback (most recent call last)",
      "\u001b[1;32m~\\Anaconda3\\lib\\site-packages\\theano\\scalar\\basic.py\u001b[0m in \u001b[0;36mimpl\u001b[1;34m(self, *inputs)\u001b[0m\n\u001b[0;32m   4022\u001b[0m     \u001b[1;32mdef\u001b[0m \u001b[0mimpl\u001b[0m\u001b[1;33m(\u001b[0m\u001b[0mself\u001b[0m\u001b[1;33m,\u001b[0m \u001b[1;33m*\u001b[0m\u001b[0minputs\u001b[0m\u001b[1;33m)\u001b[0m\u001b[1;33m:\u001b[0m\u001b[1;33m\u001b[0m\u001b[0m\n\u001b[1;32m-> 4023\u001b[1;33m         \u001b[0moutput_storage\u001b[0m \u001b[1;33m=\u001b[0m \u001b[1;33m[\u001b[0m\u001b[1;33m[\u001b[0m\u001b[1;32mNone\u001b[0m\u001b[1;33m]\u001b[0m \u001b[1;32mfor\u001b[0m \u001b[0mi\u001b[0m \u001b[1;32min\u001b[0m \u001b[0mxrange\u001b[0m\u001b[1;33m(\u001b[0m\u001b[0mself\u001b[0m\u001b[1;33m.\u001b[0m\u001b[0mnout\u001b[0m\u001b[1;33m)\u001b[0m\u001b[1;33m]\u001b[0m\u001b[1;33m\u001b[0m\u001b[0m\n\u001b[0m\u001b[0;32m   4024\u001b[0m         \u001b[0mself\u001b[0m\u001b[1;33m.\u001b[0m\u001b[0mperform\u001b[0m\u001b[1;33m(\u001b[0m\u001b[1;32mNone\u001b[0m\u001b[1;33m,\u001b[0m \u001b[0minputs\u001b[0m\u001b[1;33m,\u001b[0m \u001b[0moutput_storage\u001b[0m\u001b[1;33m)\u001b[0m\u001b[1;33m\u001b[0m\u001b[0m\n",
      "\u001b[1;31mSystemError\u001b[0m: <class 'range'> returned a result with an error set",
      "\nThe above exception was the direct cause of the following exception:\n",
      "\u001b[1;31mSystemError\u001b[0m                               Traceback (most recent call last)",
      "\u001b[1;32m~\\Anaconda3\\lib\\site-packages\\theano\\scalar\\basic.py\u001b[0m in \u001b[0;36mimpl\u001b[1;34m(self, *inputs)\u001b[0m\n\u001b[0;32m   4022\u001b[0m     \u001b[1;32mdef\u001b[0m \u001b[0mimpl\u001b[0m\u001b[1;33m(\u001b[0m\u001b[0mself\u001b[0m\u001b[1;33m,\u001b[0m \u001b[1;33m*\u001b[0m\u001b[0minputs\u001b[0m\u001b[1;33m)\u001b[0m\u001b[1;33m:\u001b[0m\u001b[1;33m\u001b[0m\u001b[0m\n\u001b[1;32m-> 4023\u001b[1;33m         \u001b[0moutput_storage\u001b[0m \u001b[1;33m=\u001b[0m \u001b[1;33m[\u001b[0m\u001b[1;33m[\u001b[0m\u001b[1;32mNone\u001b[0m\u001b[1;33m]\u001b[0m \u001b[1;32mfor\u001b[0m \u001b[0mi\u001b[0m \u001b[1;32min\u001b[0m \u001b[0mxrange\u001b[0m\u001b[1;33m(\u001b[0m\u001b[0mself\u001b[0m\u001b[1;33m.\u001b[0m\u001b[0mnout\u001b[0m\u001b[1;33m)\u001b[0m\u001b[1;33m]\u001b[0m\u001b[1;33m\u001b[0m\u001b[0m\n\u001b[0m\u001b[0;32m   4024\u001b[0m         \u001b[0mself\u001b[0m\u001b[1;33m.\u001b[0m\u001b[0mperform\u001b[0m\u001b[1;33m(\u001b[0m\u001b[1;32mNone\u001b[0m\u001b[1;33m,\u001b[0m \u001b[0minputs\u001b[0m\u001b[1;33m,\u001b[0m \u001b[0moutput_storage\u001b[0m\u001b[1;33m)\u001b[0m\u001b[1;33m\u001b[0m\u001b[0m\n",
      "\u001b[1;31mSystemError\u001b[0m: <class 'range'> returned a result with an error set",
      "\nThe above exception was the direct cause of the following exception:\n",
      "\u001b[1;31mSystemError\u001b[0m                               Traceback (most recent call last)",
      "\u001b[1;32m~\\Anaconda3\\lib\\site-packages\\theano\\scalar\\basic.py\u001b[0m in \u001b[0;36mimpl\u001b[1;34m(self, *inputs)\u001b[0m\n\u001b[0;32m   4022\u001b[0m     \u001b[1;32mdef\u001b[0m \u001b[0mimpl\u001b[0m\u001b[1;33m(\u001b[0m\u001b[0mself\u001b[0m\u001b[1;33m,\u001b[0m \u001b[1;33m*\u001b[0m\u001b[0minputs\u001b[0m\u001b[1;33m)\u001b[0m\u001b[1;33m:\u001b[0m\u001b[1;33m\u001b[0m\u001b[0m\n\u001b[1;32m-> 4023\u001b[1;33m         \u001b[0moutput_storage\u001b[0m \u001b[1;33m=\u001b[0m \u001b[1;33m[\u001b[0m\u001b[1;33m[\u001b[0m\u001b[1;32mNone\u001b[0m\u001b[1;33m]\u001b[0m \u001b[1;32mfor\u001b[0m \u001b[0mi\u001b[0m \u001b[1;32min\u001b[0m \u001b[0mxrange\u001b[0m\u001b[1;33m(\u001b[0m\u001b[0mself\u001b[0m\u001b[1;33m.\u001b[0m\u001b[0mnout\u001b[0m\u001b[1;33m)\u001b[0m\u001b[1;33m]\u001b[0m\u001b[1;33m\u001b[0m\u001b[0m\n\u001b[0m\u001b[0;32m   4024\u001b[0m         \u001b[0mself\u001b[0m\u001b[1;33m.\u001b[0m\u001b[0mperform\u001b[0m\u001b[1;33m(\u001b[0m\u001b[1;32mNone\u001b[0m\u001b[1;33m,\u001b[0m \u001b[0minputs\u001b[0m\u001b[1;33m,\u001b[0m \u001b[0moutput_storage\u001b[0m\u001b[1;33m)\u001b[0m\u001b[1;33m\u001b[0m\u001b[0m\n",
      "\u001b[1;31mSystemError\u001b[0m: <class 'range'> returned a result with an error set",
      "\nThe above exception was the direct cause of the following exception:\n",
      "\u001b[1;31mSystemError\u001b[0m                               Traceback (most recent call last)",
      "\u001b[1;32m~\\Anaconda3\\lib\\site-packages\\theano\\scalar\\basic.py\u001b[0m in \u001b[0;36mimpl\u001b[1;34m(self, *inputs)\u001b[0m\n\u001b[0;32m   4022\u001b[0m     \u001b[1;32mdef\u001b[0m \u001b[0mimpl\u001b[0m\u001b[1;33m(\u001b[0m\u001b[0mself\u001b[0m\u001b[1;33m,\u001b[0m \u001b[1;33m*\u001b[0m\u001b[0minputs\u001b[0m\u001b[1;33m)\u001b[0m\u001b[1;33m:\u001b[0m\u001b[1;33m\u001b[0m\u001b[0m\n\u001b[1;32m-> 4023\u001b[1;33m         \u001b[0moutput_storage\u001b[0m \u001b[1;33m=\u001b[0m \u001b[1;33m[\u001b[0m\u001b[1;33m[\u001b[0m\u001b[1;32mNone\u001b[0m\u001b[1;33m]\u001b[0m \u001b[1;32mfor\u001b[0m \u001b[0mi\u001b[0m \u001b[1;32min\u001b[0m \u001b[0mxrange\u001b[0m\u001b[1;33m(\u001b[0m\u001b[0mself\u001b[0m\u001b[1;33m.\u001b[0m\u001b[0mnout\u001b[0m\u001b[1;33m)\u001b[0m\u001b[1;33m]\u001b[0m\u001b[1;33m\u001b[0m\u001b[0m\n\u001b[0m\u001b[0;32m   4024\u001b[0m         \u001b[0mself\u001b[0m\u001b[1;33m.\u001b[0m\u001b[0mperform\u001b[0m\u001b[1;33m(\u001b[0m\u001b[1;32mNone\u001b[0m\u001b[1;33m,\u001b[0m \u001b[0minputs\u001b[0m\u001b[1;33m,\u001b[0m \u001b[0moutput_storage\u001b[0m\u001b[1;33m)\u001b[0m\u001b[1;33m\u001b[0m\u001b[0m\n",
      "\u001b[1;31mSystemError\u001b[0m: <class 'range'> returned a result with an error set",
      "\nThe above exception was the direct cause of the following exception:\n",
      "\u001b[1;31mSystemError\u001b[0m                               Traceback (most recent call last)",
      "\u001b[1;32m~\\Anaconda3\\lib\\site-packages\\theano\\scalar\\basic.py\u001b[0m in \u001b[0;36mimpl\u001b[1;34m(self, *inputs)\u001b[0m\n\u001b[0;32m   4022\u001b[0m     \u001b[1;32mdef\u001b[0m \u001b[0mimpl\u001b[0m\u001b[1;33m(\u001b[0m\u001b[0mself\u001b[0m\u001b[1;33m,\u001b[0m \u001b[1;33m*\u001b[0m\u001b[0minputs\u001b[0m\u001b[1;33m)\u001b[0m\u001b[1;33m:\u001b[0m\u001b[1;33m\u001b[0m\u001b[0m\n\u001b[1;32m-> 4023\u001b[1;33m         \u001b[0moutput_storage\u001b[0m \u001b[1;33m=\u001b[0m \u001b[1;33m[\u001b[0m\u001b[1;33m[\u001b[0m\u001b[1;32mNone\u001b[0m\u001b[1;33m]\u001b[0m \u001b[1;32mfor\u001b[0m \u001b[0mi\u001b[0m \u001b[1;32min\u001b[0m \u001b[0mxrange\u001b[0m\u001b[1;33m(\u001b[0m\u001b[0mself\u001b[0m\u001b[1;33m.\u001b[0m\u001b[0mnout\u001b[0m\u001b[1;33m)\u001b[0m\u001b[1;33m]\u001b[0m\u001b[1;33m\u001b[0m\u001b[0m\n\u001b[0m\u001b[0;32m   4024\u001b[0m         \u001b[0mself\u001b[0m\u001b[1;33m.\u001b[0m\u001b[0mperform\u001b[0m\u001b[1;33m(\u001b[0m\u001b[1;32mNone\u001b[0m\u001b[1;33m,\u001b[0m \u001b[0minputs\u001b[0m\u001b[1;33m,\u001b[0m \u001b[0moutput_storage\u001b[0m\u001b[1;33m)\u001b[0m\u001b[1;33m\u001b[0m\u001b[0m\n",
      "\u001b[1;31mSystemError\u001b[0m: <class 'range'> returned a result with an error set",
      "\nThe above exception was the direct cause of the following exception:\n",
      "\u001b[1;31mSystemError\u001b[0m                               Traceback (most recent call last)",
      "\u001b[1;32m~\\Anaconda3\\lib\\site-packages\\theano\\scalar\\basic.py\u001b[0m in \u001b[0;36mimpl\u001b[1;34m(self, *inputs)\u001b[0m\n\u001b[0;32m   4022\u001b[0m     \u001b[1;32mdef\u001b[0m \u001b[0mimpl\u001b[0m\u001b[1;33m(\u001b[0m\u001b[0mself\u001b[0m\u001b[1;33m,\u001b[0m \u001b[1;33m*\u001b[0m\u001b[0minputs\u001b[0m\u001b[1;33m)\u001b[0m\u001b[1;33m:\u001b[0m\u001b[1;33m\u001b[0m\u001b[0m\n\u001b[1;32m-> 4023\u001b[1;33m         \u001b[0moutput_storage\u001b[0m \u001b[1;33m=\u001b[0m \u001b[1;33m[\u001b[0m\u001b[1;33m[\u001b[0m\u001b[1;32mNone\u001b[0m\u001b[1;33m]\u001b[0m \u001b[1;32mfor\u001b[0m \u001b[0mi\u001b[0m \u001b[1;32min\u001b[0m \u001b[0mxrange\u001b[0m\u001b[1;33m(\u001b[0m\u001b[0mself\u001b[0m\u001b[1;33m.\u001b[0m\u001b[0mnout\u001b[0m\u001b[1;33m)\u001b[0m\u001b[1;33m]\u001b[0m\u001b[1;33m\u001b[0m\u001b[0m\n\u001b[0m\u001b[0;32m   4024\u001b[0m         \u001b[0mself\u001b[0m\u001b[1;33m.\u001b[0m\u001b[0mperform\u001b[0m\u001b[1;33m(\u001b[0m\u001b[1;32mNone\u001b[0m\u001b[1;33m,\u001b[0m \u001b[0minputs\u001b[0m\u001b[1;33m,\u001b[0m \u001b[0moutput_storage\u001b[0m\u001b[1;33m)\u001b[0m\u001b[1;33m\u001b[0m\u001b[0m\n",
      "\u001b[1;31mSystemError\u001b[0m: <class 'range'> returned a result with an error set",
      "\nThe above exception was the direct cause of the following exception:\n",
      "\u001b[1;31mSystemError\u001b[0m                               Traceback (most recent call last)",
      "\u001b[1;32m~\\Anaconda3\\lib\\site-packages\\theano\\scalar\\basic.py\u001b[0m in \u001b[0;36mimpl\u001b[1;34m(self, *inputs)\u001b[0m\n\u001b[0;32m   4022\u001b[0m     \u001b[1;32mdef\u001b[0m \u001b[0mimpl\u001b[0m\u001b[1;33m(\u001b[0m\u001b[0mself\u001b[0m\u001b[1;33m,\u001b[0m \u001b[1;33m*\u001b[0m\u001b[0minputs\u001b[0m\u001b[1;33m)\u001b[0m\u001b[1;33m:\u001b[0m\u001b[1;33m\u001b[0m\u001b[0m\n\u001b[1;32m-> 4023\u001b[1;33m         \u001b[0moutput_storage\u001b[0m \u001b[1;33m=\u001b[0m \u001b[1;33m[\u001b[0m\u001b[1;33m[\u001b[0m\u001b[1;32mNone\u001b[0m\u001b[1;33m]\u001b[0m \u001b[1;32mfor\u001b[0m \u001b[0mi\u001b[0m \u001b[1;32min\u001b[0m \u001b[0mxrange\u001b[0m\u001b[1;33m(\u001b[0m\u001b[0mself\u001b[0m\u001b[1;33m.\u001b[0m\u001b[0mnout\u001b[0m\u001b[1;33m)\u001b[0m\u001b[1;33m]\u001b[0m\u001b[1;33m\u001b[0m\u001b[0m\n\u001b[0m\u001b[0;32m   4024\u001b[0m         \u001b[0mself\u001b[0m\u001b[1;33m.\u001b[0m\u001b[0mperform\u001b[0m\u001b[1;33m(\u001b[0m\u001b[1;32mNone\u001b[0m\u001b[1;33m,\u001b[0m \u001b[0minputs\u001b[0m\u001b[1;33m,\u001b[0m \u001b[0moutput_storage\u001b[0m\u001b[1;33m)\u001b[0m\u001b[1;33m\u001b[0m\u001b[0m\n",
      "\u001b[1;31mSystemError\u001b[0m: <class 'range'> returned a result with an error set",
      "\nThe above exception was the direct cause of the following exception:\n",
      "\u001b[1;31mSystemError\u001b[0m                               Traceback (most recent call last)",
      "\u001b[1;32m~\\Anaconda3\\lib\\site-packages\\theano\\scalar\\basic.py\u001b[0m in \u001b[0;36mimpl\u001b[1;34m(self, *inputs)\u001b[0m\n\u001b[0;32m   4022\u001b[0m     \u001b[1;32mdef\u001b[0m \u001b[0mimpl\u001b[0m\u001b[1;33m(\u001b[0m\u001b[0mself\u001b[0m\u001b[1;33m,\u001b[0m \u001b[1;33m*\u001b[0m\u001b[0minputs\u001b[0m\u001b[1;33m)\u001b[0m\u001b[1;33m:\u001b[0m\u001b[1;33m\u001b[0m\u001b[0m\n\u001b[1;32m-> 4023\u001b[1;33m         \u001b[0moutput_storage\u001b[0m \u001b[1;33m=\u001b[0m \u001b[1;33m[\u001b[0m\u001b[1;33m[\u001b[0m\u001b[1;32mNone\u001b[0m\u001b[1;33m]\u001b[0m \u001b[1;32mfor\u001b[0m \u001b[0mi\u001b[0m \u001b[1;32min\u001b[0m \u001b[0mxrange\u001b[0m\u001b[1;33m(\u001b[0m\u001b[0mself\u001b[0m\u001b[1;33m.\u001b[0m\u001b[0mnout\u001b[0m\u001b[1;33m)\u001b[0m\u001b[1;33m]\u001b[0m\u001b[1;33m\u001b[0m\u001b[0m\n\u001b[0m\u001b[0;32m   4024\u001b[0m         \u001b[0mself\u001b[0m\u001b[1;33m.\u001b[0m\u001b[0mperform\u001b[0m\u001b[1;33m(\u001b[0m\u001b[1;32mNone\u001b[0m\u001b[1;33m,\u001b[0m \u001b[0minputs\u001b[0m\u001b[1;33m,\u001b[0m \u001b[0moutput_storage\u001b[0m\u001b[1;33m)\u001b[0m\u001b[1;33m\u001b[0m\u001b[0m\n",
      "\u001b[1;31mSystemError\u001b[0m: <class 'range'> returned a result with an error set",
      "\nThe above exception was the direct cause of the following exception:\n",
      "\u001b[1;31mSystemError\u001b[0m                               Traceback (most recent call last)",
      "\u001b[1;32m~\\Anaconda3\\lib\\site-packages\\theano\\scalar\\basic.py\u001b[0m in \u001b[0;36mimpl\u001b[1;34m(self, *inputs)\u001b[0m\n\u001b[0;32m   4022\u001b[0m     \u001b[1;32mdef\u001b[0m \u001b[0mimpl\u001b[0m\u001b[1;33m(\u001b[0m\u001b[0mself\u001b[0m\u001b[1;33m,\u001b[0m \u001b[1;33m*\u001b[0m\u001b[0minputs\u001b[0m\u001b[1;33m)\u001b[0m\u001b[1;33m:\u001b[0m\u001b[1;33m\u001b[0m\u001b[0m\n\u001b[1;32m-> 4023\u001b[1;33m         \u001b[0moutput_storage\u001b[0m \u001b[1;33m=\u001b[0m \u001b[1;33m[\u001b[0m\u001b[1;33m[\u001b[0m\u001b[1;32mNone\u001b[0m\u001b[1;33m]\u001b[0m \u001b[1;32mfor\u001b[0m \u001b[0mi\u001b[0m \u001b[1;32min\u001b[0m \u001b[0mxrange\u001b[0m\u001b[1;33m(\u001b[0m\u001b[0mself\u001b[0m\u001b[1;33m.\u001b[0m\u001b[0mnout\u001b[0m\u001b[1;33m)\u001b[0m\u001b[1;33m]\u001b[0m\u001b[1;33m\u001b[0m\u001b[0m\n\u001b[0m\u001b[0;32m   4024\u001b[0m         \u001b[0mself\u001b[0m\u001b[1;33m.\u001b[0m\u001b[0mperform\u001b[0m\u001b[1;33m(\u001b[0m\u001b[1;32mNone\u001b[0m\u001b[1;33m,\u001b[0m \u001b[0minputs\u001b[0m\u001b[1;33m,\u001b[0m \u001b[0moutput_storage\u001b[0m\u001b[1;33m)\u001b[0m\u001b[1;33m\u001b[0m\u001b[0m\n",
      "\u001b[1;31mSystemError\u001b[0m: <class 'range'> returned a result with an error set",
      "\nThe above exception was the direct cause of the following exception:\n",
      "\u001b[1;31mSystemError\u001b[0m                               Traceback (most recent call last)",
      "\u001b[1;32m~\\Anaconda3\\lib\\site-packages\\theano\\scalar\\basic.py\u001b[0m in \u001b[0;36mimpl\u001b[1;34m(self, *inputs)\u001b[0m\n\u001b[0;32m   4022\u001b[0m     \u001b[1;32mdef\u001b[0m \u001b[0mimpl\u001b[0m\u001b[1;33m(\u001b[0m\u001b[0mself\u001b[0m\u001b[1;33m,\u001b[0m \u001b[1;33m*\u001b[0m\u001b[0minputs\u001b[0m\u001b[1;33m)\u001b[0m\u001b[1;33m:\u001b[0m\u001b[1;33m\u001b[0m\u001b[0m\n\u001b[1;32m-> 4023\u001b[1;33m         \u001b[0moutput_storage\u001b[0m \u001b[1;33m=\u001b[0m \u001b[1;33m[\u001b[0m\u001b[1;33m[\u001b[0m\u001b[1;32mNone\u001b[0m\u001b[1;33m]\u001b[0m \u001b[1;32mfor\u001b[0m \u001b[0mi\u001b[0m \u001b[1;32min\u001b[0m \u001b[0mxrange\u001b[0m\u001b[1;33m(\u001b[0m\u001b[0mself\u001b[0m\u001b[1;33m.\u001b[0m\u001b[0mnout\u001b[0m\u001b[1;33m)\u001b[0m\u001b[1;33m]\u001b[0m\u001b[1;33m\u001b[0m\u001b[0m\n\u001b[0m\u001b[0;32m   4024\u001b[0m         \u001b[0mself\u001b[0m\u001b[1;33m.\u001b[0m\u001b[0mperform\u001b[0m\u001b[1;33m(\u001b[0m\u001b[1;32mNone\u001b[0m\u001b[1;33m,\u001b[0m \u001b[0minputs\u001b[0m\u001b[1;33m,\u001b[0m \u001b[0moutput_storage\u001b[0m\u001b[1;33m)\u001b[0m\u001b[1;33m\u001b[0m\u001b[0m\n",
      "\u001b[1;31mSystemError\u001b[0m: <class 'range'> returned a result with an error set",
      "\nThe above exception was the direct cause of the following exception:\n",
      "\u001b[1;31mSystemError\u001b[0m                               Traceback (most recent call last)",
      "\u001b[1;32m~\\Anaconda3\\lib\\site-packages\\theano\\scalar\\basic.py\u001b[0m in \u001b[0;36mimpl\u001b[1;34m(self, *inputs)\u001b[0m\n\u001b[0;32m   4022\u001b[0m     \u001b[1;32mdef\u001b[0m \u001b[0mimpl\u001b[0m\u001b[1;33m(\u001b[0m\u001b[0mself\u001b[0m\u001b[1;33m,\u001b[0m \u001b[1;33m*\u001b[0m\u001b[0minputs\u001b[0m\u001b[1;33m)\u001b[0m\u001b[1;33m:\u001b[0m\u001b[1;33m\u001b[0m\u001b[0m\n\u001b[1;32m-> 4023\u001b[1;33m         \u001b[0moutput_storage\u001b[0m \u001b[1;33m=\u001b[0m \u001b[1;33m[\u001b[0m\u001b[1;33m[\u001b[0m\u001b[1;32mNone\u001b[0m\u001b[1;33m]\u001b[0m \u001b[1;32mfor\u001b[0m \u001b[0mi\u001b[0m \u001b[1;32min\u001b[0m \u001b[0mxrange\u001b[0m\u001b[1;33m(\u001b[0m\u001b[0mself\u001b[0m\u001b[1;33m.\u001b[0m\u001b[0mnout\u001b[0m\u001b[1;33m)\u001b[0m\u001b[1;33m]\u001b[0m\u001b[1;33m\u001b[0m\u001b[0m\n\u001b[0m\u001b[0;32m   4024\u001b[0m         \u001b[0mself\u001b[0m\u001b[1;33m.\u001b[0m\u001b[0mperform\u001b[0m\u001b[1;33m(\u001b[0m\u001b[1;32mNone\u001b[0m\u001b[1;33m,\u001b[0m \u001b[0minputs\u001b[0m\u001b[1;33m,\u001b[0m \u001b[0moutput_storage\u001b[0m\u001b[1;33m)\u001b[0m\u001b[1;33m\u001b[0m\u001b[0m\n",
      "\u001b[1;31mSystemError\u001b[0m: <class 'range'> returned a result with an error set",
      "\nThe above exception was the direct cause of the following exception:\n",
      "\u001b[1;31mSystemError\u001b[0m                               Traceback (most recent call last)",
      "\u001b[1;32m~\\Anaconda3\\lib\\site-packages\\theano\\scalar\\basic.py\u001b[0m in \u001b[0;36mimpl\u001b[1;34m(self, *inputs)\u001b[0m\n\u001b[0;32m   4022\u001b[0m     \u001b[1;32mdef\u001b[0m \u001b[0mimpl\u001b[0m\u001b[1;33m(\u001b[0m\u001b[0mself\u001b[0m\u001b[1;33m,\u001b[0m \u001b[1;33m*\u001b[0m\u001b[0minputs\u001b[0m\u001b[1;33m)\u001b[0m\u001b[1;33m:\u001b[0m\u001b[1;33m\u001b[0m\u001b[0m\n\u001b[1;32m-> 4023\u001b[1;33m         \u001b[0moutput_storage\u001b[0m \u001b[1;33m=\u001b[0m \u001b[1;33m[\u001b[0m\u001b[1;33m[\u001b[0m\u001b[1;32mNone\u001b[0m\u001b[1;33m]\u001b[0m \u001b[1;32mfor\u001b[0m \u001b[0mi\u001b[0m \u001b[1;32min\u001b[0m \u001b[0mxrange\u001b[0m\u001b[1;33m(\u001b[0m\u001b[0mself\u001b[0m\u001b[1;33m.\u001b[0m\u001b[0mnout\u001b[0m\u001b[1;33m)\u001b[0m\u001b[1;33m]\u001b[0m\u001b[1;33m\u001b[0m\u001b[0m\n\u001b[0m\u001b[0;32m   4024\u001b[0m         \u001b[0mself\u001b[0m\u001b[1;33m.\u001b[0m\u001b[0mperform\u001b[0m\u001b[1;33m(\u001b[0m\u001b[1;32mNone\u001b[0m\u001b[1;33m,\u001b[0m \u001b[0minputs\u001b[0m\u001b[1;33m,\u001b[0m \u001b[0moutput_storage\u001b[0m\u001b[1;33m)\u001b[0m\u001b[1;33m\u001b[0m\u001b[0m\n",
      "\u001b[1;31mSystemError\u001b[0m: <class 'range'> returned a result with an error set",
      "\nThe above exception was the direct cause of the following exception:\n",
      "\u001b[1;31mSystemError\u001b[0m                               Traceback (most recent call last)",
      "\u001b[1;32m~\\Anaconda3\\lib\\site-packages\\theano\\scalar\\basic.py\u001b[0m in \u001b[0;36mimpl\u001b[1;34m(self, *inputs)\u001b[0m\n\u001b[0;32m   4022\u001b[0m     \u001b[1;32mdef\u001b[0m \u001b[0mimpl\u001b[0m\u001b[1;33m(\u001b[0m\u001b[0mself\u001b[0m\u001b[1;33m,\u001b[0m \u001b[1;33m*\u001b[0m\u001b[0minputs\u001b[0m\u001b[1;33m)\u001b[0m\u001b[1;33m:\u001b[0m\u001b[1;33m\u001b[0m\u001b[0m\n\u001b[1;32m-> 4023\u001b[1;33m         \u001b[0moutput_storage\u001b[0m \u001b[1;33m=\u001b[0m \u001b[1;33m[\u001b[0m\u001b[1;33m[\u001b[0m\u001b[1;32mNone\u001b[0m\u001b[1;33m]\u001b[0m \u001b[1;32mfor\u001b[0m \u001b[0mi\u001b[0m \u001b[1;32min\u001b[0m \u001b[0mxrange\u001b[0m\u001b[1;33m(\u001b[0m\u001b[0mself\u001b[0m\u001b[1;33m.\u001b[0m\u001b[0mnout\u001b[0m\u001b[1;33m)\u001b[0m\u001b[1;33m]\u001b[0m\u001b[1;33m\u001b[0m\u001b[0m\n\u001b[0m\u001b[0;32m   4024\u001b[0m         \u001b[0mself\u001b[0m\u001b[1;33m.\u001b[0m\u001b[0mperform\u001b[0m\u001b[1;33m(\u001b[0m\u001b[1;32mNone\u001b[0m\u001b[1;33m,\u001b[0m \u001b[0minputs\u001b[0m\u001b[1;33m,\u001b[0m \u001b[0moutput_storage\u001b[0m\u001b[1;33m)\u001b[0m\u001b[1;33m\u001b[0m\u001b[0m\n",
      "\u001b[1;31mSystemError\u001b[0m: <class 'range'> returned a result with an error set",
      "\nThe above exception was the direct cause of the following exception:\n",
      "\u001b[1;31mSystemError\u001b[0m                               Traceback (most recent call last)",
      "\u001b[1;32m~\\Anaconda3\\lib\\site-packages\\theano\\scalar\\basic.py\u001b[0m in \u001b[0;36mimpl\u001b[1;34m(self, *inputs)\u001b[0m\n\u001b[0;32m   4022\u001b[0m     \u001b[1;32mdef\u001b[0m \u001b[0mimpl\u001b[0m\u001b[1;33m(\u001b[0m\u001b[0mself\u001b[0m\u001b[1;33m,\u001b[0m \u001b[1;33m*\u001b[0m\u001b[0minputs\u001b[0m\u001b[1;33m)\u001b[0m\u001b[1;33m:\u001b[0m\u001b[1;33m\u001b[0m\u001b[0m\n\u001b[1;32m-> 4023\u001b[1;33m         \u001b[0moutput_storage\u001b[0m \u001b[1;33m=\u001b[0m \u001b[1;33m[\u001b[0m\u001b[1;33m[\u001b[0m\u001b[1;32mNone\u001b[0m\u001b[1;33m]\u001b[0m \u001b[1;32mfor\u001b[0m \u001b[0mi\u001b[0m \u001b[1;32min\u001b[0m \u001b[0mxrange\u001b[0m\u001b[1;33m(\u001b[0m\u001b[0mself\u001b[0m\u001b[1;33m.\u001b[0m\u001b[0mnout\u001b[0m\u001b[1;33m)\u001b[0m\u001b[1;33m]\u001b[0m\u001b[1;33m\u001b[0m\u001b[0m\n\u001b[0m\u001b[0;32m   4024\u001b[0m         \u001b[0mself\u001b[0m\u001b[1;33m.\u001b[0m\u001b[0mperform\u001b[0m\u001b[1;33m(\u001b[0m\u001b[1;32mNone\u001b[0m\u001b[1;33m,\u001b[0m \u001b[0minputs\u001b[0m\u001b[1;33m,\u001b[0m \u001b[0moutput_storage\u001b[0m\u001b[1;33m)\u001b[0m\u001b[1;33m\u001b[0m\u001b[0m\n",
      "\u001b[1;31mSystemError\u001b[0m: <class 'range'> returned a result with an error set",
      "\nThe above exception was the direct cause of the following exception:\n",
      "\u001b[1;31mSystemError\u001b[0m                               Traceback (most recent call last)",
      "\u001b[1;32m~\\Anaconda3\\lib\\site-packages\\theano\\scalar\\basic.py\u001b[0m in \u001b[0;36mimpl\u001b[1;34m(self, *inputs)\u001b[0m\n\u001b[0;32m   4022\u001b[0m     \u001b[1;32mdef\u001b[0m \u001b[0mimpl\u001b[0m\u001b[1;33m(\u001b[0m\u001b[0mself\u001b[0m\u001b[1;33m,\u001b[0m \u001b[1;33m*\u001b[0m\u001b[0minputs\u001b[0m\u001b[1;33m)\u001b[0m\u001b[1;33m:\u001b[0m\u001b[1;33m\u001b[0m\u001b[0m\n\u001b[1;32m-> 4023\u001b[1;33m         \u001b[0moutput_storage\u001b[0m \u001b[1;33m=\u001b[0m \u001b[1;33m[\u001b[0m\u001b[1;33m[\u001b[0m\u001b[1;32mNone\u001b[0m\u001b[1;33m]\u001b[0m \u001b[1;32mfor\u001b[0m \u001b[0mi\u001b[0m \u001b[1;32min\u001b[0m \u001b[0mxrange\u001b[0m\u001b[1;33m(\u001b[0m\u001b[0mself\u001b[0m\u001b[1;33m.\u001b[0m\u001b[0mnout\u001b[0m\u001b[1;33m)\u001b[0m\u001b[1;33m]\u001b[0m\u001b[1;33m\u001b[0m\u001b[0m\n\u001b[0m\u001b[0;32m   4024\u001b[0m         \u001b[0mself\u001b[0m\u001b[1;33m.\u001b[0m\u001b[0mperform\u001b[0m\u001b[1;33m(\u001b[0m\u001b[1;32mNone\u001b[0m\u001b[1;33m,\u001b[0m \u001b[0minputs\u001b[0m\u001b[1;33m,\u001b[0m \u001b[0moutput_storage\u001b[0m\u001b[1;33m)\u001b[0m\u001b[1;33m\u001b[0m\u001b[0m\n",
      "\u001b[1;31mSystemError\u001b[0m: <class 'range'> returned a result with an error set",
      "\nThe above exception was the direct cause of the following exception:\n",
      "\u001b[1;31mSystemError\u001b[0m                               Traceback (most recent call last)",
      "\u001b[1;32m~\\Anaconda3\\lib\\site-packages\\theano\\scalar\\basic.py\u001b[0m in \u001b[0;36mimpl\u001b[1;34m(self, *inputs)\u001b[0m\n\u001b[0;32m   4022\u001b[0m     \u001b[1;32mdef\u001b[0m \u001b[0mimpl\u001b[0m\u001b[1;33m(\u001b[0m\u001b[0mself\u001b[0m\u001b[1;33m,\u001b[0m \u001b[1;33m*\u001b[0m\u001b[0minputs\u001b[0m\u001b[1;33m)\u001b[0m\u001b[1;33m:\u001b[0m\u001b[1;33m\u001b[0m\u001b[0m\n\u001b[1;32m-> 4023\u001b[1;33m         \u001b[0moutput_storage\u001b[0m \u001b[1;33m=\u001b[0m \u001b[1;33m[\u001b[0m\u001b[1;33m[\u001b[0m\u001b[1;32mNone\u001b[0m\u001b[1;33m]\u001b[0m \u001b[1;32mfor\u001b[0m \u001b[0mi\u001b[0m \u001b[1;32min\u001b[0m \u001b[0mxrange\u001b[0m\u001b[1;33m(\u001b[0m\u001b[0mself\u001b[0m\u001b[1;33m.\u001b[0m\u001b[0mnout\u001b[0m\u001b[1;33m)\u001b[0m\u001b[1;33m]\u001b[0m\u001b[1;33m\u001b[0m\u001b[0m\n\u001b[0m\u001b[0;32m   4024\u001b[0m         \u001b[0mself\u001b[0m\u001b[1;33m.\u001b[0m\u001b[0mperform\u001b[0m\u001b[1;33m(\u001b[0m\u001b[1;32mNone\u001b[0m\u001b[1;33m,\u001b[0m \u001b[0minputs\u001b[0m\u001b[1;33m,\u001b[0m \u001b[0moutput_storage\u001b[0m\u001b[1;33m)\u001b[0m\u001b[1;33m\u001b[0m\u001b[0m\n",
      "\u001b[1;31mSystemError\u001b[0m: <class 'range'> returned a result with an error set",
      "\nThe above exception was the direct cause of the following exception:\n",
      "\u001b[1;31mSystemError\u001b[0m                               Traceback (most recent call last)",
      "\u001b[1;32m~\\Anaconda3\\lib\\site-packages\\theano\\scalar\\basic.py\u001b[0m in \u001b[0;36mimpl\u001b[1;34m(self, *inputs)\u001b[0m\n\u001b[0;32m   4022\u001b[0m     \u001b[1;32mdef\u001b[0m \u001b[0mimpl\u001b[0m\u001b[1;33m(\u001b[0m\u001b[0mself\u001b[0m\u001b[1;33m,\u001b[0m \u001b[1;33m*\u001b[0m\u001b[0minputs\u001b[0m\u001b[1;33m)\u001b[0m\u001b[1;33m:\u001b[0m\u001b[1;33m\u001b[0m\u001b[0m\n\u001b[1;32m-> 4023\u001b[1;33m         \u001b[0moutput_storage\u001b[0m \u001b[1;33m=\u001b[0m \u001b[1;33m[\u001b[0m\u001b[1;33m[\u001b[0m\u001b[1;32mNone\u001b[0m\u001b[1;33m]\u001b[0m \u001b[1;32mfor\u001b[0m \u001b[0mi\u001b[0m \u001b[1;32min\u001b[0m \u001b[0mxrange\u001b[0m\u001b[1;33m(\u001b[0m\u001b[0mself\u001b[0m\u001b[1;33m.\u001b[0m\u001b[0mnout\u001b[0m\u001b[1;33m)\u001b[0m\u001b[1;33m]\u001b[0m\u001b[1;33m\u001b[0m\u001b[0m\n\u001b[0m\u001b[0;32m   4024\u001b[0m         \u001b[0mself\u001b[0m\u001b[1;33m.\u001b[0m\u001b[0mperform\u001b[0m\u001b[1;33m(\u001b[0m\u001b[1;32mNone\u001b[0m\u001b[1;33m,\u001b[0m \u001b[0minputs\u001b[0m\u001b[1;33m,\u001b[0m \u001b[0moutput_storage\u001b[0m\u001b[1;33m)\u001b[0m\u001b[1;33m\u001b[0m\u001b[0m\n",
      "\u001b[1;31mSystemError\u001b[0m: <class 'range'> returned a result with an error set",
      "\nThe above exception was the direct cause of the following exception:\n",
      "\u001b[1;31mSystemError\u001b[0m                               Traceback (most recent call last)",
      "\u001b[1;32m~\\Anaconda3\\lib\\site-packages\\theano\\scalar\\basic.py\u001b[0m in \u001b[0;36mimpl\u001b[1;34m(self, *inputs)\u001b[0m\n\u001b[0;32m   4022\u001b[0m     \u001b[1;32mdef\u001b[0m \u001b[0mimpl\u001b[0m\u001b[1;33m(\u001b[0m\u001b[0mself\u001b[0m\u001b[1;33m,\u001b[0m \u001b[1;33m*\u001b[0m\u001b[0minputs\u001b[0m\u001b[1;33m)\u001b[0m\u001b[1;33m:\u001b[0m\u001b[1;33m\u001b[0m\u001b[0m\n\u001b[1;32m-> 4023\u001b[1;33m         \u001b[0moutput_storage\u001b[0m \u001b[1;33m=\u001b[0m \u001b[1;33m[\u001b[0m\u001b[1;33m[\u001b[0m\u001b[1;32mNone\u001b[0m\u001b[1;33m]\u001b[0m \u001b[1;32mfor\u001b[0m \u001b[0mi\u001b[0m \u001b[1;32min\u001b[0m \u001b[0mxrange\u001b[0m\u001b[1;33m(\u001b[0m\u001b[0mself\u001b[0m\u001b[1;33m.\u001b[0m\u001b[0mnout\u001b[0m\u001b[1;33m)\u001b[0m\u001b[1;33m]\u001b[0m\u001b[1;33m\u001b[0m\u001b[0m\n\u001b[0m\u001b[0;32m   4024\u001b[0m         \u001b[0mself\u001b[0m\u001b[1;33m.\u001b[0m\u001b[0mperform\u001b[0m\u001b[1;33m(\u001b[0m\u001b[1;32mNone\u001b[0m\u001b[1;33m,\u001b[0m \u001b[0minputs\u001b[0m\u001b[1;33m,\u001b[0m \u001b[0moutput_storage\u001b[0m\u001b[1;33m)\u001b[0m\u001b[1;33m\u001b[0m\u001b[0m\n",
      "\u001b[1;31mSystemError\u001b[0m: <class 'range'> returned a result with an error set",
      "\nThe above exception was the direct cause of the following exception:\n",
      "\u001b[1;31mSystemError\u001b[0m                               Traceback (most recent call last)",
      "\u001b[1;32m~\\Anaconda3\\lib\\site-packages\\theano\\scalar\\basic.py\u001b[0m in \u001b[0;36mimpl\u001b[1;34m(self, *inputs)\u001b[0m\n\u001b[0;32m   4022\u001b[0m     \u001b[1;32mdef\u001b[0m \u001b[0mimpl\u001b[0m\u001b[1;33m(\u001b[0m\u001b[0mself\u001b[0m\u001b[1;33m,\u001b[0m \u001b[1;33m*\u001b[0m\u001b[0minputs\u001b[0m\u001b[1;33m)\u001b[0m\u001b[1;33m:\u001b[0m\u001b[1;33m\u001b[0m\u001b[0m\n\u001b[1;32m-> 4023\u001b[1;33m         \u001b[0moutput_storage\u001b[0m \u001b[1;33m=\u001b[0m \u001b[1;33m[\u001b[0m\u001b[1;33m[\u001b[0m\u001b[1;32mNone\u001b[0m\u001b[1;33m]\u001b[0m \u001b[1;32mfor\u001b[0m \u001b[0mi\u001b[0m \u001b[1;32min\u001b[0m \u001b[0mxrange\u001b[0m\u001b[1;33m(\u001b[0m\u001b[0mself\u001b[0m\u001b[1;33m.\u001b[0m\u001b[0mnout\u001b[0m\u001b[1;33m)\u001b[0m\u001b[1;33m]\u001b[0m\u001b[1;33m\u001b[0m\u001b[0m\n\u001b[0m\u001b[0;32m   4024\u001b[0m         \u001b[0mself\u001b[0m\u001b[1;33m.\u001b[0m\u001b[0mperform\u001b[0m\u001b[1;33m(\u001b[0m\u001b[1;32mNone\u001b[0m\u001b[1;33m,\u001b[0m \u001b[0minputs\u001b[0m\u001b[1;33m,\u001b[0m \u001b[0moutput_storage\u001b[0m\u001b[1;33m)\u001b[0m\u001b[1;33m\u001b[0m\u001b[0m\n",
      "\u001b[1;31mSystemError\u001b[0m: <class 'range'> returned a result with an error set",
      "\nThe above exception was the direct cause of the following exception:\n",
      "\u001b[1;31mSystemError\u001b[0m                               Traceback (most recent call last)",
      "\u001b[1;32m~\\Anaconda3\\lib\\site-packages\\theano\\scalar\\basic.py\u001b[0m in \u001b[0;36mimpl\u001b[1;34m(self, *inputs)\u001b[0m\n\u001b[0;32m   4022\u001b[0m     \u001b[1;32mdef\u001b[0m \u001b[0mimpl\u001b[0m\u001b[1;33m(\u001b[0m\u001b[0mself\u001b[0m\u001b[1;33m,\u001b[0m \u001b[1;33m*\u001b[0m\u001b[0minputs\u001b[0m\u001b[1;33m)\u001b[0m\u001b[1;33m:\u001b[0m\u001b[1;33m\u001b[0m\u001b[0m\n\u001b[1;32m-> 4023\u001b[1;33m         \u001b[0moutput_storage\u001b[0m \u001b[1;33m=\u001b[0m \u001b[1;33m[\u001b[0m\u001b[1;33m[\u001b[0m\u001b[1;32mNone\u001b[0m\u001b[1;33m]\u001b[0m \u001b[1;32mfor\u001b[0m \u001b[0mi\u001b[0m \u001b[1;32min\u001b[0m \u001b[0mxrange\u001b[0m\u001b[1;33m(\u001b[0m\u001b[0mself\u001b[0m\u001b[1;33m.\u001b[0m\u001b[0mnout\u001b[0m\u001b[1;33m)\u001b[0m\u001b[1;33m]\u001b[0m\u001b[1;33m\u001b[0m\u001b[0m\n\u001b[0m\u001b[0;32m   4024\u001b[0m         \u001b[0mself\u001b[0m\u001b[1;33m.\u001b[0m\u001b[0mperform\u001b[0m\u001b[1;33m(\u001b[0m\u001b[1;32mNone\u001b[0m\u001b[1;33m,\u001b[0m \u001b[0minputs\u001b[0m\u001b[1;33m,\u001b[0m \u001b[0moutput_storage\u001b[0m\u001b[1;33m)\u001b[0m\u001b[1;33m\u001b[0m\u001b[0m\n",
      "\u001b[1;31mSystemError\u001b[0m: <class 'range'> returned a result with an error set",
      "\nThe above exception was the direct cause of the following exception:\n",
      "\u001b[1;31mSystemError\u001b[0m                               Traceback (most recent call last)",
      "\u001b[1;32m~\\Anaconda3\\lib\\site-packages\\theano\\scalar\\basic.py\u001b[0m in \u001b[0;36mimpl\u001b[1;34m(self, *inputs)\u001b[0m\n\u001b[0;32m   4022\u001b[0m     \u001b[1;32mdef\u001b[0m \u001b[0mimpl\u001b[0m\u001b[1;33m(\u001b[0m\u001b[0mself\u001b[0m\u001b[1;33m,\u001b[0m \u001b[1;33m*\u001b[0m\u001b[0minputs\u001b[0m\u001b[1;33m)\u001b[0m\u001b[1;33m:\u001b[0m\u001b[1;33m\u001b[0m\u001b[0m\n\u001b[1;32m-> 4023\u001b[1;33m         \u001b[0moutput_storage\u001b[0m \u001b[1;33m=\u001b[0m \u001b[1;33m[\u001b[0m\u001b[1;33m[\u001b[0m\u001b[1;32mNone\u001b[0m\u001b[1;33m]\u001b[0m \u001b[1;32mfor\u001b[0m \u001b[0mi\u001b[0m \u001b[1;32min\u001b[0m \u001b[0mxrange\u001b[0m\u001b[1;33m(\u001b[0m\u001b[0mself\u001b[0m\u001b[1;33m.\u001b[0m\u001b[0mnout\u001b[0m\u001b[1;33m)\u001b[0m\u001b[1;33m]\u001b[0m\u001b[1;33m\u001b[0m\u001b[0m\n\u001b[0m\u001b[0;32m   4024\u001b[0m         \u001b[0mself\u001b[0m\u001b[1;33m.\u001b[0m\u001b[0mperform\u001b[0m\u001b[1;33m(\u001b[0m\u001b[1;32mNone\u001b[0m\u001b[1;33m,\u001b[0m \u001b[0minputs\u001b[0m\u001b[1;33m,\u001b[0m \u001b[0moutput_storage\u001b[0m\u001b[1;33m)\u001b[0m\u001b[1;33m\u001b[0m\u001b[0m\n",
      "\u001b[1;31mSystemError\u001b[0m: <class 'range'> returned a result with an error set",
      "\nThe above exception was the direct cause of the following exception:\n",
      "\u001b[1;31mSystemError\u001b[0m                               Traceback (most recent call last)",
      "\u001b[1;32m~\\Anaconda3\\lib\\site-packages\\theano\\scalar\\basic.py\u001b[0m in \u001b[0;36mimpl\u001b[1;34m(self, *inputs)\u001b[0m\n\u001b[0;32m   4022\u001b[0m     \u001b[1;32mdef\u001b[0m \u001b[0mimpl\u001b[0m\u001b[1;33m(\u001b[0m\u001b[0mself\u001b[0m\u001b[1;33m,\u001b[0m \u001b[1;33m*\u001b[0m\u001b[0minputs\u001b[0m\u001b[1;33m)\u001b[0m\u001b[1;33m:\u001b[0m\u001b[1;33m\u001b[0m\u001b[0m\n\u001b[1;32m-> 4023\u001b[1;33m         \u001b[0moutput_storage\u001b[0m \u001b[1;33m=\u001b[0m \u001b[1;33m[\u001b[0m\u001b[1;33m[\u001b[0m\u001b[1;32mNone\u001b[0m\u001b[1;33m]\u001b[0m \u001b[1;32mfor\u001b[0m \u001b[0mi\u001b[0m \u001b[1;32min\u001b[0m \u001b[0mxrange\u001b[0m\u001b[1;33m(\u001b[0m\u001b[0mself\u001b[0m\u001b[1;33m.\u001b[0m\u001b[0mnout\u001b[0m\u001b[1;33m)\u001b[0m\u001b[1;33m]\u001b[0m\u001b[1;33m\u001b[0m\u001b[0m\n\u001b[0m\u001b[0;32m   4024\u001b[0m         \u001b[0mself\u001b[0m\u001b[1;33m.\u001b[0m\u001b[0mperform\u001b[0m\u001b[1;33m(\u001b[0m\u001b[1;32mNone\u001b[0m\u001b[1;33m,\u001b[0m \u001b[0minputs\u001b[0m\u001b[1;33m,\u001b[0m \u001b[0moutput_storage\u001b[0m\u001b[1;33m)\u001b[0m\u001b[1;33m\u001b[0m\u001b[0m\n",
      "\u001b[1;31mSystemError\u001b[0m: <class 'range'> returned a result with an error set",
      "\nThe above exception was the direct cause of the following exception:\n",
      "\u001b[1;31mSystemError\u001b[0m                               Traceback (most recent call last)",
      "\u001b[1;32m~\\Anaconda3\\lib\\site-packages\\theano\\scalar\\basic.py\u001b[0m in \u001b[0;36mimpl\u001b[1;34m(self, *inputs)\u001b[0m\n\u001b[0;32m   4022\u001b[0m     \u001b[1;32mdef\u001b[0m \u001b[0mimpl\u001b[0m\u001b[1;33m(\u001b[0m\u001b[0mself\u001b[0m\u001b[1;33m,\u001b[0m \u001b[1;33m*\u001b[0m\u001b[0minputs\u001b[0m\u001b[1;33m)\u001b[0m\u001b[1;33m:\u001b[0m\u001b[1;33m\u001b[0m\u001b[0m\n\u001b[1;32m-> 4023\u001b[1;33m         \u001b[0moutput_storage\u001b[0m \u001b[1;33m=\u001b[0m \u001b[1;33m[\u001b[0m\u001b[1;33m[\u001b[0m\u001b[1;32mNone\u001b[0m\u001b[1;33m]\u001b[0m \u001b[1;32mfor\u001b[0m \u001b[0mi\u001b[0m \u001b[1;32min\u001b[0m \u001b[0mxrange\u001b[0m\u001b[1;33m(\u001b[0m\u001b[0mself\u001b[0m\u001b[1;33m.\u001b[0m\u001b[0mnout\u001b[0m\u001b[1;33m)\u001b[0m\u001b[1;33m]\u001b[0m\u001b[1;33m\u001b[0m\u001b[0m\n\u001b[0m\u001b[0;32m   4024\u001b[0m         \u001b[0mself\u001b[0m\u001b[1;33m.\u001b[0m\u001b[0mperform\u001b[0m\u001b[1;33m(\u001b[0m\u001b[1;32mNone\u001b[0m\u001b[1;33m,\u001b[0m \u001b[0minputs\u001b[0m\u001b[1;33m,\u001b[0m \u001b[0moutput_storage\u001b[0m\u001b[1;33m)\u001b[0m\u001b[1;33m\u001b[0m\u001b[0m\n",
      "\u001b[1;31mSystemError\u001b[0m: <class 'range'> returned a result with an error set",
      "\nThe above exception was the direct cause of the following exception:\n",
      "\u001b[1;31mSystemError\u001b[0m                               Traceback (most recent call last)",
      "\u001b[1;32m~\\Anaconda3\\lib\\site-packages\\theano\\scalar\\basic.py\u001b[0m in \u001b[0;36mimpl\u001b[1;34m(self, *inputs)\u001b[0m\n\u001b[0;32m   4022\u001b[0m     \u001b[1;32mdef\u001b[0m \u001b[0mimpl\u001b[0m\u001b[1;33m(\u001b[0m\u001b[0mself\u001b[0m\u001b[1;33m,\u001b[0m \u001b[1;33m*\u001b[0m\u001b[0minputs\u001b[0m\u001b[1;33m)\u001b[0m\u001b[1;33m:\u001b[0m\u001b[1;33m\u001b[0m\u001b[0m\n\u001b[1;32m-> 4023\u001b[1;33m         \u001b[0moutput_storage\u001b[0m \u001b[1;33m=\u001b[0m \u001b[1;33m[\u001b[0m\u001b[1;33m[\u001b[0m\u001b[1;32mNone\u001b[0m\u001b[1;33m]\u001b[0m \u001b[1;32mfor\u001b[0m \u001b[0mi\u001b[0m \u001b[1;32min\u001b[0m \u001b[0mxrange\u001b[0m\u001b[1;33m(\u001b[0m\u001b[0mself\u001b[0m\u001b[1;33m.\u001b[0m\u001b[0mnout\u001b[0m\u001b[1;33m)\u001b[0m\u001b[1;33m]\u001b[0m\u001b[1;33m\u001b[0m\u001b[0m\n\u001b[0m\u001b[0;32m   4024\u001b[0m         \u001b[0mself\u001b[0m\u001b[1;33m.\u001b[0m\u001b[0mperform\u001b[0m\u001b[1;33m(\u001b[0m\u001b[1;32mNone\u001b[0m\u001b[1;33m,\u001b[0m \u001b[0minputs\u001b[0m\u001b[1;33m,\u001b[0m \u001b[0moutput_storage\u001b[0m\u001b[1;33m)\u001b[0m\u001b[1;33m\u001b[0m\u001b[0m\n",
      "\u001b[1;31mSystemError\u001b[0m: <class 'range'> returned a result with an error set",
      "\nThe above exception was the direct cause of the following exception:\n",
      "\u001b[1;31mSystemError\u001b[0m                               Traceback (most recent call last)",
      "\u001b[1;32m~\\Anaconda3\\lib\\site-packages\\theano\\scalar\\basic.py\u001b[0m in \u001b[0;36mimpl\u001b[1;34m(self, *inputs)\u001b[0m\n\u001b[0;32m   4022\u001b[0m     \u001b[1;32mdef\u001b[0m \u001b[0mimpl\u001b[0m\u001b[1;33m(\u001b[0m\u001b[0mself\u001b[0m\u001b[1;33m,\u001b[0m \u001b[1;33m*\u001b[0m\u001b[0minputs\u001b[0m\u001b[1;33m)\u001b[0m\u001b[1;33m:\u001b[0m\u001b[1;33m\u001b[0m\u001b[0m\n\u001b[1;32m-> 4023\u001b[1;33m         \u001b[0moutput_storage\u001b[0m \u001b[1;33m=\u001b[0m \u001b[1;33m[\u001b[0m\u001b[1;33m[\u001b[0m\u001b[1;32mNone\u001b[0m\u001b[1;33m]\u001b[0m \u001b[1;32mfor\u001b[0m \u001b[0mi\u001b[0m \u001b[1;32min\u001b[0m \u001b[0mxrange\u001b[0m\u001b[1;33m(\u001b[0m\u001b[0mself\u001b[0m\u001b[1;33m.\u001b[0m\u001b[0mnout\u001b[0m\u001b[1;33m)\u001b[0m\u001b[1;33m]\u001b[0m\u001b[1;33m\u001b[0m\u001b[0m\n\u001b[0m\u001b[0;32m   4024\u001b[0m         \u001b[0mself\u001b[0m\u001b[1;33m.\u001b[0m\u001b[0mperform\u001b[0m\u001b[1;33m(\u001b[0m\u001b[1;32mNone\u001b[0m\u001b[1;33m,\u001b[0m \u001b[0minputs\u001b[0m\u001b[1;33m,\u001b[0m \u001b[0moutput_storage\u001b[0m\u001b[1;33m)\u001b[0m\u001b[1;33m\u001b[0m\u001b[0m\n",
      "\u001b[1;31mSystemError\u001b[0m: <class 'range'> returned a result with an error set",
      "\nThe above exception was the direct cause of the following exception:\n",
      "\u001b[1;31mSystemError\u001b[0m                               Traceback (most recent call last)",
      "\u001b[1;32m~\\Anaconda3\\lib\\site-packages\\theano\\scalar\\basic.py\u001b[0m in \u001b[0;36mimpl\u001b[1;34m(self, *inputs)\u001b[0m\n\u001b[0;32m   4022\u001b[0m     \u001b[1;32mdef\u001b[0m \u001b[0mimpl\u001b[0m\u001b[1;33m(\u001b[0m\u001b[0mself\u001b[0m\u001b[1;33m,\u001b[0m \u001b[1;33m*\u001b[0m\u001b[0minputs\u001b[0m\u001b[1;33m)\u001b[0m\u001b[1;33m:\u001b[0m\u001b[1;33m\u001b[0m\u001b[0m\n\u001b[1;32m-> 4023\u001b[1;33m         \u001b[0moutput_storage\u001b[0m \u001b[1;33m=\u001b[0m \u001b[1;33m[\u001b[0m\u001b[1;33m[\u001b[0m\u001b[1;32mNone\u001b[0m\u001b[1;33m]\u001b[0m \u001b[1;32mfor\u001b[0m \u001b[0mi\u001b[0m \u001b[1;32min\u001b[0m \u001b[0mxrange\u001b[0m\u001b[1;33m(\u001b[0m\u001b[0mself\u001b[0m\u001b[1;33m.\u001b[0m\u001b[0mnout\u001b[0m\u001b[1;33m)\u001b[0m\u001b[1;33m]\u001b[0m\u001b[1;33m\u001b[0m\u001b[0m\n\u001b[0m\u001b[0;32m   4024\u001b[0m         \u001b[0mself\u001b[0m\u001b[1;33m.\u001b[0m\u001b[0mperform\u001b[0m\u001b[1;33m(\u001b[0m\u001b[1;32mNone\u001b[0m\u001b[1;33m,\u001b[0m \u001b[0minputs\u001b[0m\u001b[1;33m,\u001b[0m \u001b[0moutput_storage\u001b[0m\u001b[1;33m)\u001b[0m\u001b[1;33m\u001b[0m\u001b[0m\n",
      "\u001b[1;31mSystemError\u001b[0m: <class 'range'> returned a result with an error set",
      "\nThe above exception was the direct cause of the following exception:\n",
      "\u001b[1;31mSystemError\u001b[0m                               Traceback (most recent call last)",
      "\u001b[1;32m~\\Anaconda3\\lib\\site-packages\\theano\\scalar\\basic.py\u001b[0m in \u001b[0;36mimpl\u001b[1;34m(self, *inputs)\u001b[0m\n\u001b[0;32m   4022\u001b[0m     \u001b[1;32mdef\u001b[0m \u001b[0mimpl\u001b[0m\u001b[1;33m(\u001b[0m\u001b[0mself\u001b[0m\u001b[1;33m,\u001b[0m \u001b[1;33m*\u001b[0m\u001b[0minputs\u001b[0m\u001b[1;33m)\u001b[0m\u001b[1;33m:\u001b[0m\u001b[1;33m\u001b[0m\u001b[0m\n\u001b[1;32m-> 4023\u001b[1;33m         \u001b[0moutput_storage\u001b[0m \u001b[1;33m=\u001b[0m \u001b[1;33m[\u001b[0m\u001b[1;33m[\u001b[0m\u001b[1;32mNone\u001b[0m\u001b[1;33m]\u001b[0m \u001b[1;32mfor\u001b[0m \u001b[0mi\u001b[0m \u001b[1;32min\u001b[0m \u001b[0mxrange\u001b[0m\u001b[1;33m(\u001b[0m\u001b[0mself\u001b[0m\u001b[1;33m.\u001b[0m\u001b[0mnout\u001b[0m\u001b[1;33m)\u001b[0m\u001b[1;33m]\u001b[0m\u001b[1;33m\u001b[0m\u001b[0m\n\u001b[0m\u001b[0;32m   4024\u001b[0m         \u001b[0mself\u001b[0m\u001b[1;33m.\u001b[0m\u001b[0mperform\u001b[0m\u001b[1;33m(\u001b[0m\u001b[1;32mNone\u001b[0m\u001b[1;33m,\u001b[0m \u001b[0minputs\u001b[0m\u001b[1;33m,\u001b[0m \u001b[0moutput_storage\u001b[0m\u001b[1;33m)\u001b[0m\u001b[1;33m\u001b[0m\u001b[0m\n",
      "\u001b[1;31mSystemError\u001b[0m: <class 'range'> returned a result with an error set",
      "\nThe above exception was the direct cause of the following exception:\n",
      "\u001b[1;31mSystemError\u001b[0m                               Traceback (most recent call last)",
      "\u001b[1;32m~\\Anaconda3\\lib\\site-packages\\theano\\scalar\\basic.py\u001b[0m in \u001b[0;36mimpl\u001b[1;34m(self, *inputs)\u001b[0m\n\u001b[0;32m   4022\u001b[0m     \u001b[1;32mdef\u001b[0m \u001b[0mimpl\u001b[0m\u001b[1;33m(\u001b[0m\u001b[0mself\u001b[0m\u001b[1;33m,\u001b[0m \u001b[1;33m*\u001b[0m\u001b[0minputs\u001b[0m\u001b[1;33m)\u001b[0m\u001b[1;33m:\u001b[0m\u001b[1;33m\u001b[0m\u001b[0m\n\u001b[1;32m-> 4023\u001b[1;33m         \u001b[0moutput_storage\u001b[0m \u001b[1;33m=\u001b[0m \u001b[1;33m[\u001b[0m\u001b[1;33m[\u001b[0m\u001b[1;32mNone\u001b[0m\u001b[1;33m]\u001b[0m \u001b[1;32mfor\u001b[0m \u001b[0mi\u001b[0m \u001b[1;32min\u001b[0m \u001b[0mxrange\u001b[0m\u001b[1;33m(\u001b[0m\u001b[0mself\u001b[0m\u001b[1;33m.\u001b[0m\u001b[0mnout\u001b[0m\u001b[1;33m)\u001b[0m\u001b[1;33m]\u001b[0m\u001b[1;33m\u001b[0m\u001b[0m\n\u001b[0m\u001b[0;32m   4024\u001b[0m         \u001b[0mself\u001b[0m\u001b[1;33m.\u001b[0m\u001b[0mperform\u001b[0m\u001b[1;33m(\u001b[0m\u001b[1;32mNone\u001b[0m\u001b[1;33m,\u001b[0m \u001b[0minputs\u001b[0m\u001b[1;33m,\u001b[0m \u001b[0moutput_storage\u001b[0m\u001b[1;33m)\u001b[0m\u001b[1;33m\u001b[0m\u001b[0m\n",
      "\u001b[1;31mSystemError\u001b[0m: <class 'range'> returned a result with an error set",
      "\nThe above exception was the direct cause of the following exception:\n",
      "\u001b[1;31mSystemError\u001b[0m                               Traceback (most recent call last)",
      "\u001b[1;32m~\\Anaconda3\\lib\\site-packages\\theano\\scalar\\basic.py\u001b[0m in \u001b[0;36mimpl\u001b[1;34m(self, *inputs)\u001b[0m\n\u001b[0;32m   4022\u001b[0m     \u001b[1;32mdef\u001b[0m \u001b[0mimpl\u001b[0m\u001b[1;33m(\u001b[0m\u001b[0mself\u001b[0m\u001b[1;33m,\u001b[0m \u001b[1;33m*\u001b[0m\u001b[0minputs\u001b[0m\u001b[1;33m)\u001b[0m\u001b[1;33m:\u001b[0m\u001b[1;33m\u001b[0m\u001b[0m\n\u001b[1;32m-> 4023\u001b[1;33m         \u001b[0moutput_storage\u001b[0m \u001b[1;33m=\u001b[0m \u001b[1;33m[\u001b[0m\u001b[1;33m[\u001b[0m\u001b[1;32mNone\u001b[0m\u001b[1;33m]\u001b[0m \u001b[1;32mfor\u001b[0m \u001b[0mi\u001b[0m \u001b[1;32min\u001b[0m \u001b[0mxrange\u001b[0m\u001b[1;33m(\u001b[0m\u001b[0mself\u001b[0m\u001b[1;33m.\u001b[0m\u001b[0mnout\u001b[0m\u001b[1;33m)\u001b[0m\u001b[1;33m]\u001b[0m\u001b[1;33m\u001b[0m\u001b[0m\n\u001b[0m\u001b[0;32m   4024\u001b[0m         \u001b[0mself\u001b[0m\u001b[1;33m.\u001b[0m\u001b[0mperform\u001b[0m\u001b[1;33m(\u001b[0m\u001b[1;32mNone\u001b[0m\u001b[1;33m,\u001b[0m \u001b[0minputs\u001b[0m\u001b[1;33m,\u001b[0m \u001b[0moutput_storage\u001b[0m\u001b[1;33m)\u001b[0m\u001b[1;33m\u001b[0m\u001b[0m\n",
      "\u001b[1;31mSystemError\u001b[0m: <class 'range'> returned a result with an error set",
      "\nThe above exception was the direct cause of the following exception:\n",
      "\u001b[1;31mSystemError\u001b[0m                               Traceback (most recent call last)",
      "\u001b[1;32m~\\Anaconda3\\lib\\site-packages\\theano\\scalar\\basic.py\u001b[0m in \u001b[0;36mimpl\u001b[1;34m(self, *inputs)\u001b[0m\n\u001b[0;32m   4022\u001b[0m     \u001b[1;32mdef\u001b[0m \u001b[0mimpl\u001b[0m\u001b[1;33m(\u001b[0m\u001b[0mself\u001b[0m\u001b[1;33m,\u001b[0m \u001b[1;33m*\u001b[0m\u001b[0minputs\u001b[0m\u001b[1;33m)\u001b[0m\u001b[1;33m:\u001b[0m\u001b[1;33m\u001b[0m\u001b[0m\n\u001b[1;32m-> 4023\u001b[1;33m         \u001b[0moutput_storage\u001b[0m \u001b[1;33m=\u001b[0m \u001b[1;33m[\u001b[0m\u001b[1;33m[\u001b[0m\u001b[1;32mNone\u001b[0m\u001b[1;33m]\u001b[0m \u001b[1;32mfor\u001b[0m \u001b[0mi\u001b[0m \u001b[1;32min\u001b[0m \u001b[0mxrange\u001b[0m\u001b[1;33m(\u001b[0m\u001b[0mself\u001b[0m\u001b[1;33m.\u001b[0m\u001b[0mnout\u001b[0m\u001b[1;33m)\u001b[0m\u001b[1;33m]\u001b[0m\u001b[1;33m\u001b[0m\u001b[0m\n\u001b[0m\u001b[0;32m   4024\u001b[0m         \u001b[0mself\u001b[0m\u001b[1;33m.\u001b[0m\u001b[0mperform\u001b[0m\u001b[1;33m(\u001b[0m\u001b[1;32mNone\u001b[0m\u001b[1;33m,\u001b[0m \u001b[0minputs\u001b[0m\u001b[1;33m,\u001b[0m \u001b[0moutput_storage\u001b[0m\u001b[1;33m)\u001b[0m\u001b[1;33m\u001b[0m\u001b[0m\n",
      "\u001b[1;31mSystemError\u001b[0m: <class 'range'> returned a result with an error set",
      "\nThe above exception was the direct cause of the following exception:\n",
      "\u001b[1;31mSystemError\u001b[0m                               Traceback (most recent call last)",
      "\u001b[1;32m~\\Anaconda3\\lib\\site-packages\\theano\\scalar\\basic.py\u001b[0m in \u001b[0;36mimpl\u001b[1;34m(self, *inputs)\u001b[0m\n\u001b[0;32m   4022\u001b[0m     \u001b[1;32mdef\u001b[0m \u001b[0mimpl\u001b[0m\u001b[1;33m(\u001b[0m\u001b[0mself\u001b[0m\u001b[1;33m,\u001b[0m \u001b[1;33m*\u001b[0m\u001b[0minputs\u001b[0m\u001b[1;33m)\u001b[0m\u001b[1;33m:\u001b[0m\u001b[1;33m\u001b[0m\u001b[0m\n\u001b[1;32m-> 4023\u001b[1;33m         \u001b[0moutput_storage\u001b[0m \u001b[1;33m=\u001b[0m \u001b[1;33m[\u001b[0m\u001b[1;33m[\u001b[0m\u001b[1;32mNone\u001b[0m\u001b[1;33m]\u001b[0m \u001b[1;32mfor\u001b[0m \u001b[0mi\u001b[0m \u001b[1;32min\u001b[0m \u001b[0mxrange\u001b[0m\u001b[1;33m(\u001b[0m\u001b[0mself\u001b[0m\u001b[1;33m.\u001b[0m\u001b[0mnout\u001b[0m\u001b[1;33m)\u001b[0m\u001b[1;33m]\u001b[0m\u001b[1;33m\u001b[0m\u001b[0m\n\u001b[0m\u001b[0;32m   4024\u001b[0m         \u001b[0mself\u001b[0m\u001b[1;33m.\u001b[0m\u001b[0mperform\u001b[0m\u001b[1;33m(\u001b[0m\u001b[1;32mNone\u001b[0m\u001b[1;33m,\u001b[0m \u001b[0minputs\u001b[0m\u001b[1;33m,\u001b[0m \u001b[0moutput_storage\u001b[0m\u001b[1;33m)\u001b[0m\u001b[1;33m\u001b[0m\u001b[0m\n",
      "\u001b[1;31mSystemError\u001b[0m: <class 'range'> returned a result with an error set",
      "\nThe above exception was the direct cause of the following exception:\n",
      "\u001b[1;31mSystemError\u001b[0m                               Traceback (most recent call last)",
      "\u001b[1;32m~\\Anaconda3\\lib\\site-packages\\theano\\scalar\\basic.py\u001b[0m in \u001b[0;36mimpl\u001b[1;34m(self, *inputs)\u001b[0m\n\u001b[0;32m   4022\u001b[0m     \u001b[1;32mdef\u001b[0m \u001b[0mimpl\u001b[0m\u001b[1;33m(\u001b[0m\u001b[0mself\u001b[0m\u001b[1;33m,\u001b[0m \u001b[1;33m*\u001b[0m\u001b[0minputs\u001b[0m\u001b[1;33m)\u001b[0m\u001b[1;33m:\u001b[0m\u001b[1;33m\u001b[0m\u001b[0m\n\u001b[1;32m-> 4023\u001b[1;33m         \u001b[0moutput_storage\u001b[0m \u001b[1;33m=\u001b[0m \u001b[1;33m[\u001b[0m\u001b[1;33m[\u001b[0m\u001b[1;32mNone\u001b[0m\u001b[1;33m]\u001b[0m \u001b[1;32mfor\u001b[0m \u001b[0mi\u001b[0m \u001b[1;32min\u001b[0m \u001b[0mxrange\u001b[0m\u001b[1;33m(\u001b[0m\u001b[0mself\u001b[0m\u001b[1;33m.\u001b[0m\u001b[0mnout\u001b[0m\u001b[1;33m)\u001b[0m\u001b[1;33m]\u001b[0m\u001b[1;33m\u001b[0m\u001b[0m\n\u001b[0m\u001b[0;32m   4024\u001b[0m         \u001b[0mself\u001b[0m\u001b[1;33m.\u001b[0m\u001b[0mperform\u001b[0m\u001b[1;33m(\u001b[0m\u001b[1;32mNone\u001b[0m\u001b[1;33m,\u001b[0m \u001b[0minputs\u001b[0m\u001b[1;33m,\u001b[0m \u001b[0moutput_storage\u001b[0m\u001b[1;33m)\u001b[0m\u001b[1;33m\u001b[0m\u001b[0m\n",
      "\u001b[1;31mSystemError\u001b[0m: <class 'range'> returned a result with an error set",
      "\nThe above exception was the direct cause of the following exception:\n",
      "\u001b[1;31mSystemError\u001b[0m                               Traceback (most recent call last)",
      "\u001b[1;32m~\\Anaconda3\\lib\\site-packages\\theano\\scalar\\basic.py\u001b[0m in \u001b[0;36mimpl\u001b[1;34m(self, *inputs)\u001b[0m\n\u001b[0;32m   4022\u001b[0m     \u001b[1;32mdef\u001b[0m \u001b[0mimpl\u001b[0m\u001b[1;33m(\u001b[0m\u001b[0mself\u001b[0m\u001b[1;33m,\u001b[0m \u001b[1;33m*\u001b[0m\u001b[0minputs\u001b[0m\u001b[1;33m)\u001b[0m\u001b[1;33m:\u001b[0m\u001b[1;33m\u001b[0m\u001b[0m\n\u001b[1;32m-> 4023\u001b[1;33m         \u001b[0moutput_storage\u001b[0m \u001b[1;33m=\u001b[0m \u001b[1;33m[\u001b[0m\u001b[1;33m[\u001b[0m\u001b[1;32mNone\u001b[0m\u001b[1;33m]\u001b[0m \u001b[1;32mfor\u001b[0m \u001b[0mi\u001b[0m \u001b[1;32min\u001b[0m \u001b[0mxrange\u001b[0m\u001b[1;33m(\u001b[0m\u001b[0mself\u001b[0m\u001b[1;33m.\u001b[0m\u001b[0mnout\u001b[0m\u001b[1;33m)\u001b[0m\u001b[1;33m]\u001b[0m\u001b[1;33m\u001b[0m\u001b[0m\n\u001b[0m\u001b[0;32m   4024\u001b[0m         \u001b[0mself\u001b[0m\u001b[1;33m.\u001b[0m\u001b[0mperform\u001b[0m\u001b[1;33m(\u001b[0m\u001b[1;32mNone\u001b[0m\u001b[1;33m,\u001b[0m \u001b[0minputs\u001b[0m\u001b[1;33m,\u001b[0m \u001b[0moutput_storage\u001b[0m\u001b[1;33m)\u001b[0m\u001b[1;33m\u001b[0m\u001b[0m\n",
      "\u001b[1;31mSystemError\u001b[0m: <class 'range'> returned a result with an error set",
      "\nThe above exception was the direct cause of the following exception:\n",
      "\u001b[1;31mSystemError\u001b[0m                               Traceback (most recent call last)",
      "\u001b[1;32m~\\Anaconda3\\lib\\site-packages\\theano\\scalar\\basic.py\u001b[0m in \u001b[0;36mimpl\u001b[1;34m(self, *inputs)\u001b[0m\n\u001b[0;32m   4022\u001b[0m     \u001b[1;32mdef\u001b[0m \u001b[0mimpl\u001b[0m\u001b[1;33m(\u001b[0m\u001b[0mself\u001b[0m\u001b[1;33m,\u001b[0m \u001b[1;33m*\u001b[0m\u001b[0minputs\u001b[0m\u001b[1;33m)\u001b[0m\u001b[1;33m:\u001b[0m\u001b[1;33m\u001b[0m\u001b[0m\n\u001b[1;32m-> 4023\u001b[1;33m         \u001b[0moutput_storage\u001b[0m \u001b[1;33m=\u001b[0m \u001b[1;33m[\u001b[0m\u001b[1;33m[\u001b[0m\u001b[1;32mNone\u001b[0m\u001b[1;33m]\u001b[0m \u001b[1;32mfor\u001b[0m \u001b[0mi\u001b[0m \u001b[1;32min\u001b[0m \u001b[0mxrange\u001b[0m\u001b[1;33m(\u001b[0m\u001b[0mself\u001b[0m\u001b[1;33m.\u001b[0m\u001b[0mnout\u001b[0m\u001b[1;33m)\u001b[0m\u001b[1;33m]\u001b[0m\u001b[1;33m\u001b[0m\u001b[0m\n\u001b[0m\u001b[0;32m   4024\u001b[0m         \u001b[0mself\u001b[0m\u001b[1;33m.\u001b[0m\u001b[0mperform\u001b[0m\u001b[1;33m(\u001b[0m\u001b[1;32mNone\u001b[0m\u001b[1;33m,\u001b[0m \u001b[0minputs\u001b[0m\u001b[1;33m,\u001b[0m \u001b[0moutput_storage\u001b[0m\u001b[1;33m)\u001b[0m\u001b[1;33m\u001b[0m\u001b[0m\n",
      "\u001b[1;31mSystemError\u001b[0m: <class 'range'> returned a result with an error set",
      "\nThe above exception was the direct cause of the following exception:\n",
      "\u001b[1;31mSystemError\u001b[0m                               Traceback (most recent call last)",
      "\u001b[1;32m~\\Anaconda3\\lib\\site-packages\\theano\\scalar\\basic.py\u001b[0m in \u001b[0;36mimpl\u001b[1;34m(self, *inputs)\u001b[0m\n\u001b[0;32m   4022\u001b[0m     \u001b[1;32mdef\u001b[0m \u001b[0mimpl\u001b[0m\u001b[1;33m(\u001b[0m\u001b[0mself\u001b[0m\u001b[1;33m,\u001b[0m \u001b[1;33m*\u001b[0m\u001b[0minputs\u001b[0m\u001b[1;33m)\u001b[0m\u001b[1;33m:\u001b[0m\u001b[1;33m\u001b[0m\u001b[0m\n\u001b[1;32m-> 4023\u001b[1;33m         \u001b[0moutput_storage\u001b[0m \u001b[1;33m=\u001b[0m \u001b[1;33m[\u001b[0m\u001b[1;33m[\u001b[0m\u001b[1;32mNone\u001b[0m\u001b[1;33m]\u001b[0m \u001b[1;32mfor\u001b[0m \u001b[0mi\u001b[0m \u001b[1;32min\u001b[0m \u001b[0mxrange\u001b[0m\u001b[1;33m(\u001b[0m\u001b[0mself\u001b[0m\u001b[1;33m.\u001b[0m\u001b[0mnout\u001b[0m\u001b[1;33m)\u001b[0m\u001b[1;33m]\u001b[0m\u001b[1;33m\u001b[0m\u001b[0m\n\u001b[0m\u001b[0;32m   4024\u001b[0m         \u001b[0mself\u001b[0m\u001b[1;33m.\u001b[0m\u001b[0mperform\u001b[0m\u001b[1;33m(\u001b[0m\u001b[1;32mNone\u001b[0m\u001b[1;33m,\u001b[0m \u001b[0minputs\u001b[0m\u001b[1;33m,\u001b[0m \u001b[0moutput_storage\u001b[0m\u001b[1;33m)\u001b[0m\u001b[1;33m\u001b[0m\u001b[0m\n",
      "\u001b[1;31mSystemError\u001b[0m: <class 'range'> returned a result with an error set",
      "\nThe above exception was the direct cause of the following exception:\n",
      "\u001b[1;31mSystemError\u001b[0m                               Traceback (most recent call last)",
      "\u001b[1;32m~\\Anaconda3\\lib\\site-packages\\theano\\scalar\\basic.py\u001b[0m in \u001b[0;36mimpl\u001b[1;34m(self, *inputs)\u001b[0m\n\u001b[0;32m   4022\u001b[0m     \u001b[1;32mdef\u001b[0m \u001b[0mimpl\u001b[0m\u001b[1;33m(\u001b[0m\u001b[0mself\u001b[0m\u001b[1;33m,\u001b[0m \u001b[1;33m*\u001b[0m\u001b[0minputs\u001b[0m\u001b[1;33m)\u001b[0m\u001b[1;33m:\u001b[0m\u001b[1;33m\u001b[0m\u001b[0m\n\u001b[1;32m-> 4023\u001b[1;33m         \u001b[0moutput_storage\u001b[0m \u001b[1;33m=\u001b[0m \u001b[1;33m[\u001b[0m\u001b[1;33m[\u001b[0m\u001b[1;32mNone\u001b[0m\u001b[1;33m]\u001b[0m \u001b[1;32mfor\u001b[0m \u001b[0mi\u001b[0m \u001b[1;32min\u001b[0m \u001b[0mxrange\u001b[0m\u001b[1;33m(\u001b[0m\u001b[0mself\u001b[0m\u001b[1;33m.\u001b[0m\u001b[0mnout\u001b[0m\u001b[1;33m)\u001b[0m\u001b[1;33m]\u001b[0m\u001b[1;33m\u001b[0m\u001b[0m\n\u001b[0m\u001b[0;32m   4024\u001b[0m         \u001b[0mself\u001b[0m\u001b[1;33m.\u001b[0m\u001b[0mperform\u001b[0m\u001b[1;33m(\u001b[0m\u001b[1;32mNone\u001b[0m\u001b[1;33m,\u001b[0m \u001b[0minputs\u001b[0m\u001b[1;33m,\u001b[0m \u001b[0moutput_storage\u001b[0m\u001b[1;33m)\u001b[0m\u001b[1;33m\u001b[0m\u001b[0m\n",
      "\u001b[1;31mSystemError\u001b[0m: <class 'range'> returned a result with an error set",
      "\nThe above exception was the direct cause of the following exception:\n",
      "\u001b[1;31mSystemError\u001b[0m                               Traceback (most recent call last)",
      "\u001b[1;32m~\\Anaconda3\\lib\\site-packages\\theano\\scalar\\basic.py\u001b[0m in \u001b[0;36mimpl\u001b[1;34m(self, *inputs)\u001b[0m\n\u001b[0;32m   4022\u001b[0m     \u001b[1;32mdef\u001b[0m \u001b[0mimpl\u001b[0m\u001b[1;33m(\u001b[0m\u001b[0mself\u001b[0m\u001b[1;33m,\u001b[0m \u001b[1;33m*\u001b[0m\u001b[0minputs\u001b[0m\u001b[1;33m)\u001b[0m\u001b[1;33m:\u001b[0m\u001b[1;33m\u001b[0m\u001b[0m\n\u001b[1;32m-> 4023\u001b[1;33m         \u001b[0moutput_storage\u001b[0m \u001b[1;33m=\u001b[0m \u001b[1;33m[\u001b[0m\u001b[1;33m[\u001b[0m\u001b[1;32mNone\u001b[0m\u001b[1;33m]\u001b[0m \u001b[1;32mfor\u001b[0m \u001b[0mi\u001b[0m \u001b[1;32min\u001b[0m \u001b[0mxrange\u001b[0m\u001b[1;33m(\u001b[0m\u001b[0mself\u001b[0m\u001b[1;33m.\u001b[0m\u001b[0mnout\u001b[0m\u001b[1;33m)\u001b[0m\u001b[1;33m]\u001b[0m\u001b[1;33m\u001b[0m\u001b[0m\n\u001b[0m\u001b[0;32m   4024\u001b[0m         \u001b[0mself\u001b[0m\u001b[1;33m.\u001b[0m\u001b[0mperform\u001b[0m\u001b[1;33m(\u001b[0m\u001b[1;32mNone\u001b[0m\u001b[1;33m,\u001b[0m \u001b[0minputs\u001b[0m\u001b[1;33m,\u001b[0m \u001b[0moutput_storage\u001b[0m\u001b[1;33m)\u001b[0m\u001b[1;33m\u001b[0m\u001b[0m\n",
      "\u001b[1;31mSystemError\u001b[0m: <class 'range'> returned a result with an error set",
      "\nThe above exception was the direct cause of the following exception:\n",
      "\u001b[1;31mSystemError\u001b[0m                               Traceback (most recent call last)",
      "\u001b[1;32m~\\Anaconda3\\lib\\site-packages\\theano\\scalar\\basic.py\u001b[0m in \u001b[0;36mimpl\u001b[1;34m(self, *inputs)\u001b[0m\n\u001b[0;32m   4022\u001b[0m     \u001b[1;32mdef\u001b[0m \u001b[0mimpl\u001b[0m\u001b[1;33m(\u001b[0m\u001b[0mself\u001b[0m\u001b[1;33m,\u001b[0m \u001b[1;33m*\u001b[0m\u001b[0minputs\u001b[0m\u001b[1;33m)\u001b[0m\u001b[1;33m:\u001b[0m\u001b[1;33m\u001b[0m\u001b[0m\n\u001b[1;32m-> 4023\u001b[1;33m         \u001b[0moutput_storage\u001b[0m \u001b[1;33m=\u001b[0m \u001b[1;33m[\u001b[0m\u001b[1;33m[\u001b[0m\u001b[1;32mNone\u001b[0m\u001b[1;33m]\u001b[0m \u001b[1;32mfor\u001b[0m \u001b[0mi\u001b[0m \u001b[1;32min\u001b[0m \u001b[0mxrange\u001b[0m\u001b[1;33m(\u001b[0m\u001b[0mself\u001b[0m\u001b[1;33m.\u001b[0m\u001b[0mnout\u001b[0m\u001b[1;33m)\u001b[0m\u001b[1;33m]\u001b[0m\u001b[1;33m\u001b[0m\u001b[0m\n\u001b[0m\u001b[0;32m   4024\u001b[0m         \u001b[0mself\u001b[0m\u001b[1;33m.\u001b[0m\u001b[0mperform\u001b[0m\u001b[1;33m(\u001b[0m\u001b[1;32mNone\u001b[0m\u001b[1;33m,\u001b[0m \u001b[0minputs\u001b[0m\u001b[1;33m,\u001b[0m \u001b[0moutput_storage\u001b[0m\u001b[1;33m)\u001b[0m\u001b[1;33m\u001b[0m\u001b[0m\n",
      "\u001b[1;31mSystemError\u001b[0m: <class 'range'> returned a result with an error set",
      "\nThe above exception was the direct cause of the following exception:\n",
      "\u001b[1;31mSystemError\u001b[0m                               Traceback (most recent call last)",
      "\u001b[1;32m~\\Anaconda3\\lib\\site-packages\\theano\\scalar\\basic.py\u001b[0m in \u001b[0;36mimpl\u001b[1;34m(self, *inputs)\u001b[0m\n\u001b[0;32m   4022\u001b[0m     \u001b[1;32mdef\u001b[0m \u001b[0mimpl\u001b[0m\u001b[1;33m(\u001b[0m\u001b[0mself\u001b[0m\u001b[1;33m,\u001b[0m \u001b[1;33m*\u001b[0m\u001b[0minputs\u001b[0m\u001b[1;33m)\u001b[0m\u001b[1;33m:\u001b[0m\u001b[1;33m\u001b[0m\u001b[0m\n\u001b[1;32m-> 4023\u001b[1;33m         \u001b[0moutput_storage\u001b[0m \u001b[1;33m=\u001b[0m \u001b[1;33m[\u001b[0m\u001b[1;33m[\u001b[0m\u001b[1;32mNone\u001b[0m\u001b[1;33m]\u001b[0m \u001b[1;32mfor\u001b[0m \u001b[0mi\u001b[0m \u001b[1;32min\u001b[0m \u001b[0mxrange\u001b[0m\u001b[1;33m(\u001b[0m\u001b[0mself\u001b[0m\u001b[1;33m.\u001b[0m\u001b[0mnout\u001b[0m\u001b[1;33m)\u001b[0m\u001b[1;33m]\u001b[0m\u001b[1;33m\u001b[0m\u001b[0m\n\u001b[0m\u001b[0;32m   4024\u001b[0m         \u001b[0mself\u001b[0m\u001b[1;33m.\u001b[0m\u001b[0mperform\u001b[0m\u001b[1;33m(\u001b[0m\u001b[1;32mNone\u001b[0m\u001b[1;33m,\u001b[0m \u001b[0minputs\u001b[0m\u001b[1;33m,\u001b[0m \u001b[0moutput_storage\u001b[0m\u001b[1;33m)\u001b[0m\u001b[1;33m\u001b[0m\u001b[0m\n",
      "\u001b[1;31mSystemError\u001b[0m: <class 'range'> returned a result with an error set",
      "\nThe above exception was the direct cause of the following exception:\n",
      "\u001b[1;31mSystemError\u001b[0m                               Traceback (most recent call last)",
      "\u001b[1;32m~\\Anaconda3\\lib\\site-packages\\theano\\scalar\\basic.py\u001b[0m in \u001b[0;36mimpl\u001b[1;34m(self, *inputs)\u001b[0m\n\u001b[0;32m   4022\u001b[0m     \u001b[1;32mdef\u001b[0m \u001b[0mimpl\u001b[0m\u001b[1;33m(\u001b[0m\u001b[0mself\u001b[0m\u001b[1;33m,\u001b[0m \u001b[1;33m*\u001b[0m\u001b[0minputs\u001b[0m\u001b[1;33m)\u001b[0m\u001b[1;33m:\u001b[0m\u001b[1;33m\u001b[0m\u001b[0m\n\u001b[1;32m-> 4023\u001b[1;33m         \u001b[0moutput_storage\u001b[0m \u001b[1;33m=\u001b[0m \u001b[1;33m[\u001b[0m\u001b[1;33m[\u001b[0m\u001b[1;32mNone\u001b[0m\u001b[1;33m]\u001b[0m \u001b[1;32mfor\u001b[0m \u001b[0mi\u001b[0m \u001b[1;32min\u001b[0m \u001b[0mxrange\u001b[0m\u001b[1;33m(\u001b[0m\u001b[0mself\u001b[0m\u001b[1;33m.\u001b[0m\u001b[0mnout\u001b[0m\u001b[1;33m)\u001b[0m\u001b[1;33m]\u001b[0m\u001b[1;33m\u001b[0m\u001b[0m\n\u001b[0m\u001b[0;32m   4024\u001b[0m         \u001b[0mself\u001b[0m\u001b[1;33m.\u001b[0m\u001b[0mperform\u001b[0m\u001b[1;33m(\u001b[0m\u001b[1;32mNone\u001b[0m\u001b[1;33m,\u001b[0m \u001b[0minputs\u001b[0m\u001b[1;33m,\u001b[0m \u001b[0moutput_storage\u001b[0m\u001b[1;33m)\u001b[0m\u001b[1;33m\u001b[0m\u001b[0m\n",
      "\u001b[1;31mSystemError\u001b[0m: <class 'range'> returned a result with an error set",
      "\nThe above exception was the direct cause of the following exception:\n",
      "\u001b[1;31mSystemError\u001b[0m                               Traceback (most recent call last)",
      "\u001b[1;32m~\\Anaconda3\\lib\\site-packages\\theano\\scalar\\basic.py\u001b[0m in \u001b[0;36mimpl\u001b[1;34m(self, *inputs)\u001b[0m\n\u001b[0;32m   4022\u001b[0m     \u001b[1;32mdef\u001b[0m \u001b[0mimpl\u001b[0m\u001b[1;33m(\u001b[0m\u001b[0mself\u001b[0m\u001b[1;33m,\u001b[0m \u001b[1;33m*\u001b[0m\u001b[0minputs\u001b[0m\u001b[1;33m)\u001b[0m\u001b[1;33m:\u001b[0m\u001b[1;33m\u001b[0m\u001b[0m\n\u001b[1;32m-> 4023\u001b[1;33m         \u001b[0moutput_storage\u001b[0m \u001b[1;33m=\u001b[0m \u001b[1;33m[\u001b[0m\u001b[1;33m[\u001b[0m\u001b[1;32mNone\u001b[0m\u001b[1;33m]\u001b[0m \u001b[1;32mfor\u001b[0m \u001b[0mi\u001b[0m \u001b[1;32min\u001b[0m \u001b[0mxrange\u001b[0m\u001b[1;33m(\u001b[0m\u001b[0mself\u001b[0m\u001b[1;33m.\u001b[0m\u001b[0mnout\u001b[0m\u001b[1;33m)\u001b[0m\u001b[1;33m]\u001b[0m\u001b[1;33m\u001b[0m\u001b[0m\n\u001b[0m\u001b[0;32m   4024\u001b[0m         \u001b[0mself\u001b[0m\u001b[1;33m.\u001b[0m\u001b[0mperform\u001b[0m\u001b[1;33m(\u001b[0m\u001b[1;32mNone\u001b[0m\u001b[1;33m,\u001b[0m \u001b[0minputs\u001b[0m\u001b[1;33m,\u001b[0m \u001b[0moutput_storage\u001b[0m\u001b[1;33m)\u001b[0m\u001b[1;33m\u001b[0m\u001b[0m\n",
      "\u001b[1;31mSystemError\u001b[0m: <class 'range'> returned a result with an error set",
      "\nThe above exception was the direct cause of the following exception:\n",
      "\u001b[1;31mSystemError\u001b[0m                               Traceback (most recent call last)",
      "\u001b[1;32m~\\Anaconda3\\lib\\site-packages\\theano\\scalar\\basic.py\u001b[0m in \u001b[0;36mimpl\u001b[1;34m(self, *inputs)\u001b[0m\n\u001b[0;32m   4022\u001b[0m     \u001b[1;32mdef\u001b[0m \u001b[0mimpl\u001b[0m\u001b[1;33m(\u001b[0m\u001b[0mself\u001b[0m\u001b[1;33m,\u001b[0m \u001b[1;33m*\u001b[0m\u001b[0minputs\u001b[0m\u001b[1;33m)\u001b[0m\u001b[1;33m:\u001b[0m\u001b[1;33m\u001b[0m\u001b[0m\n\u001b[1;32m-> 4023\u001b[1;33m         \u001b[0moutput_storage\u001b[0m \u001b[1;33m=\u001b[0m \u001b[1;33m[\u001b[0m\u001b[1;33m[\u001b[0m\u001b[1;32mNone\u001b[0m\u001b[1;33m]\u001b[0m \u001b[1;32mfor\u001b[0m \u001b[0mi\u001b[0m \u001b[1;32min\u001b[0m \u001b[0mxrange\u001b[0m\u001b[1;33m(\u001b[0m\u001b[0mself\u001b[0m\u001b[1;33m.\u001b[0m\u001b[0mnout\u001b[0m\u001b[1;33m)\u001b[0m\u001b[1;33m]\u001b[0m\u001b[1;33m\u001b[0m\u001b[0m\n\u001b[0m\u001b[0;32m   4024\u001b[0m         \u001b[0mself\u001b[0m\u001b[1;33m.\u001b[0m\u001b[0mperform\u001b[0m\u001b[1;33m(\u001b[0m\u001b[1;32mNone\u001b[0m\u001b[1;33m,\u001b[0m \u001b[0minputs\u001b[0m\u001b[1;33m,\u001b[0m \u001b[0moutput_storage\u001b[0m\u001b[1;33m)\u001b[0m\u001b[1;33m\u001b[0m\u001b[0m\n",
      "\u001b[1;31mSystemError\u001b[0m: <class 'range'> returned a result with an error set",
      "\nThe above exception was the direct cause of the following exception:\n",
      "\u001b[1;31mSystemError\u001b[0m                               Traceback (most recent call last)",
      "\u001b[1;32m~\\Anaconda3\\lib\\site-packages\\theano\\scalar\\basic.py\u001b[0m in \u001b[0;36mimpl\u001b[1;34m(self, *inputs)\u001b[0m\n\u001b[0;32m   4022\u001b[0m     \u001b[1;32mdef\u001b[0m \u001b[0mimpl\u001b[0m\u001b[1;33m(\u001b[0m\u001b[0mself\u001b[0m\u001b[1;33m,\u001b[0m \u001b[1;33m*\u001b[0m\u001b[0minputs\u001b[0m\u001b[1;33m)\u001b[0m\u001b[1;33m:\u001b[0m\u001b[1;33m\u001b[0m\u001b[0m\n\u001b[1;32m-> 4023\u001b[1;33m         \u001b[0moutput_storage\u001b[0m \u001b[1;33m=\u001b[0m \u001b[1;33m[\u001b[0m\u001b[1;33m[\u001b[0m\u001b[1;32mNone\u001b[0m\u001b[1;33m]\u001b[0m \u001b[1;32mfor\u001b[0m \u001b[0mi\u001b[0m \u001b[1;32min\u001b[0m \u001b[0mxrange\u001b[0m\u001b[1;33m(\u001b[0m\u001b[0mself\u001b[0m\u001b[1;33m.\u001b[0m\u001b[0mnout\u001b[0m\u001b[1;33m)\u001b[0m\u001b[1;33m]\u001b[0m\u001b[1;33m\u001b[0m\u001b[0m\n\u001b[0m\u001b[0;32m   4024\u001b[0m         \u001b[0mself\u001b[0m\u001b[1;33m.\u001b[0m\u001b[0mperform\u001b[0m\u001b[1;33m(\u001b[0m\u001b[1;32mNone\u001b[0m\u001b[1;33m,\u001b[0m \u001b[0minputs\u001b[0m\u001b[1;33m,\u001b[0m \u001b[0moutput_storage\u001b[0m\u001b[1;33m)\u001b[0m\u001b[1;33m\u001b[0m\u001b[0m\n",
      "\u001b[1;31mSystemError\u001b[0m: <class 'range'> returned a result with an error set",
      "\nThe above exception was the direct cause of the following exception:\n",
      "\u001b[1;31mSystemError\u001b[0m                               Traceback (most recent call last)",
      "\u001b[1;32m~\\Anaconda3\\lib\\site-packages\\theano\\scalar\\basic.py\u001b[0m in \u001b[0;36mimpl\u001b[1;34m(self, *inputs)\u001b[0m\n\u001b[0;32m   4022\u001b[0m     \u001b[1;32mdef\u001b[0m \u001b[0mimpl\u001b[0m\u001b[1;33m(\u001b[0m\u001b[0mself\u001b[0m\u001b[1;33m,\u001b[0m \u001b[1;33m*\u001b[0m\u001b[0minputs\u001b[0m\u001b[1;33m)\u001b[0m\u001b[1;33m:\u001b[0m\u001b[1;33m\u001b[0m\u001b[0m\n\u001b[1;32m-> 4023\u001b[1;33m         \u001b[0moutput_storage\u001b[0m \u001b[1;33m=\u001b[0m \u001b[1;33m[\u001b[0m\u001b[1;33m[\u001b[0m\u001b[1;32mNone\u001b[0m\u001b[1;33m]\u001b[0m \u001b[1;32mfor\u001b[0m \u001b[0mi\u001b[0m \u001b[1;32min\u001b[0m \u001b[0mxrange\u001b[0m\u001b[1;33m(\u001b[0m\u001b[0mself\u001b[0m\u001b[1;33m.\u001b[0m\u001b[0mnout\u001b[0m\u001b[1;33m)\u001b[0m\u001b[1;33m]\u001b[0m\u001b[1;33m\u001b[0m\u001b[0m\n\u001b[0m\u001b[0;32m   4024\u001b[0m         \u001b[0mself\u001b[0m\u001b[1;33m.\u001b[0m\u001b[0mperform\u001b[0m\u001b[1;33m(\u001b[0m\u001b[1;32mNone\u001b[0m\u001b[1;33m,\u001b[0m \u001b[0minputs\u001b[0m\u001b[1;33m,\u001b[0m \u001b[0moutput_storage\u001b[0m\u001b[1;33m)\u001b[0m\u001b[1;33m\u001b[0m\u001b[0m\n",
      "\u001b[1;31mSystemError\u001b[0m: <class 'range'> returned a result with an error set",
      "\nThe above exception was the direct cause of the following exception:\n",
      "\u001b[1;31mSystemError\u001b[0m                               Traceback (most recent call last)",
      "\u001b[1;32m~\\Anaconda3\\lib\\site-packages\\theano\\scalar\\basic.py\u001b[0m in \u001b[0;36mimpl\u001b[1;34m(self, *inputs)\u001b[0m\n\u001b[0;32m   4022\u001b[0m     \u001b[1;32mdef\u001b[0m \u001b[0mimpl\u001b[0m\u001b[1;33m(\u001b[0m\u001b[0mself\u001b[0m\u001b[1;33m,\u001b[0m \u001b[1;33m*\u001b[0m\u001b[0minputs\u001b[0m\u001b[1;33m)\u001b[0m\u001b[1;33m:\u001b[0m\u001b[1;33m\u001b[0m\u001b[0m\n\u001b[1;32m-> 4023\u001b[1;33m         \u001b[0moutput_storage\u001b[0m \u001b[1;33m=\u001b[0m \u001b[1;33m[\u001b[0m\u001b[1;33m[\u001b[0m\u001b[1;32mNone\u001b[0m\u001b[1;33m]\u001b[0m \u001b[1;32mfor\u001b[0m \u001b[0mi\u001b[0m \u001b[1;32min\u001b[0m \u001b[0mxrange\u001b[0m\u001b[1;33m(\u001b[0m\u001b[0mself\u001b[0m\u001b[1;33m.\u001b[0m\u001b[0mnout\u001b[0m\u001b[1;33m)\u001b[0m\u001b[1;33m]\u001b[0m\u001b[1;33m\u001b[0m\u001b[0m\n\u001b[0m\u001b[0;32m   4024\u001b[0m         \u001b[0mself\u001b[0m\u001b[1;33m.\u001b[0m\u001b[0mperform\u001b[0m\u001b[1;33m(\u001b[0m\u001b[1;32mNone\u001b[0m\u001b[1;33m,\u001b[0m \u001b[0minputs\u001b[0m\u001b[1;33m,\u001b[0m \u001b[0moutput_storage\u001b[0m\u001b[1;33m)\u001b[0m\u001b[1;33m\u001b[0m\u001b[0m\n",
      "\u001b[1;31mSystemError\u001b[0m: <class 'range'> returned a result with an error set",
      "\nThe above exception was the direct cause of the following exception:\n",
      "\u001b[1;31mSystemError\u001b[0m                               Traceback (most recent call last)",
      "\u001b[1;32m~\\Anaconda3\\lib\\site-packages\\theano\\scalar\\basic.py\u001b[0m in \u001b[0;36mimpl\u001b[1;34m(self, *inputs)\u001b[0m\n\u001b[0;32m   4022\u001b[0m     \u001b[1;32mdef\u001b[0m \u001b[0mimpl\u001b[0m\u001b[1;33m(\u001b[0m\u001b[0mself\u001b[0m\u001b[1;33m,\u001b[0m \u001b[1;33m*\u001b[0m\u001b[0minputs\u001b[0m\u001b[1;33m)\u001b[0m\u001b[1;33m:\u001b[0m\u001b[1;33m\u001b[0m\u001b[0m\n\u001b[1;32m-> 4023\u001b[1;33m         \u001b[0moutput_storage\u001b[0m \u001b[1;33m=\u001b[0m \u001b[1;33m[\u001b[0m\u001b[1;33m[\u001b[0m\u001b[1;32mNone\u001b[0m\u001b[1;33m]\u001b[0m \u001b[1;32mfor\u001b[0m \u001b[0mi\u001b[0m \u001b[1;32min\u001b[0m \u001b[0mxrange\u001b[0m\u001b[1;33m(\u001b[0m\u001b[0mself\u001b[0m\u001b[1;33m.\u001b[0m\u001b[0mnout\u001b[0m\u001b[1;33m)\u001b[0m\u001b[1;33m]\u001b[0m\u001b[1;33m\u001b[0m\u001b[0m\n\u001b[0m\u001b[0;32m   4024\u001b[0m         \u001b[0mself\u001b[0m\u001b[1;33m.\u001b[0m\u001b[0mperform\u001b[0m\u001b[1;33m(\u001b[0m\u001b[1;32mNone\u001b[0m\u001b[1;33m,\u001b[0m \u001b[0minputs\u001b[0m\u001b[1;33m,\u001b[0m \u001b[0moutput_storage\u001b[0m\u001b[1;33m)\u001b[0m\u001b[1;33m\u001b[0m\u001b[0m\n",
      "\u001b[1;31mSystemError\u001b[0m: <class 'range'> returned a result with an error set",
      "\nThe above exception was the direct cause of the following exception:\n",
      "\u001b[1;31mSystemError\u001b[0m                               Traceback (most recent call last)",
      "\u001b[1;32m~\\Anaconda3\\lib\\site-packages\\theano\\gof\\vm.py\u001b[0m in \u001b[0;36m__call__\u001b[1;34m(self)\u001b[0m\n\u001b[0;32m    299\u001b[0m                                                     self.post_thunk_clear):\n\u001b[1;32m--> 300\u001b[1;33m                     \u001b[0mthunk\u001b[0m\u001b[1;33m(\u001b[0m\u001b[1;33m)\u001b[0m\u001b[1;33m\u001b[0m\u001b[0m\n\u001b[0m\u001b[0;32m    301\u001b[0m                     \u001b[1;32mfor\u001b[0m \u001b[0mold_s\u001b[0m \u001b[1;32min\u001b[0m \u001b[0mold_storage\u001b[0m\u001b[1;33m:\u001b[0m\u001b[1;33m\u001b[0m\u001b[0m\n",
      "\u001b[1;32m~\\Anaconda3\\lib\\site-packages\\theano\\gof\\op.py\u001b[0m in \u001b[0;36mrval\u001b[1;34m(p, i, o, n)\u001b[0m\n\u001b[0;32m    891\u001b[0m             \u001b[1;32mdef\u001b[0m \u001b[0mrval\u001b[0m\u001b[1;33m(\u001b[0m\u001b[0mp\u001b[0m\u001b[1;33m=\u001b[0m\u001b[0mp\u001b[0m\u001b[1;33m,\u001b[0m \u001b[0mi\u001b[0m\u001b[1;33m=\u001b[0m\u001b[0mnode_input_storage\u001b[0m\u001b[1;33m,\u001b[0m \u001b[0mo\u001b[0m\u001b[1;33m=\u001b[0m\u001b[0mnode_output_storage\u001b[0m\u001b[1;33m,\u001b[0m \u001b[0mn\u001b[0m\u001b[1;33m=\u001b[0m\u001b[0mnode\u001b[0m\u001b[1;33m)\u001b[0m\u001b[1;33m:\u001b[0m\u001b[1;33m\u001b[0m\u001b[0m\n\u001b[1;32m--> 892\u001b[1;33m                 \u001b[0mr\u001b[0m \u001b[1;33m=\u001b[0m \u001b[0mp\u001b[0m\u001b[1;33m(\u001b[0m\u001b[0mn\u001b[0m\u001b[1;33m,\u001b[0m \u001b[1;33m[\u001b[0m\u001b[0mx\u001b[0m\u001b[1;33m[\u001b[0m\u001b[1;36m0\u001b[0m\u001b[1;33m]\u001b[0m \u001b[1;32mfor\u001b[0m \u001b[0mx\u001b[0m \u001b[1;32min\u001b[0m \u001b[0mi\u001b[0m\u001b[1;33m]\u001b[0m\u001b[1;33m,\u001b[0m \u001b[0mo\u001b[0m\u001b[1;33m)\u001b[0m\u001b[1;33m\u001b[0m\u001b[0m\n\u001b[0m\u001b[0;32m    893\u001b[0m                 \u001b[1;32mfor\u001b[0m \u001b[0mo\u001b[0m \u001b[1;32min\u001b[0m \u001b[0mnode\u001b[0m\u001b[1;33m.\u001b[0m\u001b[0moutputs\u001b[0m\u001b[1;33m:\u001b[0m\u001b[1;33m\u001b[0m\u001b[0m\n",
      "\u001b[1;32m~\\Anaconda3\\lib\\site-packages\\theano\\tensor\\elemwise.py\u001b[0m in \u001b[0;36mperform\u001b[1;34m(self, node, inputs, output_storage)\u001b[0m\n\u001b[0;32m    789\u001b[0m \u001b[1;33m\u001b[0m\u001b[0m\n\u001b[1;32m--> 790\u001b[1;33m         \u001b[0mvariables\u001b[0m \u001b[1;33m=\u001b[0m \u001b[0mufunc\u001b[0m\u001b[1;33m(\u001b[0m\u001b[1;33m*\u001b[0m\u001b[0mufunc_args\u001b[0m\u001b[1;33m,\u001b[0m \u001b[1;33m**\u001b[0m\u001b[0mufunc_kwargs\u001b[0m\u001b[1;33m)\u001b[0m\u001b[1;33m\u001b[0m\u001b[0m\n\u001b[0m\u001b[0;32m    791\u001b[0m \u001b[1;33m\u001b[0m\u001b[0m\n",
      "\u001b[1;32m~\\Anaconda3\\lib\\site-packages\\theano\\scalar\\basic.py\u001b[0m in \u001b[0;36mimpl\u001b[1;34m(self, *inputs)\u001b[0m\n\u001b[0;32m   4022\u001b[0m     \u001b[1;32mdef\u001b[0m \u001b[0mimpl\u001b[0m\u001b[1;33m(\u001b[0m\u001b[0mself\u001b[0m\u001b[1;33m,\u001b[0m \u001b[1;33m*\u001b[0m\u001b[0minputs\u001b[0m\u001b[1;33m)\u001b[0m\u001b[1;33m:\u001b[0m\u001b[1;33m\u001b[0m\u001b[0m\n\u001b[1;32m-> 4023\u001b[1;33m         \u001b[0moutput_storage\u001b[0m \u001b[1;33m=\u001b[0m \u001b[1;33m[\u001b[0m\u001b[1;33m[\u001b[0m\u001b[1;32mNone\u001b[0m\u001b[1;33m]\u001b[0m \u001b[1;32mfor\u001b[0m \u001b[0mi\u001b[0m \u001b[1;32min\u001b[0m \u001b[0mxrange\u001b[0m\u001b[1;33m(\u001b[0m\u001b[0mself\u001b[0m\u001b[1;33m.\u001b[0m\u001b[0mnout\u001b[0m\u001b[1;33m)\u001b[0m\u001b[1;33m]\u001b[0m\u001b[1;33m\u001b[0m\u001b[0m\n\u001b[0m\u001b[0;32m   4024\u001b[0m         \u001b[0mself\u001b[0m\u001b[1;33m.\u001b[0m\u001b[0mperform\u001b[0m\u001b[1;33m(\u001b[0m\u001b[1;32mNone\u001b[0m\u001b[1;33m,\u001b[0m \u001b[0minputs\u001b[0m\u001b[1;33m,\u001b[0m \u001b[0moutput_storage\u001b[0m\u001b[1;33m)\u001b[0m\u001b[1;33m\u001b[0m\u001b[0m\n",
      "\u001b[1;31mSystemError\u001b[0m: <class 'range'> returned a result with an error set",
      "\nDuring handling of the above exception, another exception occurred:\n",
      "\u001b[1;31mSystemError\u001b[0m                               Traceback (most recent call last)",
      "\u001b[1;32m<ipython-input-5-57c655dd7a55>\u001b[0m in \u001b[0;36m<module>\u001b[1;34m()\u001b[0m\n\u001b[0;32m      1\u001b[0m \u001b[1;31m# define the 3072-1024-512-10 architecture using Keras\u001b[0m\u001b[1;33m\u001b[0m\u001b[1;33m\u001b[0m\u001b[0m\n\u001b[0;32m      2\u001b[0m \u001b[0mmodel\u001b[0m \u001b[1;33m=\u001b[0m \u001b[0mSequential\u001b[0m\u001b[1;33m(\u001b[0m\u001b[1;33m)\u001b[0m\u001b[1;33m\u001b[0m\u001b[0m\n\u001b[1;32m----> 3\u001b[1;33m \u001b[0mmodel\u001b[0m\u001b[1;33m.\u001b[0m\u001b[0madd\u001b[0m\u001b[1;33m(\u001b[0m\u001b[0mDense\u001b[0m\u001b[1;33m(\u001b[0m\u001b[1;36m1024\u001b[0m\u001b[1;33m,\u001b[0m \u001b[0minput_shape\u001b[0m\u001b[1;33m=\u001b[0m\u001b[1;33m(\u001b[0m\u001b[1;36m3072\u001b[0m\u001b[1;33m,\u001b[0m\u001b[1;33m)\u001b[0m\u001b[1;33m,\u001b[0m \u001b[0mactivation\u001b[0m\u001b[1;33m=\u001b[0m\u001b[1;34m\"relu\"\u001b[0m\u001b[1;33m)\u001b[0m\u001b[1;33m)\u001b[0m\u001b[1;33m\u001b[0m\u001b[0m\n\u001b[0m\u001b[0;32m      4\u001b[0m \u001b[0mmodel\u001b[0m\u001b[1;33m.\u001b[0m\u001b[0madd\u001b[0m\u001b[1;33m(\u001b[0m\u001b[0mDense\u001b[0m\u001b[1;33m(\u001b[0m\u001b[1;36m512\u001b[0m\u001b[1;33m,\u001b[0m \u001b[0mactivation\u001b[0m\u001b[1;33m=\u001b[0m\u001b[1;34m\"relu\"\u001b[0m\u001b[1;33m)\u001b[0m\u001b[1;33m)\u001b[0m\u001b[1;33m\u001b[0m\u001b[0m\n\u001b[0;32m      5\u001b[0m \u001b[0mmodel\u001b[0m\u001b[1;33m.\u001b[0m\u001b[0madd\u001b[0m\u001b[1;33m(\u001b[0m\u001b[0mDense\u001b[0m\u001b[1;33m(\u001b[0m\u001b[1;36m10\u001b[0m\u001b[1;33m,\u001b[0m \u001b[0mactivation\u001b[0m\u001b[1;33m=\u001b[0m\u001b[1;34m\"softmax\"\u001b[0m\u001b[1;33m)\u001b[0m\u001b[1;33m)\u001b[0m\u001b[1;33m\u001b[0m\u001b[0m\n",
      "\u001b[1;32m~\\Anaconda3\\lib\\site-packages\\keras\\models.py\u001b[0m in \u001b[0;36madd\u001b[1;34m(self, layer)\u001b[0m\n\u001b[0;32m    465\u001b[0m                 \u001b[1;31m# and create the node connecting the current layer\u001b[0m\u001b[1;33m\u001b[0m\u001b[1;33m\u001b[0m\u001b[0m\n\u001b[0;32m    466\u001b[0m                 \u001b[1;31m# to the input layer we just created.\u001b[0m\u001b[1;33m\u001b[0m\u001b[1;33m\u001b[0m\u001b[0m\n\u001b[1;32m--> 467\u001b[1;33m                 \u001b[0mlayer\u001b[0m\u001b[1;33m(\u001b[0m\u001b[0mx\u001b[0m\u001b[1;33m)\u001b[0m\u001b[1;33m\u001b[0m\u001b[0m\n\u001b[0m\u001b[0;32m    468\u001b[0m \u001b[1;33m\u001b[0m\u001b[0m\n\u001b[0;32m    469\u001b[0m             \u001b[1;32mif\u001b[0m \u001b[0mlen\u001b[0m\u001b[1;33m(\u001b[0m\u001b[0mlayer\u001b[0m\u001b[1;33m.\u001b[0m\u001b[0m_inbound_nodes\u001b[0m\u001b[1;33m[\u001b[0m\u001b[1;33m-\u001b[0m\u001b[1;36m1\u001b[0m\u001b[1;33m]\u001b[0m\u001b[1;33m.\u001b[0m\u001b[0moutput_tensors\u001b[0m\u001b[1;33m)\u001b[0m \u001b[1;33m!=\u001b[0m \u001b[1;36m1\u001b[0m\u001b[1;33m:\u001b[0m\u001b[1;33m\u001b[0m\u001b[0m\n",
      "\u001b[1;32m~\\Anaconda3\\lib\\site-packages\\keras\\engine\\topology.py\u001b[0m in \u001b[0;36m__call__\u001b[1;34m(self, inputs, **kwargs)\u001b[0m\n\u001b[0;32m    590\u001b[0m                                          '`layer.build(batch_input_shape)`')\n\u001b[0;32m    591\u001b[0m                 \u001b[1;32mif\u001b[0m \u001b[0mlen\u001b[0m\u001b[1;33m(\u001b[0m\u001b[0minput_shapes\u001b[0m\u001b[1;33m)\u001b[0m \u001b[1;33m==\u001b[0m \u001b[1;36m1\u001b[0m\u001b[1;33m:\u001b[0m\u001b[1;33m\u001b[0m\u001b[0m\n\u001b[1;32m--> 592\u001b[1;33m                     \u001b[0mself\u001b[0m\u001b[1;33m.\u001b[0m\u001b[0mbuild\u001b[0m\u001b[1;33m(\u001b[0m\u001b[0minput_shapes\u001b[0m\u001b[1;33m[\u001b[0m\u001b[1;36m0\u001b[0m\u001b[1;33m]\u001b[0m\u001b[1;33m)\u001b[0m\u001b[1;33m\u001b[0m\u001b[0m\n\u001b[0m\u001b[0;32m    593\u001b[0m                 \u001b[1;32melse\u001b[0m\u001b[1;33m:\u001b[0m\u001b[1;33m\u001b[0m\u001b[0m\n\u001b[0;32m    594\u001b[0m                     \u001b[0mself\u001b[0m\u001b[1;33m.\u001b[0m\u001b[0mbuild\u001b[0m\u001b[1;33m(\u001b[0m\u001b[0minput_shapes\u001b[0m\u001b[1;33m)\u001b[0m\u001b[1;33m\u001b[0m\u001b[0m\n",
      "\u001b[1;32m~\\Anaconda3\\lib\\site-packages\\keras\\layers\\core.py\u001b[0m in \u001b[0;36mbuild\u001b[1;34m(self, input_shape)\u001b[0m\n\u001b[0;32m    840\u001b[0m                                       \u001b[0mname\u001b[0m\u001b[1;33m=\u001b[0m\u001b[1;34m'kernel'\u001b[0m\u001b[1;33m,\u001b[0m\u001b[1;33m\u001b[0m\u001b[0m\n\u001b[0;32m    841\u001b[0m                                       \u001b[0mregularizer\u001b[0m\u001b[1;33m=\u001b[0m\u001b[0mself\u001b[0m\u001b[1;33m.\u001b[0m\u001b[0mkernel_regularizer\u001b[0m\u001b[1;33m,\u001b[0m\u001b[1;33m\u001b[0m\u001b[0m\n\u001b[1;32m--> 842\u001b[1;33m                                       constraint=self.kernel_constraint)\n\u001b[0m\u001b[0;32m    843\u001b[0m         \u001b[1;32mif\u001b[0m \u001b[0mself\u001b[0m\u001b[1;33m.\u001b[0m\u001b[0muse_bias\u001b[0m\u001b[1;33m:\u001b[0m\u001b[1;33m\u001b[0m\u001b[0m\n\u001b[0;32m    844\u001b[0m             self.bias = self.add_weight(shape=(self.units,),\n",
      "\u001b[1;32m~\\Anaconda3\\lib\\site-packages\\keras\\legacy\\interfaces.py\u001b[0m in \u001b[0;36mwrapper\u001b[1;34m(*args, **kwargs)\u001b[0m\n\u001b[0;32m     89\u001b[0m                 warnings.warn('Update your `' + object_name +\n\u001b[0;32m     90\u001b[0m                               '` call to the Keras 2 API: ' + signature, stacklevel=2)\n\u001b[1;32m---> 91\u001b[1;33m             \u001b[1;32mreturn\u001b[0m \u001b[0mfunc\u001b[0m\u001b[1;33m(\u001b[0m\u001b[1;33m*\u001b[0m\u001b[0margs\u001b[0m\u001b[1;33m,\u001b[0m \u001b[1;33m**\u001b[0m\u001b[0mkwargs\u001b[0m\u001b[1;33m)\u001b[0m\u001b[1;33m\u001b[0m\u001b[0m\n\u001b[0m\u001b[0;32m     92\u001b[0m         \u001b[0mwrapper\u001b[0m\u001b[1;33m.\u001b[0m\u001b[0m_original_function\u001b[0m \u001b[1;33m=\u001b[0m \u001b[0mfunc\u001b[0m\u001b[1;33m\u001b[0m\u001b[0m\n\u001b[0;32m     93\u001b[0m         \u001b[1;32mreturn\u001b[0m \u001b[0mwrapper\u001b[0m\u001b[1;33m\u001b[0m\u001b[0m\n",
      "\u001b[1;32m~\\Anaconda3\\lib\\site-packages\\keras\\engine\\topology.py\u001b[0m in \u001b[0;36madd_weight\u001b[1;34m(self, name, shape, dtype, initializer, regularizer, trainable, constraint)\u001b[0m\n\u001b[0;32m    414\u001b[0m                             \u001b[0mdtype\u001b[0m\u001b[1;33m=\u001b[0m\u001b[0mdtype\u001b[0m\u001b[1;33m,\u001b[0m\u001b[1;33m\u001b[0m\u001b[0m\n\u001b[0;32m    415\u001b[0m                             \u001b[0mname\u001b[0m\u001b[1;33m=\u001b[0m\u001b[0mname\u001b[0m\u001b[1;33m,\u001b[0m\u001b[1;33m\u001b[0m\u001b[0m\n\u001b[1;32m--> 416\u001b[1;33m                             constraint=constraint)\n\u001b[0m\u001b[0;32m    417\u001b[0m         \u001b[1;32mif\u001b[0m \u001b[0mregularizer\u001b[0m \u001b[1;32mis\u001b[0m \u001b[1;32mnot\u001b[0m \u001b[1;32mNone\u001b[0m\u001b[1;33m:\u001b[0m\u001b[1;33m\u001b[0m\u001b[0m\n\u001b[0;32m    418\u001b[0m             \u001b[0mself\u001b[0m\u001b[1;33m.\u001b[0m\u001b[0madd_loss\u001b[0m\u001b[1;33m(\u001b[0m\u001b[0mregularizer\u001b[0m\u001b[1;33m(\u001b[0m\u001b[0mweight\u001b[0m\u001b[1;33m)\u001b[0m\u001b[1;33m)\u001b[0m\u001b[1;33m\u001b[0m\u001b[0m\n",
      "\u001b[1;32m~\\Anaconda3\\lib\\site-packages\\keras\\backend\\theano_backend.py\u001b[0m in \u001b[0;36mvariable\u001b[1;34m(value, dtype, name, constraint)\u001b[0m\n\u001b[0;32m    148\u001b[0m                               theano.tensor.TensorConstant)):\n\u001b[0;32m    149\u001b[0m             \u001b[1;31m# Support for RandomStreams().normal(), .uniform().\u001b[0m\u001b[1;33m\u001b[0m\u001b[1;33m\u001b[0m\u001b[0m\n\u001b[1;32m--> 150\u001b[1;33m             \u001b[0mvalue\u001b[0m \u001b[1;33m=\u001b[0m \u001b[0mvalue\u001b[0m\u001b[1;33m.\u001b[0m\u001b[0meval\u001b[0m\u001b[1;33m(\u001b[0m\u001b[1;33m)\u001b[0m\u001b[1;33m\u001b[0m\u001b[0m\n\u001b[0m\u001b[0;32m    151\u001b[0m         \u001b[0mvalue\u001b[0m \u001b[1;33m=\u001b[0m \u001b[0mnp\u001b[0m\u001b[1;33m.\u001b[0m\u001b[0masarray\u001b[0m\u001b[1;33m(\u001b[0m\u001b[0mvalue\u001b[0m\u001b[1;33m,\u001b[0m \u001b[0mdtype\u001b[0m\u001b[1;33m=\u001b[0m\u001b[0mdtype\u001b[0m\u001b[1;33m)\u001b[0m\u001b[1;33m\u001b[0m\u001b[0m\n\u001b[0;32m    152\u001b[0m         variable = theano.shared(value=value,\n",
      "\u001b[1;32m~\\Anaconda3\\lib\\site-packages\\theano\\gof\\graph.py\u001b[0m in \u001b[0;36meval\u001b[1;34m(self, inputs_to_values)\u001b[0m\n\u001b[0;32m    523\u001b[0m         \u001b[0margs\u001b[0m \u001b[1;33m=\u001b[0m \u001b[1;33m[\u001b[0m\u001b[0minputs_to_values\u001b[0m\u001b[1;33m[\u001b[0m\u001b[0mparam\u001b[0m\u001b[1;33m]\u001b[0m \u001b[1;32mfor\u001b[0m \u001b[0mparam\u001b[0m \u001b[1;32min\u001b[0m \u001b[0minputs\u001b[0m\u001b[1;33m]\u001b[0m\u001b[1;33m\u001b[0m\u001b[0m\n\u001b[0;32m    524\u001b[0m \u001b[1;33m\u001b[0m\u001b[0m\n\u001b[1;32m--> 525\u001b[1;33m         \u001b[0mrval\u001b[0m \u001b[1;33m=\u001b[0m \u001b[0mself\u001b[0m\u001b[1;33m.\u001b[0m\u001b[0m_fn_cache\u001b[0m\u001b[1;33m[\u001b[0m\u001b[0minputs\u001b[0m\u001b[1;33m]\u001b[0m\u001b[1;33m(\u001b[0m\u001b[1;33m*\u001b[0m\u001b[0margs\u001b[0m\u001b[1;33m)\u001b[0m\u001b[1;33m\u001b[0m\u001b[0m\n\u001b[0m\u001b[0;32m    526\u001b[0m \u001b[1;33m\u001b[0m\u001b[0m\n\u001b[0;32m    527\u001b[0m         \u001b[1;32mreturn\u001b[0m \u001b[0mrval\u001b[0m\u001b[1;33m\u001b[0m\u001b[0m\n",
      "\u001b[1;32m~\\Anaconda3\\lib\\site-packages\\theano\\compile\\function_module.py\u001b[0m in \u001b[0;36m__call__\u001b[1;34m(self, *args, **kwargs)\u001b[0m\n\u001b[0;32m    901\u001b[0m         \u001b[1;32mtry\u001b[0m\u001b[1;33m:\u001b[0m\u001b[1;33m\u001b[0m\u001b[0m\n\u001b[0;32m    902\u001b[0m             \u001b[0moutputs\u001b[0m \u001b[1;33m=\u001b[0m\u001b[0;31m\\\u001b[0m\u001b[1;33m\u001b[0m\u001b[0m\n\u001b[1;32m--> 903\u001b[1;33m                 \u001b[0mself\u001b[0m\u001b[1;33m.\u001b[0m\u001b[0mfn\u001b[0m\u001b[1;33m(\u001b[0m\u001b[1;33m)\u001b[0m \u001b[1;32mif\u001b[0m \u001b[0moutput_subset\u001b[0m \u001b[1;32mis\u001b[0m \u001b[1;32mNone\u001b[0m \u001b[1;32melse\u001b[0m\u001b[0;31m\\\u001b[0m\u001b[1;33m\u001b[0m\u001b[0m\n\u001b[0m\u001b[0;32m    904\u001b[0m                 \u001b[0mself\u001b[0m\u001b[1;33m.\u001b[0m\u001b[0mfn\u001b[0m\u001b[1;33m(\u001b[0m\u001b[0moutput_subset\u001b[0m\u001b[1;33m=\u001b[0m\u001b[0moutput_subset\u001b[0m\u001b[1;33m)\u001b[0m\u001b[1;33m\u001b[0m\u001b[0m\n\u001b[0;32m    905\u001b[0m         \u001b[1;32mexcept\u001b[0m \u001b[0mException\u001b[0m\u001b[1;33m:\u001b[0m\u001b[1;33m\u001b[0m\u001b[0m\n",
      "\u001b[1;32m~\\Anaconda3\\lib\\site-packages\\theano\\gof\\vm.py\u001b[0m in \u001b[0;36m__call__\u001b[1;34m(self)\u001b[0m\n\u001b[0;32m    302\u001b[0m                         \u001b[0mold_s\u001b[0m\u001b[1;33m[\u001b[0m\u001b[1;36m0\u001b[0m\u001b[1;33m]\u001b[0m \u001b[1;33m=\u001b[0m \u001b[1;32mNone\u001b[0m\u001b[1;33m\u001b[0m\u001b[0m\n\u001b[0;32m    303\u001b[0m             \u001b[1;32mexcept\u001b[0m\u001b[1;33m:\u001b[0m\u001b[1;33m\u001b[0m\u001b[0m\n\u001b[1;32m--> 304\u001b[1;33m                 \u001b[0mlink\u001b[0m\u001b[1;33m.\u001b[0m\u001b[0mraise_with_op\u001b[0m\u001b[1;33m(\u001b[0m\u001b[0mnode\u001b[0m\u001b[1;33m,\u001b[0m \u001b[0mthunk\u001b[0m\u001b[1;33m)\u001b[0m\u001b[1;33m\u001b[0m\u001b[0m\n\u001b[0m\u001b[0;32m    305\u001b[0m \u001b[1;33m\u001b[0m\u001b[0m\n\u001b[0;32m    306\u001b[0m \u001b[1;33m\u001b[0m\u001b[0m\n",
      "\u001b[1;32m~\\Anaconda3\\lib\\site-packages\\theano\\gof\\link.py\u001b[0m in \u001b[0;36mraise_with_op\u001b[1;34m(node, thunk, exc_info, storage_map)\u001b[0m\n\u001b[0;32m    323\u001b[0m         \u001b[1;31m# extra long error message in that case.\u001b[0m\u001b[1;33m\u001b[0m\u001b[1;33m\u001b[0m\u001b[0m\n\u001b[0;32m    324\u001b[0m         \u001b[1;32mpass\u001b[0m\u001b[1;33m\u001b[0m\u001b[0m\n\u001b[1;32m--> 325\u001b[1;33m     \u001b[0mreraise\u001b[0m\u001b[1;33m(\u001b[0m\u001b[0mexc_type\u001b[0m\u001b[1;33m,\u001b[0m \u001b[0mexc_value\u001b[0m\u001b[1;33m,\u001b[0m \u001b[0mexc_trace\u001b[0m\u001b[1;33m)\u001b[0m\u001b[1;33m\u001b[0m\u001b[0m\n\u001b[0m\u001b[0;32m    326\u001b[0m \u001b[1;33m\u001b[0m\u001b[0m\n\u001b[0;32m    327\u001b[0m \u001b[1;33m\u001b[0m\u001b[0m\n",
      "\u001b[1;32m~\\Anaconda3\\lib\\site-packages\\six.py\u001b[0m in \u001b[0;36mreraise\u001b[1;34m(tp, value, tb)\u001b[0m\n\u001b[0;32m    690\u001b[0m                 \u001b[0mvalue\u001b[0m \u001b[1;33m=\u001b[0m \u001b[0mtp\u001b[0m\u001b[1;33m(\u001b[0m\u001b[1;33m)\u001b[0m\u001b[1;33m\u001b[0m\u001b[0m\n\u001b[0;32m    691\u001b[0m             \u001b[1;32mif\u001b[0m \u001b[0mvalue\u001b[0m\u001b[1;33m.\u001b[0m\u001b[0m__traceback__\u001b[0m \u001b[1;32mis\u001b[0m \u001b[1;32mnot\u001b[0m \u001b[0mtb\u001b[0m\u001b[1;33m:\u001b[0m\u001b[1;33m\u001b[0m\u001b[0m\n\u001b[1;32m--> 692\u001b[1;33m                 \u001b[1;32mraise\u001b[0m \u001b[0mvalue\u001b[0m\u001b[1;33m.\u001b[0m\u001b[0mwith_traceback\u001b[0m\u001b[1;33m(\u001b[0m\u001b[0mtb\u001b[0m\u001b[1;33m)\u001b[0m\u001b[1;33m\u001b[0m\u001b[0m\n\u001b[0m\u001b[0;32m    693\u001b[0m             \u001b[1;32mraise\u001b[0m \u001b[0mvalue\u001b[0m\u001b[1;33m\u001b[0m\u001b[0m\n\u001b[0;32m    694\u001b[0m         \u001b[1;32mfinally\u001b[0m\u001b[1;33m:\u001b[0m\u001b[1;33m\u001b[0m\u001b[0m\n",
      "\u001b[1;32m~\\Anaconda3\\lib\\site-packages\\theano\\gof\\vm.py\u001b[0m in \u001b[0;36m__call__\u001b[1;34m(self)\u001b[0m\n\u001b[0;32m    298\u001b[0m                 for thunk, node, old_storage in zip(self.thunks, self.nodes,\n\u001b[0;32m    299\u001b[0m                                                     self.post_thunk_clear):\n\u001b[1;32m--> 300\u001b[1;33m                     \u001b[0mthunk\u001b[0m\u001b[1;33m(\u001b[0m\u001b[1;33m)\u001b[0m\u001b[1;33m\u001b[0m\u001b[0m\n\u001b[0m\u001b[0;32m    301\u001b[0m                     \u001b[1;32mfor\u001b[0m \u001b[0mold_s\u001b[0m \u001b[1;32min\u001b[0m \u001b[0mold_storage\u001b[0m\u001b[1;33m:\u001b[0m\u001b[1;33m\u001b[0m\u001b[0m\n\u001b[0;32m    302\u001b[0m                         \u001b[0mold_s\u001b[0m\u001b[1;33m[\u001b[0m\u001b[1;36m0\u001b[0m\u001b[1;33m]\u001b[0m \u001b[1;33m=\u001b[0m \u001b[1;32mNone\u001b[0m\u001b[1;33m\u001b[0m\u001b[0m\n",
      "\u001b[1;32m~\\Anaconda3\\lib\\site-packages\\theano\\gof\\op.py\u001b[0m in \u001b[0;36mrval\u001b[1;34m(p, i, o, n)\u001b[0m\n\u001b[0;32m    890\u001b[0m             \u001b[1;31m# default arguments are stored in the closure of `rval`\u001b[0m\u001b[1;33m\u001b[0m\u001b[1;33m\u001b[0m\u001b[0m\n\u001b[0;32m    891\u001b[0m             \u001b[1;32mdef\u001b[0m \u001b[0mrval\u001b[0m\u001b[1;33m(\u001b[0m\u001b[0mp\u001b[0m\u001b[1;33m=\u001b[0m\u001b[0mp\u001b[0m\u001b[1;33m,\u001b[0m \u001b[0mi\u001b[0m\u001b[1;33m=\u001b[0m\u001b[0mnode_input_storage\u001b[0m\u001b[1;33m,\u001b[0m \u001b[0mo\u001b[0m\u001b[1;33m=\u001b[0m\u001b[0mnode_output_storage\u001b[0m\u001b[1;33m,\u001b[0m \u001b[0mn\u001b[0m\u001b[1;33m=\u001b[0m\u001b[0mnode\u001b[0m\u001b[1;33m)\u001b[0m\u001b[1;33m:\u001b[0m\u001b[1;33m\u001b[0m\u001b[0m\n\u001b[1;32m--> 892\u001b[1;33m                 \u001b[0mr\u001b[0m \u001b[1;33m=\u001b[0m \u001b[0mp\u001b[0m\u001b[1;33m(\u001b[0m\u001b[0mn\u001b[0m\u001b[1;33m,\u001b[0m \u001b[1;33m[\u001b[0m\u001b[0mx\u001b[0m\u001b[1;33m[\u001b[0m\u001b[1;36m0\u001b[0m\u001b[1;33m]\u001b[0m \u001b[1;32mfor\u001b[0m \u001b[0mx\u001b[0m \u001b[1;32min\u001b[0m \u001b[0mi\u001b[0m\u001b[1;33m]\u001b[0m\u001b[1;33m,\u001b[0m \u001b[0mo\u001b[0m\u001b[1;33m)\u001b[0m\u001b[1;33m\u001b[0m\u001b[0m\n\u001b[0m\u001b[0;32m    893\u001b[0m                 \u001b[1;32mfor\u001b[0m \u001b[0mo\u001b[0m \u001b[1;32min\u001b[0m \u001b[0mnode\u001b[0m\u001b[1;33m.\u001b[0m\u001b[0moutputs\u001b[0m\u001b[1;33m:\u001b[0m\u001b[1;33m\u001b[0m\u001b[0m\n\u001b[0;32m    894\u001b[0m                     \u001b[0mcompute_map\u001b[0m\u001b[1;33m[\u001b[0m\u001b[0mo\u001b[0m\u001b[1;33m]\u001b[0m\u001b[1;33m[\u001b[0m\u001b[1;36m0\u001b[0m\u001b[1;33m]\u001b[0m \u001b[1;33m=\u001b[0m \u001b[1;32mTrue\u001b[0m\u001b[1;33m\u001b[0m\u001b[0m\n",
      "\u001b[1;32m~\\Anaconda3\\lib\\site-packages\\theano\\tensor\\elemwise.py\u001b[0m in \u001b[0;36mperform\u001b[1;34m(self, node, inputs, output_storage)\u001b[0m\n\u001b[0;32m    788\u001b[0m             \u001b[0mnout\u001b[0m \u001b[1;33m=\u001b[0m \u001b[0mufunc\u001b[0m\u001b[1;33m.\u001b[0m\u001b[0mnout\u001b[0m\u001b[1;33m\u001b[0m\u001b[0m\n\u001b[0;32m    789\u001b[0m \u001b[1;33m\u001b[0m\u001b[0m\n\u001b[1;32m--> 790\u001b[1;33m         \u001b[0mvariables\u001b[0m \u001b[1;33m=\u001b[0m \u001b[0mufunc\u001b[0m\u001b[1;33m(\u001b[0m\u001b[1;33m*\u001b[0m\u001b[0mufunc_args\u001b[0m\u001b[1;33m,\u001b[0m \u001b[1;33m**\u001b[0m\u001b[0mufunc_kwargs\u001b[0m\u001b[1;33m)\u001b[0m\u001b[1;33m\u001b[0m\u001b[0m\n\u001b[0m\u001b[0;32m    791\u001b[0m \u001b[1;33m\u001b[0m\u001b[0m\n\u001b[0;32m    792\u001b[0m         \u001b[1;32mif\u001b[0m \u001b[0mnout\u001b[0m \u001b[1;33m==\u001b[0m \u001b[1;36m1\u001b[0m\u001b[1;33m:\u001b[0m\u001b[1;33m\u001b[0m\u001b[0m\n",
      "\u001b[1;32m~\\Anaconda3\\lib\\site-packages\\theano\\scalar\\basic.py\u001b[0m in \u001b[0;36mimpl\u001b[1;34m(self, *inputs)\u001b[0m\n\u001b[0;32m   4021\u001b[0m \u001b[1;33m\u001b[0m\u001b[0m\n\u001b[0;32m   4022\u001b[0m     \u001b[1;32mdef\u001b[0m \u001b[0mimpl\u001b[0m\u001b[1;33m(\u001b[0m\u001b[0mself\u001b[0m\u001b[1;33m,\u001b[0m \u001b[1;33m*\u001b[0m\u001b[0minputs\u001b[0m\u001b[1;33m)\u001b[0m\u001b[1;33m:\u001b[0m\u001b[1;33m\u001b[0m\u001b[0m\n\u001b[1;32m-> 4023\u001b[1;33m         \u001b[0moutput_storage\u001b[0m \u001b[1;33m=\u001b[0m \u001b[1;33m[\u001b[0m\u001b[1;33m[\u001b[0m\u001b[1;32mNone\u001b[0m\u001b[1;33m]\u001b[0m \u001b[1;32mfor\u001b[0m \u001b[0mi\u001b[0m \u001b[1;32min\u001b[0m \u001b[0mxrange\u001b[0m\u001b[1;33m(\u001b[0m\u001b[0mself\u001b[0m\u001b[1;33m.\u001b[0m\u001b[0mnout\u001b[0m\u001b[1;33m)\u001b[0m\u001b[1;33m]\u001b[0m\u001b[1;33m\u001b[0m\u001b[0m\n\u001b[0m\u001b[0;32m   4024\u001b[0m         \u001b[0mself\u001b[0m\u001b[1;33m.\u001b[0m\u001b[0mperform\u001b[0m\u001b[1;33m(\u001b[0m\u001b[1;32mNone\u001b[0m\u001b[1;33m,\u001b[0m \u001b[0minputs\u001b[0m\u001b[1;33m,\u001b[0m \u001b[0moutput_storage\u001b[0m\u001b[1;33m)\u001b[0m\u001b[1;33m\u001b[0m\u001b[0m\n\u001b[0;32m   4025\u001b[0m         ret = utils.to_return_values([storage[0] for storage in\n",
      "\u001b[1;31mSystemError\u001b[0m: <class 'range'> returned a result with an error set\nApply node that caused the error: Elemwise{Composite{(i0 + (i1 * i2))}}[(0, 2)](TensorConstant{(1, 1) of ..0.03827328}, TensorConstant{(1, 1) of 0.07654656}, mrg_uniform{TensorType(float32, matrix),inplace}.1)\nToposort index: 1\nInputs types: [TensorType(float32, (True, True)), TensorType(float32, (True, True)), TensorType(float32, matrix)]\nInputs shapes: [(1, 1), (1, 1), (3072, 1024)]\nInputs strides: [(4, 4), (4, 4), (4096, 4)]\nInputs values: [array([[-0.03827328]], dtype=float32), array([[0.07654656]], dtype=float32), 'not shown']\nOutputs clients: [['output']]\n\nHINT: Re-running with most Theano optimization disabled could give you a back-trace of when this node was created. This can be done with by setting the Theano flag 'optimizer=fast_compile'. If that does not work, Theano optimizations can be disabled with 'optimizer=None'.\nHINT: Use the Theano flag 'exception_verbosity=high' for a debugprint and storage map footprint of this apply node."
     ]
    }
   ],
   "source": [
    "# define the 3072-1024-512-10 architecture using Keras\n",
    "model = Sequential()\n",
    "model.add(Dense(1024, input_shape=(3072,), activation=\"relu\"))\n",
    "model.add(Dense(512, activation=\"relu\"))\n",
    "model.add(Dense(10, activation=\"softmax\"))"
   ]
  },
  {
   "cell_type": "code",
   "execution_count": null,
   "metadata": {},
   "outputs": [],
   "source": [
    "# train the model usign SGD\n",
    "# WARNING: THIS TAKES A LONG TIME IF YOU DON'T HAVE GPU SUPPORT\n",
    "print(\"[INFO] training network...\")\n",
    "sgd = SGD(0.01)\n",
    "model.compile(loss=\"categorical_crossentropy\", optimizer=sgd, metrics=[\"accuracy\"])\n",
    "H = model.fit(trainX, trainY, validation_data=(testX, testY), epochs=100, batch_size=32)"
   ]
  },
  {
   "cell_type": "code",
   "execution_count": null,
   "metadata": {},
   "outputs": [],
   "source": [
    "# evaluate the network\n",
    "print(\"[INFO] evaluating network...\")\n",
    "predictions = model.predict(testX, batch_size=32)\n",
    "print(classification_report(testY.argmax(axis=1), predictions.argmax(axis=1), target_names=labelNames))"
   ]
  },
  {
   "cell_type": "code",
   "execution_count": null,
   "metadata": {},
   "outputs": [],
   "source": [
    "import seaborn as sns\n",
    "\n",
    "%matplotlib inline\n",
    "sns.set()\n",
    "\n",
    "# plot the training loss and accuracy\n",
    "plt.figure(figsize=(12,8))\n",
    "plt.plot(np.arange(0, 100), H.history[\"loss\"], label=\"train_loss\")\n",
    "plt.plot(np.arange(0, 100), H.history[\"val_loss\"], label=\"val_loss\")\n",
    "plt.plot(np.arange(0, 100), H.history[\"acc\"], label=\"train_acc\")\n",
    "plt.plot(np.arange(0, 100), H.history[\"val_acc\"], label=\"val_acc\")\n",
    "plt.title(\"Training Loss and Accuracy\")\n",
    "plt.xlabel(\"Epoch #\")\n",
    "plt.ylabel(\"Loss/Accuracy\")\n",
    "plt.legend();"
   ]
  },
  {
   "cell_type": "markdown",
   "metadata": {},
   "source": [
    "So we only got around 58% accuracy. If we look at the plot above we see train loss keeps going steady down, but after the 10th epoch we are already **overfitting** as the val_loss stops going down and actually goes up as we continue the training.\n",
    "\n",
    "Notice our training accuracy goes to 1 and our validation accuracy goes to 0. \n",
    "\n",
    "Simple fact: basic feedforward networks with fully connected layers are not suitable for challenging image datasets."
   ]
  },
  {
   "cell_type": "code",
   "execution_count": null,
   "metadata": {},
   "outputs": [],
   "source": []
  }
 ],
 "metadata": {
  "kernelspec": {
   "display_name": "Python 3",
   "language": "python",
   "name": "python3"
  },
  "language_info": {
   "codemirror_mode": {
    "name": "ipython",
    "version": 3
   },
   "file_extension": ".py",
   "mimetype": "text/x-python",
   "name": "python",
   "nbconvert_exporter": "python",
   "pygments_lexer": "ipython3",
   "version": "3.6.4"
  }
 },
 "nbformat": 4,
 "nbformat_minor": 2
}
